Workbook
Name UPDATE: 'Data Sheet'!$E$1

Sheet Financials

Sheet Ratio analysis
B2: ="Ratio Analysis - "&'Data Sheet'!B1 -> Ratio Analysis - ASIAN PAINTS LTD
B3: Years | C3: ='Data Sheet'!B16 -> 42460 | D3: ='Data Sheet'!C16 -> 42825 | E3: ='Data Sheet'!D16 -> 43190 | F3: ='Data Sheet'!E16 -> 43555 | G3: ='Data Sheet'!F16 -> 43921 | H3: ='Data Sheet'!G16 -> 44286 | I3: ='Data Sheet'!H16 -> 44651 | J3: ='Data Sheet'!I16 -> 45016 | ... L3: ='Data Sheet'!K16 -> 45747 | M3: Trend | N3: Mean | O3: Median
B4: SalesGrowth | D4: =IFERROR('Historical FS'!D6,0) -> 0.055390152 | E4: =IFERROR('Historical FS'!E6,0) -> 0.11702039 | F4: =IFERROR('Historical FS'!F6,0) -> 0.14357472 | G4: =IFERROR('Historical FS'!G6,0) -> 0.050473671 | H4: =IFERROR('Historical FS'!H6,0) -> 0.074292288 | I4: =IFERROR('Historical FS'!I6,0) -> 0.34028285 | J4: =IFERROR('Historical FS'!J6,0) -> 0.18512278 | K4: =IFERROR('Historical FS'!K6,0) -> 0.029173127 | L4: =IFERROR('Historical FS'!L6,0) -> -0.044770308 | N4: =MEDIAN(C4:L4) -> 0.074292288 | O4: =AVERAGE(C4:L4) -> 0.10561774
B5: GrossMargin | D5: =IFERROR('Historical FS'!C11/'Historical FS'!C5,0) -> 0.34037441 | E5: =IFERROR('Historical FS'!D11/'Historical FS'!D5,0) -> 0.28363649 | F5: =IFERROR('Historical FS'!E11/'Historical FS'!E5,0) -> 0.35154818 | G5: =IFERROR('Historical FS'!F11/'Historical FS'!F5,0) -> 0.29874019 | H5: =IFERROR('Historical FS'!G11/'Historical FS'!G5,0) -> 0.32531041 | I5: =IFERROR('Historical FS'!H11/'Historical FS'!H5,0) -> 0.34508785 | J5: =IFERROR('Historical FS'!I11/'Historical FS'!I5,0) -> 0.20139217 | K5: =IFERROR('Historical FS'!J11/'Historical FS'!J5,0) -> 0.29292093 | L5: =IFERROR('Historical FS'!K11/'Historical FS'!K5,0) -> 0.37223385 | N5: =MEDIAN(C5:L5) -> 0.32531041 | O5: =AVERAGE(C5:L5) -> 0.3123605
B6: EBITDA Growth | D6: =IFERROR('Historical FS'!D16/'Historical FS'!C16-1,0) -> -0.28934621 | E6: =IFERROR('Historical FS'!E16/'Historical FS'!D16-1,0) -> 0.80127133 | F6: =IFERROR('Historical FS'!F16/'Historical FS'!E16-1,0) -> -0.088826266 | G6: =IFERROR('Historical FS'!G16/'Historical FS'!F16-1,0) -> 0.15734233 | H6: =IFERROR('Historical FS'!H16/'Historical FS'!G16-1,0) -> 0.26972261 | I6: =IFERROR('Historical FS'!I16/'Historical FS'!H16-1,0) -> -0.53889781 | J6: =IFERROR('Historical FS'!J16/'Historical FS'!I16-1,0) -> 1.6189621 | K6: =IFERROR('Historical FS'!K16/'Historical FS'!J16-1,0) -> 0.47376241 | L6: =IFERROR('Historical FS'!L16/'Historical FS'!K16-1,0) -> -0.32677821 | N6: =MEDIAN(C6:L6) -> 0.15734233 | O6: =AVERAGE(C6:L6) -> 0.23080136
B7: EBIT Growth | D7: =IFERROR('Historical FS'!D25/'Historical FS'!C25-1,0) -> -0.34827491 | E7: =IFERROR('Historical FS'!E25/'Historical FS'!D25-1,0) -> 0.97280177 | F7: =IFERROR('Historical FS'!F25/'Historical FS'!E25-1,0) -> -0.20753452 | G7: =IFERROR('Historical FS'!G25/'Historical FS'!F25-1,0) -> 0.14305281 | H7: =IFERROR('Historical FS'!H25/'Historical FS'!G25-1,0) -> 0.35487125 | I7: =IFERROR('Historical FS'!I25/'Historical FS'!H25-1,0) -> -0.67213158 | J7: =IFERROR('Historical FS'!J25/'Historical FS'!I25-1,0) -> 2.7345277 | K7: =IFERROR('Historical FS'!K25/'Historical FS'!J25-1,0) -> 0.56415497 | L7: =IFERROR('Historical FS'!L25/'Historical FS'!K25-1,0) -> -0.40135035 | N7: =MEDIAN(C7:L7) -> 0.14305281 | O7: =AVERAGE(C7:L7) -> 0.34890191
B8: Net Profit Growth | D8: =IFERROR('Historical FS'!D31/'Historical FS'!C31-1,0) -> -0.60079565 | E8: =IFERROR('Historical FS'!E31/'Historical FS'!D31-1,0) -> 2.2928761 | F8: =IFERROR('Historical FS'!F31/'Historical FS'!E31-1,0) -> -0.34107276 | G8: =IFERROR('Historical FS'!G31/'Historical FS'!F31-1,0) -> 0.44005936 | H8: =IFERROR('Historical FS'!H31/'Historical FS'!G31-1,0) -> 0.38610086 | I8: =IFERROR('Historical FS'!I31/'Historical FS'!H31-1,0) -> -0.9483347 | J8: =IFERROR('Historical FS'!J31/'Historical FS'!I31-1,0) -> 21.623282 | K8: =IFERROR('Historical FS'!K31/'Historical FS'!J31-1,0) -> 0.73779183 | L8: =IFERROR('Historical FS'!L31/'Historical FS'!K31-1,0) -> -0.46022843 | N8: =MEDIAN(C8:L8) -> 0.38610086 | O8: =AVERAGE(C8:L8) -> 2.5699643
B9: Dividend Growth | D9: =IFERROR('Historical FS'!D39/'Historical FS'!C39-1,0) -> 0.37333889 | E9: =IFERROR('Historical FS'!E39/'Historical FS'!D39-1,0) -> -0.15534727 | F9: =IFERROR('Historical FS'!F39/'Historical FS'!E39-1,0) -> 0.20690234 | G9: =IFERROR('Historical FS'!G39/'Historical FS'!F39-1,0) -> 0.14285714 | H9: =IFERROR('Historical FS'!H39/'Historical FS'!G39-1,0) -> 0.48749826 | I9: =IFERROR('Historical FS'!I39/'Historical FS'!H39-1,0) -> 0.072831553 | J9: =IFERROR('Historical FS'!J39/'Historical FS'!I39-1,0) -> 0.33942522 | K9: =IFERROR('Historical FS'!K39/'Historical FS'!J39-1,0) -> 0.29824618 | L9: =IFERROR('Historical FS'!L39/'Historical FS'!K39-1,0) -> -0.25525494 | N9: =MEDIAN(C9:L9) -> 0.20690234 | O9: =AVERAGE(C9:L9) -> 0.16783304
B11: Gross Margin | C11: =IFERROR('Historical FS'!C11/'Historical FS'!C5,0) -> 0.34037441 | D11: =IFERROR('Historical FS'!D11/'Historical FS'!D5,0) -> 0.28363649 | E11: =IFERROR('Historical FS'!E11/'Historical FS'!E5,0) -> 0.35154818 | F11: =IFERROR('Historical FS'!F11/'Historical FS'!F5,0) -> 0.29874019 | G11: =IFERROR('Historical FS'!G11/'Historical FS'!G5,0) -> 0.32531041 | H11: =IFERROR('Historical FS'!H11/'Historical FS'!H5,0) -> 0.34508785 | I11: =IFERROR('Historical FS'!I11/'Historical FS'!I5,0) -> 0.20139217 | J11: =IFERROR('Historical FS'!J11/'Historical FS'!J5,0) -> 0.29292093 | ... L11: =IFERROR('Historical FS'!L11/'Historical FS'!L5,0) -> 0.31718488 | N11: =MEDIAN(C11:L11) -> 0.32124764 | O11: =AVERAGE(C11:L11) -> 0.31284294
B12: Operating Margin
B13: EBITDA Margin | C13: =IFERROR('Historical FS'!C17,0) -> 0.19094292 | D13: =IFERROR('Historical FS'!D17,0) -> 0.12857265 | E13: =IFERROR('Historical FS'!E17,0) -> 0.20733214 | F13: =IFERROR('Historical FS'!F17,0) -> 0.16519743 | G13: =IFERROR('Historical FS'!G17,0) -> 0.18200359 | H13: =IFERROR('Historical FS'!H17,0) -> 0.21511284 | I13: =IFERROR('Historical FS'!I17,0) -> 0.074006023 | J13: =IFERROR('Historical FS'!J17,0) -> 0.16354336 | ... L13: =IFERROR('Historical FS'!L17,0) -> 0.16505258 | N13: =MEDIAN(C13:L13) -> 0.17360051 | O13: =AVERAGE(C13:L13) -> 0.17259555
B14: EBIT Margin | C14: =IFERROR(('Historical FS'!C16-'Historical FS'!C22)/'Historical FS'!C5,0) -> 0.1716331 | D14: =IFERROR(('Historical FS'!D16-'Historical FS'!D22)/'Historical FS'!D5,0) -> 0.10634518 | E14: =IFERROR(('Historical FS'!E16-'Historical FS'!E22)/'Historical FS'!E5,0) -> 0.1859069 | F14: =IFERROR(('Historical FS'!F16-'Historical FS'!F22)/'Historical FS'!F5,0) -> 0.13286189 | G14: =IFERROR(('Historical FS'!G16-'Historical FS'!G22)/'Historical FS'!G5,0) -> 0.14338648 | H14: =IFERROR(('Historical FS'!H16-'Historical FS'!H22)/'Historical FS'!H5,0) -> 0.17867027 | I14: =IFERROR(('Historical FS'!I16-'Historical FS'!I22)/'Historical FS'!I5,0) -> 0.045953649 | J14: =IFERROR(('Historical FS'!J16-'Historical FS'!J22)/'Historical FS'!J5,0) -> 0.13866499 | ... L14: =IFERROR(('Historical FS'!L16-'Historical FS'!L22)/'Historical FS'!L5,0) -> 0.13478208 | N14: =MEDIAN(C14:L14) -> 0.14102574 | O14: =AVERAGE(C14:L14) -> 0.14483647
B15: EBT Margin | C15: =IFERROR('Historical FS'!C26,0) -> 0.16819968 | D15: =IFERROR('Historical FS'!D26,0) -> 0.10386675 | E15: =IFERROR('Historical FS'!E26,0) -> 0.18344205 | F15: =IFERROR('Historical FS'!F26,0) -> 0.12712024 | G15: =IFERROR('Historical FS'!G26,0) -> 0.13832346 | H15: =IFERROR('Historical FS'!H26,0) -> 0.17445017 | I15: =IFERROR('Historical FS'!I26,0) -> 0.042675099 | J15: =IFERROR('Historical FS'!J26,0) -> 0.13447665 | ... L15: =IFERROR('Historical FS'!L26,0) -> 0.12808644 | N15: =MEDIAN(C15:L15) -> 0.13640005 | O15: =AVERAGE(C15:L15) -> 0.14050205
B16: Net Profit Margin | C16: =IFERROR('Historical FS'!C32,0) -> 0.10902646 | D16: =IFERROR('Historical FS'!D32,0) -> 0.041239571 | E16: =IFERROR('Historical FS'!E32,0) -> 0.12157056 | F16: =IFERROR('Historical FS'!F32,0) -> 0.070048903 | G16: =IFERROR('Historical FS'!G32,0) -> 0.096027707 | H16: =IFERROR('Historical FS'!H32,0) -> 0.12389932 | I16: =IFERROR('Historical FS'!I32,0) -> 0.0047760786 | J16: =IFERROR('Historical FS'!J32,0) -> 0.091172472 | ... L16: =IFERROR('Historical FS'!L32,0) -> 0.086991183 | N16: =MEDIAN(C16:L16) -> 0.09360009 | O16: =AVERAGE(C16:L16) -> 0.08986999
B18: SalesExpenses%Sales | C18: =IFERROR('Historical FS'!C14,0) -> 0.14943149 | D18: =IFERROR('Historical FS'!D14,0) -> 0.15506384 | E18: =IFERROR('Historical FS'!E14,0) -> 0.14421604 | F18: =IFERROR('Historical FS'!F14,0) -> 0.13354276 | G18: =IFERROR('Historical FS'!G14,0) -> 0.14330682 | H18: =IFERROR('Historical FS'!H14,0) -> 0.12997501 | I18: =IFERROR('Historical FS'!I14,0) -> 0.12738615 | J18: =IFERROR('Historical FS'!J14,0) -> 0.12937757 | ... L18: =IFERROR('Historical FS'!L14,0) -> 0.1521323 | N18: =MEDIAN(C18:L18) -> 0.14067436 | O18: =AVERAGE(C18:L18) -> 0.14024739
B19: Depreciation%Sales | C19: =IFERROR('Historical FS'!C23,0) -> 0.019309827 | D19: =IFERROR('Historical FS'!D23,0) -> 0.022227475 | E19: =IFERROR('Historical FS'!E23,0) -> 0.021425239 | F19: =IFERROR('Historical FS'!F23,0) -> 0.03233554 | G19: =IFERROR('Historical FS'!G23,0) -> 0.038617107 | H19: =IFERROR('Historical FS'!H23,0) -> 0.036442576 | I19: =IFERROR('Historical FS'!I23,0) -> 0.028052374 | J19: =IFERROR('Historical FS'!J23,0) -> 0.024878373 | ... L19: =IFERROR('Historical FS'!L23,0) -> 0.030270498 | N19: =MEDIAN(C19:L19) -> 0.026465374 | O19: =AVERAGE(C19:L19) -> 0.027759074
B20: OperatingIncome%Sales | C20: =C14 -> 0.1716331 | D20: =D14 -> 0.10634518 | E20: =E14 -> 0.1859069 | F20: =F14 -> 0.13286189 | G20: =G14 -> 0.14338648 | H20: =H14 -> 0.17867027 | I20: =I14 -> 0.045953649 | J20: =J14 -> 0.13866499 | ... L20: =L14 -> 0.13478208 | N20: =MEDIAN(C20:L20) -> 0.14102574 | O20: =AVERAGE(C20:L20) -> 0.14483647
B22: Return on Capital Employed | C22: =IFERROR(('Historical FS'!C16-'Historical FS'!C19) / SUM('Historical FS'!C45:C47),0) -> 0.39077059 | D22: =IFERROR(('Historical FS'!D16-'Historical FS'!D19) / SUM('Historical FS'!D45:D47),0) -> 0.23262818 | E22: =IFERROR(('Historical FS'!E16-'Historical FS'!E19) / SUM('Historical FS'!E45:E47),0) -> 0.38539032 | F22: =IFERROR(('Historical FS'!F16-'Historical FS'!F19) / SUM('Historical FS'!F45:F47),0) -> 0.28432876 | G22: =IFERROR(('Historical FS'!G16-'Historical FS'!G19) / SUM('Historical FS'!G45:G47),0) -> 0.31792142 | H22: =IFERROR(('Historical FS'!H16-'Historical FS'!H19) / SUM('Historical FS'!H45:H47),0) -> 0.32944348 | I22: =IFERROR(('Historical FS'!I16-'Historical FS'!I19) / SUM('Historical FS'!I45:I47),0) -> 0.13366679 | J22: =IFERROR(('Historical FS'!J16-'Historical FS'!J19) / SUM('Historical FS'!J45:J47),0) -> 0.30660954 | ... L22: =IFERROR(('Historical FS'!L16-'Historical FS'!L19) / SUM('Historical FS'!L45:L47),0) -> 0.24754104 | N22: =MEDIAN(C22:L22) -> 0.31226548 | O22: =AVERAGE(C22:L22) -> 0.30106768
B23: Retained Earnings% | C23: =IFERROR('Historical FS'!C42,0) -> 0.53765175 | D23: =IFERROR('Historical FS'!D42,0) -> 0 | E23: =IFERROR('Historical FS'!E42,0) -> 0.59200536 | F23: =IFERROR('Historical FS'!F42,0) -> 0.25271007 | G23: =IFERROR('Historical FS'!G42,0) -> 0.4069372 | H23: =IFERROR('Historical FS'!H42,0) -> 0.3635529 | I23: =IFERROR('Historical FS'!I42,0) -> 0 | J23: =IFERROR('Historical FS'!J42,0) -> 0.21754797 | ... L23: =IFERROR('Historical FS'!L42,0) -> 0.19348091 | N23: =MEDIAN(C23:L23) -> 0.30813148 | O23: =AVERAGE(C23:L23) -> 0.29793424
B24: Return on Equity% | C24: =IFERROR('Historical FS'!C31/SUM('Historical FS'!C45:C46),0) -> 0.23846941 | D24: =IFERROR('Historical FS'!D31/SUM('Historical FS'!D45:D46),0) -> 0.081688452 | E24: =IFERROR('Historical FS'!E31/SUM('Historical FS'!E45:E46),0) -> 0.24320025 | F24: =IFERROR('Historical FS'!F31/SUM('Historical FS'!F45:F46),0) -> 0.14230958 | G24: =IFERROR('Historical FS'!G31/SUM('Historical FS'!G45:G46),0) -> 0.19159026 | H24: =IFERROR('Historical FS'!H31/SUM('Historical FS'!H45:H46),0) -> 0.21006865 | I24: =IFERROR('Historical FS'!I31/SUM('Historical FS'!I45:I46),0) -> 0.010063309 | J24: =IFERROR('Historical FS'!J31/SUM('Historical FS'!J45:J46),0) -> 0.19662111 | ... L24: =IFERROR('Historical FS'!L31/SUM('Historical FS'!L45:L46),0) -> 0.15203706 | N24: =MEDIAN(C24:L24) -> 0.19410569 | O24: =AVERAGE(C24:L24) -> 0.17578167
B25: Self Sustained Growth Rate | C25: =IFERROR(C23*C24,0) -> 0.1282135 | D25: =IFERROR(D23*D24,0) -> 0 | E25: =IFERROR(E23*E24,0) -> 0.14397585 | F25: =IFERROR(F23*F24,0) -> 0.035963064 | G25: =IFERROR(G23*G24,0) -> 0.077965205 | H25: =IFERROR(H23*H24,0) -> 0.076371065 | I25: =IFERROR(I23*I24,0) -> 0 | J25: =IFERROR(J23*J24,0) -> 0.042774522 | ... L25: =IFERROR(L23*L24,0) -> 0.029416267 | N25: =MEDIAN(C25:L25) -> 0.059572793 | O25: =AVERAGE(C25:L25) -> 0.065589656
B26: Interest Coverage Ratio | C26: =IFERROR(('Historical FS'!C16-'Historical FS'!C19)/'Historical FS'!C19,0) -> 54.613061 | D26: =IFERROR(('Historical FS'!D16-'Historical FS'!D19)/'Historical FS'!D19,0) -> 50.876775 | E26: =IFERROR(('Historical FS'!E16-'Historical FS'!E19)/'Historical FS'!E19,0) -> 83.115505 | F26: =IFERROR(('Historical FS'!F16-'Historical FS'!F19)/'Historical FS'!F19,0) -> 27.771793 | G26: =IFERROR(('Historical FS'!G16-'Historical FS'!G19)/'Historical FS'!G19,0) -> 34.94762 | H26: =IFERROR(('Historical FS'!H16-'Historical FS'!H19)/'Historical FS'!H19,0) -> 49.97348 | I26: =IFERROR(('Historical FS'!I16-'Historical FS'!I19)/'Historical FS'!I19,0) -> 21.572791 | J26: =IFERROR(('Historical FS'!J16-'Historical FS'!J19)/'Historical FS'!J19,0) -> 38.047283 | ... L26: =IFERROR(('Historical FS'!L16-'Historical FS'!L19)/'Historical FS'!L19,0) -> 23.650736 | N26: =MEDIAN(C26:L26) -> 38.781428 | O26: =AVERAGE(C26:L26) -> 42.408462
B28: Debtor Turnover Ratio | C28: =IFERROR('Historical FS'!C5/'Historical FS'!C57,0) -> 12.02478 | D28: =IFERROR('Historical FS'!D5/'Historical FS'!D57,0) -> 10.411994 | E28: =IFERROR('Historical FS'!E5/'Historical FS'!E57,0) -> 9.7216332 | F28: =IFERROR('Historical FS'!F5/'Historical FS'!F57,0) -> 10.087468 | G28: =IFERROR('Historical FS'!G5/'Historical FS'!G57,0) -> 11.258369 | H28: =IFERROR('Historical FS'!H5/'Historical FS'!H57,0) -> 8.344109 | I28: =IFERROR('Historical FS'!I5/'Historical FS'!I57,0) -> 7.5169136 | J28: =IFERROR('Historical FS'!J5/'Historical FS'!J57,0) -> 7.4377909 | ... L28: =IFERROR('Historical FS'!L5/'Historical FS'!L57,0) -> 7.8600767 | N28: =MEDIAN(C28:L28) -> 9.0328711 | O28: =AVERAGE(C28:L28) -> 9.1923181
B29: Creditor Turnover Ratio | C29: =IFERROR('Historical FS'!C5/'Historical FS'!C48,0) -> 3.8458091 | D29: =IFERROR('Historical FS'!D5/'Historical FS'!D48,0) -> 3.551552 | E29: =IFERROR('Historical FS'!E5/'Historical FS'!E48,0) -> 3.4907009 | F29: =IFERROR('Historical FS'!F5/'Historical FS'!F48,0) -> 3.524679 | G29: =IFERROR('Historical FS'!G5/'Historical FS'!G48,0) -> 4.1337633 | H29: =IFERROR('Historical FS'!H5/'Historical FS'!H48,0) -> 3.3632319 | I29: =IFERROR('Historical FS'!I5/'Historical FS'!I48,0) -> 3.8493808 | J29: =IFERROR('Historical FS'!J5/'Historical FS'!J48,0) -> 4.390945 | ... L29: =IFERROR('Historical FS'!L5/'Historical FS'!L48,0) -> 3.9128717 | N29: =MEDIAN(C29:L29) -> 3.8475949 | O29: =AVERAGE(C29:L29) -> 3.8143684
B30: Inventory Turnover | C30: =IFERROR('Historical FS'!C5/'Historical FS'!C58,0) -> 7.14203 | D30: =IFERROR('Historical FS'!D5/'Historical FS'!D58,0) -> 5.7336635 | E30: =IFERROR('Historical FS'!E5/'Historical FS'!E58,0) -> 6.3290399 | F30: =IFERROR('Historical FS'!F5/'Historical FS'!F58,0) -> 6.1082493 | G30: =IFERROR('Historical FS'!G5/'Historical FS'!G58,0) -> 5.9623548 | H30: =IFERROR('Historical FS'!H5/'Historical FS'!H58,0) -> 5.715998 | I30: =IFERROR('Historical FS'!I5/'Historical FS'!I58,0) -> 4.7296237 | J30: =IFERROR('Historical FS'!J5/'Historical FS'!J58,0) -> 5.5531459 | ... L30: =IFERROR('Historical FS'!L5/'Historical FS'!L58,0) -> 5.0460273 | N30: =MEDIAN(C30:L30) -> 5.8480092 | O30: =AVERAGE(C30:L30) -> 5.8312412
B31: Fixed Asset Turnover | C31: =IFERROR('Historical FS'!C5/'Historical FS'!C51,0) -> 4.1774086 | D31: =IFERROR('Historical FS'!D5/'Historical FS'!D51,0) -> 4.5590724 | E31: =IFERROR('Historical FS'!E5/'Historical FS'!E51,0) -> 4.5078961 | F31: =IFERROR('Historical FS'!F5/'Historical FS'!F51,0) -> 2.9615874 | G31: =IFERROR('Historical FS'!G5/'Historical FS'!G51,0) -> 3.2222977 | H31: =IFERROR('Historical FS'!H5/'Historical FS'!H51,0) -> 3.7061903 | I31: =IFERROR('Historical FS'!I5/'Historical FS'!I51,0) -> 5.2728689 | J31: =IFERROR('Historical FS'!J5/'Historical FS'!J51,0) -> 5.9767488 | ... L31: =IFERROR('Historical FS'!L5/'Historical FS'!L51,0) -> 3.6773592 | N31: =MEDIAN(C31:L31) -> 4.3426524 | O31: =AVERAGE(C31:L31) -> 4.3028075
B32: Capital Turnover Ratio | C32: =IFERROR('Historical FS'!C5/SUM('Historical FS'!C45:C47),0) -> 2.0840042 | D32: =IFERROR('Historical FS'!D5/SUM('Historical FS'!D45:D47),0) -> 1.8448758 | E32: =IFERROR('Historical FS'!E5/SUM('Historical FS'!E45:E47),0) -> 1.8811706 | F32: =IFERROR('Historical FS'!F5/SUM('Historical FS'!F45:F47),0) -> 1.7831198 | G32: =IFERROR('Historical FS'!G5/SUM('Historical FS'!G45:G47),0) -> 1.7967696 | H32: =IFERROR('Historical FS'!H5/SUM('Historical FS'!H45:H47),0) -> 1.5621375 | I32: =IFERROR('Historical FS'!I5/SUM('Historical FS'!I45:I47),0) -> 1.8898849 | J32: =IFERROR('Historical FS'!J5/SUM('Historical FS'!J45:J47),0) -> 1.9240658 | ... L32: =IFERROR('Historical FS'!L5/SUM('Historical FS'!L45:L47),0) -> 1.5631841 | N32: =MEDIAN(C32:L32) -> 1.8208227 | O32: =AVERAGE(C32:L32) -> 1.800328
B35: Debtor Days | C35: =IFERROR(365/C28,0) -> 30.353985 | D35: =IFERROR(365/D28,0) -> 35.055726 | E35: =IFERROR(365/E28,0) -> 37.545132 | F35: =IFERROR(365/F28,0) -> 36.183511 | G35: =IFERROR(365/G28,0) -> 32.420325 | H35: =IFERROR(365/H28,0) -> 43.743436 | I35: =IFERROR(365/I28,0) -> 48.557163 | J35: =IFERROR(365/J28,0) -> 49.073711 | ... L35: =IFERROR(365/L28,0) -> 46.437206 | N35: =MEDIAN(C35:L35) -> 40.644284 | O35: =AVERAGE(C35:L35) -> 40.964536
B36: Payable Days | C36: =IFERROR(365/C29,0) -> 94.908506 | D36: =IFERROR(365/D29,0) -> 102.77197 | E36: =IFERROR(365/E29,0) -> 104.56353 | F36: =IFERROR(365/F29,0) -> 103.55553 | G36: =IFERROR(365/G29,0) -> 88.297268 | H36: =IFERROR(365/H29,0) -> 108.52656 | I36: =IFERROR(365/I29,0) -> 94.820446 | J36: =IFERROR(365/J29,0) -> 83.125613 | ... L36: =IFERROR(365/L29,0) -> 93.281873 | N36: =MEDIAN(C36:L36) -> 94.864476 | O36: =AVERAGE(C36:L36) -> 96.329564
B37: Inventory Days | C37: =IFERROR(365/C30,0) -> 51.105918 | D37: =IFERROR(365/D30,0) -> 63.659125 | E37: =IFERROR(365/E30,0) -> 57.670675 | F37: =IFERROR(365/F30,0) -> 59.755256 | G37: =IFERROR(365/G30,0) -> 61.217423 | H37: =IFERROR(365/H30,0) -> 63.855866 | I37: =IFERROR(365/I30,0) -> 77.173159 | J37: =IFERROR(365/J30,0) -> 65.728509 | ... L37: =IFERROR(365/L30,0) -> 72.334131 | N37: =MEDIAN(C37:L37) -> 62.438274 | O37: =AVERAGE(C37:L37) -> 63.341177
B38: Cash Conversion Cycle (in days) | C38: =IFERROR(SUM(C35,C37)-C36,0) -> -13.448603 | D38: =IFERROR(SUM(D35,D37)-D36,0) -> -4.0571199 | E38: =IFERROR(SUM(E35,E37)-E36,0) -> -9.347721 | F38: =IFERROR(SUM(F35,F37)-F36,0) -> -7.6167625 | G38: =IFERROR(SUM(G35,G37)-G36,0) -> 5.3404812 | H38: =IFERROR(SUM(H35,H37)-H36,0) -> -0.92725992 | I38: =IFERROR(SUM(I35,I37)-I36,0) -> 30.909876 | J38: =IFERROR(SUM(J35,J37)-J36,0) -> 31.676607 | ... L38: =IFERROR(SUM(L35,L37)-L36,0) -> 25.489463 | N38: =MEDIAN(C38:L38) -> 2.2066106 | O38: =AVERAGE(C38:L38) -> 7.9761485
B40: CFO/Sales | C40: =IFERROR('Historical FS'!C76/'Historical FS'!C5,0) -> 0.1348843 | D40: =IFERROR('Historical FS'!D76/'Historical FS'!D5,0) -> 0.090359906 | E40: =IFERROR('Historical FS'!E76/'Historical FS'!E5,0) -> 0.24886253 | F40: =IFERROR('Historical FS'!F76/'Historical FS'!F5,0) -> 0.343085 | G40: =IFERROR('Historical FS'!G76/'Historical FS'!G5,0) -> -0.16114788 | H40: =IFERROR('Historical FS'!H76/'Historical FS'!H5,0) -> 0.52798374 | I40: =IFERROR('Historical FS'!I76/'Historical FS'!I5,0) -> 0.27613906 | J40: =IFERROR('Historical FS'!J76/'Historical FS'!J5,0) -> 0.13653791 | ... L40: =IFERROR('Historical FS'!L76/'Historical FS'!L5,0) -> 0.3234567 | N40: =MEDIAN(C40:L40) -> 0.25187272 | O40: =AVERAGE(C40:L40) -> 0.21750442
B41: CFO/Total Assets | C41: =IFERROR('Historical FS'!C76/'Historical FS'!C62,0) -> 0.18230841 | D41: =IFERROR('Historical FS'!D76/'Historical FS'!D62,0) -> 0.10971214 | E41: =IFERROR('Historical FS'!E76/'Historical FS'!E62,0) -> 0.30421085 | F41: =IFERROR('Historical FS'!F76/'Historical FS'!F62,0) -> 0.40624438 | G41: =IFERROR('Historical FS'!G76/'Historical FS'!G62,0) -> -0.20182216 | H41: =IFERROR('Historical FS'!H76/'Historical FS'!H62,0) -> 0.56319374 | I41: =IFERROR('Historical FS'!I76/'Historical FS'!I62,0) -> 0.35002393 | J41: =IFERROR('Historical FS'!J76/'Historical FS'!J62,0) -> 0.18266572 | ... L41: =IFERROR('Historical FS'!L76/'Historical FS'!L62,0) -> 0.36128841 | N41: =MEDIAN(C41:L41) -> 0.30338916 | O41: =AVERAGE(C41:L41) -> 0.25603929
B42: CFO/Total Debt | C42: =IFERROR('Historical FS'!C76/'Historical FS'!C47,0) -> 5.9544063 | D42: =IFERROR('Historical FS'!D76/'Historical FS'!D47,0) -> 2.4288825 | E42: =IFERROR('Historical FS'!E76/'Historical FS'!E47,0) -> 7.8492023 | F42: =IFERROR('Historical FS'!F76/'Historical FS'!F47,0) -> 5.0022734 | G42: =IFERROR('Historical FS'!G76/'Historical FS'!G47,0) -> -2.9119356 | H42: =IFERROR('Historical FS'!H76/'Historical FS'!H47,0) -> 10.487412 | I42: =IFERROR('Historical FS'!I76/'Historical FS'!I47,0) -> 5.064025 | J42: =IFERROR('Historical FS'!J76/'Historical FS'!J47,0) -> 2.4365887 | ... L42: =IFERROR('Historical FS'!L76/'Historical FS'!L47,0) -> 4.7884766 | N42: =MEDIAN(C42:L42) -> 4.895375 | O42: =AVERAGE(C42:L42) -> 4.4755601

Sheet Forecasting
B2: ='Data Sheet'!B1&" - "&'Data Sheet'!A17 -> ASIAN PAINTS LTD - Sales | H2: ='Data Sheet'!B1&" - "&'Historical FS'!B16 -> ASIAN PAINTS LTD - EBIDTA
B3: Year Weight | C3: Year | D3: Sales | E3: Sales growth | H3: Year Weight | I3: Year | J3: EBIDTA | K3: EBIDTA growth
B4: =1 -> 1 | C4: ='Data Sheet'!B16 -> 42460 | D4: {=TRANSPOSE('Data Sheet'!B17:K17)} -> 14271.49 | H4: =1 -> 1 | I4: ='Data Sheet'!B16 -> 42460 | J4: {=TRANSPOSE('Historical FS'!C16:L16)} -> 2725.04
B5: =B4+1 -> 2 | C5: =C4+365 -> 42825 | D5: 269692.51 | E5: =(D5-D4)/D4 -> 17.897292 | H5: =H4+1 -> 2 | I5: =I4+365 -> 42825 | J5: 1936.56 | K5: =(J5-J4)/J4 -> -0.28934621
B6: =B5+1 -> 3 | C6: =C5+365 -> 43190 | D6: 291550.48 | E6: =(D6-D5)/D5 -> 0.081047746 | H6: =H5+1 -> 3 | I6: =I5+365 -> 43190 | J6: 3488.27 | K6: =(J6-J5)/J5 -> 0.80127133
B7: =B6+1 -> 4 | C7: =C6+365 -> 43555 | D7: 301938.4 | E7: =(D7-D6)/D6 -> 0.035629919 | H7: =H6+1 -> 4 | I7: =I6+365 -> 43555 | J7: 3178.42 | K7: =(J7-J6)/J6 -> -0.088826266
B8: =B7+1 -> 5 | C8: =C7+365 -> 43920 | D8: 261067.97 | E8: =(D8-D7)/D7 -> -0.13536016 | H8: =H7+1 -> 5 | I8: =I7+365 -> 43920 | J8: 3678.52 | K8: =(J8-J7)/J7 -> 0.15734233
B9: =B8+1 -> 6 | C9: =C8+365 -> 44285 | D9: 249794.75 | E9: =(D9-D8)/D8 -> -0.043181168 | H9: =H8+1 -> 6 | I9: =I8+365 -> 44285 | J9: 4670.7 | K9: =(J9-J8)/J8 -> 0.26972261
B10: =B9+1 -> 7 | C10: =C9+365 -> 44650 | D10: 278453.62 | E10: =(D10-D9)/D9 -> 0.11472967 | H10: =H9+1 -> 7 | I10: =I9+365 -> 44650 | J10: 2153.67 | K10: =(J10-J9)/J9 -> -0.53889781
B11: =B10+1 -> 8 | C11: =C10+365 -> 45015 | D11: 345966.97 | E11: =(D11-D10)/D10 -> 0.24245815 | H11: =H10+1 -> 8 | I11: =I10+365 -> 45015 | J11: 5640.38 | K11: =(J11-J10)/J10 -> 1.6189621
B12: =B11+1 -> 9 | C12: =C11+365 -> 45380 | D12: 434016 | E12: =(D12-D11)/D11 -> 0.25450126 | H12: =H11+1 -> 9 | I12: =I11+365 -> 45380 | J12: 8312.58 | K12: =(J12-J11)/J11 -> 0.47376241
B13: =B12+1 -> 10 | C13: =C12+365 -> 45745 | D13: 439695 | E13: =(D13-D12)/D12 -> 0.013084771 | H13: =H12+1 -> 10 | I13: =I12+365 -> 45745 | J13: 5596.21 | K13: =(J13-J12)/J12 -> -0.32677821
B14: =B13+1 -> 11 | C14: =C13+365 -> 46110 | D14: =_xlfn.FORECAST.LINEAR(B14,_xlfn.ANCHORARRAY($D$4),$B$4:$B$13) -> 460959.08 | E14: =(D14-D13)/D13 -> 0.048360984 | H14: =H13+1 -> 11 | I14: =I13+365 -> 46110 | J14: =_xlfn.FORECAST.LINEAR(H14,_xlfn.ANCHORARRAY($J$4),$H$4:$H$13) -> 6776.4067 | K14: =(J14-J13)/J13 -> 0.21089213
B15: =B14+1 -> 12 | C15: =C14+365 -> 46475 | D15: =_xlfn.FORECAST.LINEAR(B15,_xlfn.ANCHORARRAY($D$4),$B$4:$B$13) -> 492288.97 | E15: =(D15-D14)/D14 -> 0.067966736 | H15: =H14+1 -> 12 | I15: =I14+365 -> 46475 | J15: =_xlfn.FORECAST.LINEAR(H15,_xlfn.ANCHORARRAY($J$4),$H$4:$H$13) -> 7256.1106 | K15: =(J15-J14)/J14 -> 0.070790312
B16: =B15+1 -> 13 | C16: =C15+365 -> 46840 | D16: =_xlfn.FORECAST.LINEAR(B16,_xlfn.ANCHORARRAY($D$4),$B$4:$B$13) -> 523618.85 | E16: =(D16-D15)/D15 -> 0.063641248 | H16: =H15+1 -> 13 | I16: =I15+365 -> 46840 | J16: =_xlfn.FORECAST.LINEAR(H16,_xlfn.ANCHORARRAY($J$4),$H$4:$H$13) -> 7735.8145 | K16: =(J16-J15)/J15 -> 0.06611034
B17: =B16+1 -> 14 | C17: =C16+365 -> 47205 | D17: =_xlfn.FORECAST.LINEAR(B17,_xlfn.ANCHORARRAY($D$4),$B$4:$B$13) -> 554948.74 | E17: =(D17-D16)/D16 -> 0.059833377 | H17: =H16+1 -> 14 | I17: =I16+365 -> 47205 | J17: =_xlfn.FORECAST.LINEAR(H17,_xlfn.ANCHORARRAY($J$4),$H$4:$H$13) -> 8215.5185 | K17: =(J17-J16)/J16 -> 0.062010786
B18: =B17+1 -> 15 | C18: =C17+365 -> 47570 | D18: =_xlfn.FORECAST.LINEAR(B18,_xlfn.ANCHORARRAY($D$4),$B$4:$B$13) -> 586278.62 | E18: =(D18-D17)/D17 -> 0.056455457 | H18: =H17+1 -> 15 | I18: =I17+365 -> 47570 | J18: =_xlfn.FORECAST.LINEAR(H18,_xlfn.ANCHORARRAY($J$4),$H$4:$H$13) -> 8695.2224 | K18: =(J18-J17)/J17 -> 0.058389977

Sheet Common Size Statement
B2: ="Common Size Statement"&" "&" - "&'Data Sheet'!B1 -> Common Size Statement - ASIAN PAINTS LTD
B4: Particulars | C4: ='Data Sheet'!B16 -> 42460 | D4: ='Data Sheet'!C16 -> 42825 | E4: ='Data Sheet'!D16 -> 43190 | F4: ='Data Sheet'!E16 -> 43555 | G4: ='Data Sheet'!F16 -> 43921 | H4: ='Data Sheet'!G16 -> 44286 | I4: ='Data Sheet'!H16 -> 44651 | J4: ='Data Sheet'!I16 -> 45016 | ... L4: ='Data Sheet'!K16 -> 45747
B5: ='Data Sheet'!A17 -> Sales | C5: ='Data Sheet'!B17/'Data Sheet'!B$17 -> 1 | D5: ='Data Sheet'!C17/'Data Sheet'!C$17 -> 1 | E5: ='Data Sheet'!D17/'Data Sheet'!D$17 -> 1 | F5: ='Data Sheet'!E17/'Data Sheet'!E$17 -> 1 | G5: ='Data Sheet'!F17/'Data Sheet'!F$17 -> 1 | H5: ='Data Sheet'!G17/'Data Sheet'!G$17 -> 1 | I5: ='Data Sheet'!H17/'Data Sheet'!H$17 -> 1 | J5: ='Data Sheet'!I17/'Data Sheet'!I$17 -> 1 | ... L5: ='Data Sheet'!K17/'Data Sheet'!K$17 -> 1
B6: ='Data Sheet'!A18 -> Raw Material Cost | C6: ='Data Sheet'!B18/'Data Sheet'!B$17 -> 0.46034647 | D6: ='Data Sheet'!C18/'Data Sheet'!C$17 -> 0.49479518 | E6: ='Data Sheet'!D18/'Data Sheet'!D$17 -> 0.48311366 | F6: ='Data Sheet'!E18/'Data Sheet'!E$17 -> 0.51841646 | G6: ='Data Sheet'!F18/'Data Sheet'!F$17 -> 0.49388286 | H6: ='Data Sheet'!G18/'Data Sheet'!G$17 -> 0.48015709 | I6: ='Data Sheet'!H18/'Data Sheet'!H$17 -> 0.58840195 | J6: ='Data Sheet'!I18/'Data Sheet'!I$17 -> 0.55048728 | ... L6: ='Data Sheet'!K18/'Data Sheet'!K$17 -> 0.51627164
B7: ='Data Sheet'!A19 -> Change in Inventory | C7: ='Data Sheet'!B19/'Data Sheet'!B$17 -> -0.013967007 | D7: ='Data Sheet'!C19/'Data Sheet'!C$17 -> 0.035094964 | E7: ='Data Sheet'!D19/'Data Sheet'!D$17 -> -0.0084477742 | F7: ='Data Sheet'!E19/'Data Sheet'!E$17 -> 0.015242101 | G7: ='Data Sheet'!F19/'Data Sheet'!F$17 -> 0.011832519 | H7: ='Data Sheet'!G19/'Data Sheet'!G$17 -> 0.0042578591 | I7: ='Data Sheet'!H19/'Data Sheet'!H$17 -> 0.045529612 | J7: ='Data Sheet'!I19/'Data Sheet'!I$17 -> 0.0089806513 | ... L7: ='Data Sheet'!K19/'Data Sheet'!K$17 -> 0.0060461953
B8: ='Data Sheet'!A20 -> Power and Fuel | C8: ='Data Sheet'!B20/'Data Sheet'!B$17 -> 0.0080215871 | D8: ='Data Sheet'!C20/'Data Sheet'!C$17 -> 0.0070389105 | E8: ='Data Sheet'!D20/'Data Sheet'!D$17 -> 0.006555896 | F8: ='Data Sheet'!E20/'Data Sheet'!E$17 -> 0.0062177335 | G8: ='Data Sheet'!F20/'Data Sheet'!F$17 -> 0.0048383945 | H8: ='Data Sheet'!G20/'Data Sheet'!G$17 -> 0.0039631019 | I8: ='Data Sheet'!H20/'Data Sheet'!H$17 -> 0.0040283451 | J8: ='Data Sheet'!I20/'Data Sheet'!I$17 -> 0.0040097319 | ... L8: ='Data Sheet'!K20/'Data Sheet'!K$17 -> 0.0043821644
B9: ='Data Sheet'!A21 -> Other Mfr. Exp | C9: ='Data Sheet'!B21/'Data Sheet'!B$17 -> 0.10757251 | D9: ='Data Sheet'!C21/'Data Sheet'!C$17 -> 0.11039378 | E9: ='Data Sheet'!D21/'Data Sheet'!D$17 -> 0.10054831 | F9: ='Data Sheet'!E21/'Data Sheet'!E$17 -> 0.096795084 | G9: ='Data Sheet'!F21/'Data Sheet'!F$17 -> 0.096288948 | H9: ='Data Sheet'!G21/'Data Sheet'!G$17 -> 0.09525768 | I9: ='Data Sheet'!H21/'Data Sheet'!H$17 -> 0.098980182 | J9: ='Data Sheet'!I21/'Data Sheet'!I$17 -> 0.084555501 | ... L9: ='Data Sheet'!K21/'Data Sheet'!K$17 -> 0.079261196
B10: ='Data Sheet'!A22 -> Employee Cost | C10: ='Data Sheet'!B22/'Data Sheet'!B$17 -> 0.069718018 | D10: ='Data Sheet'!C22/'Data Sheet'!C$17 -> 0.069040678 | E10: ='Data Sheet'!D22/'Data Sheet'!D$17 -> 0.066681724 | F10: ='Data Sheet'!E22/'Data Sheet'!E$17 -> 0.064588441 | G10: ='Data Sheet'!F22/'Data Sheet'!F$17 -> 0.067846867 | H10: ='Data Sheet'!G22/'Data Sheet'!G$17 -> 0.071276423 | I10: ='Data Sheet'!H22/'Data Sheet'!H$17 -> 0.061667734 | J10: ='Data Sheet'!I22/'Data Sheet'!I$17 -> 0.059045905 | ... L10: ='Data Sheet'!K22/'Data Sheet'!K$17 -> 0.076853926
B11: ='Data Sheet'!A23 -> Selling and admin | C11: ='Data Sheet'!B23/'Data Sheet'!B$17 -> 0.27413396 | D11: ='Data Sheet'!C23/'Data Sheet'!C$17 -> 0.28973861 | E11: ='Data Sheet'!D23/'Data Sheet'!D$17 -> 0.13402558 | F11: ='Data Sheet'!E23/'Data Sheet'!E$17 -> 0.12301736 | G11: ='Data Sheet'!F23/'Data Sheet'!F$17 -> 0.11436749 | H11: ='Data Sheet'!G23/'Data Sheet'!G$17 -> 0.10342706 | I11: ='Data Sheet'!H23/'Data Sheet'!H$17 -> 0.10109452 | J11: ='Data Sheet'!I23/'Data Sheet'!I$17 -> 0.10150719 | ... L11: ='Data Sheet'!K23/'Data Sheet'!K$17 -> 0.11428607
B12: ='Data Sheet'!A24 -> Other Expenses | C12: ='Data Sheet'!B24/'Data Sheet'!B$17 -> -0.12470247 | D12: ='Data Sheet'!C24/'Data Sheet'!C$17 -> -0.13467477 | E12: ='Data Sheet'!D24/'Data Sheet'!D$17 -> 0.010190466 | F12: ='Data Sheet'!E24/'Data Sheet'!E$17 -> 0.010525397 | G12: ='Data Sheet'!F24/'Data Sheet'!F$17 -> 0.028939328 | H12: ='Data Sheet'!G24/'Data Sheet'!G$17 -> 0.026547947 | I12: ='Data Sheet'!H24/'Data Sheet'!H$17 -> 0.026291627 | J12: ='Data Sheet'!I24/'Data Sheet'!I$17 -> 0.027870377 | ... L12: ='Data Sheet'!K24/'Data Sheet'!K$17 -> 0.037846233
B13: ='Data Sheet'!A25 -> Other Income | C13: ='Data Sheet'!B25/'Data Sheet'!B$17 -> 0.014952188 | D13: ='Data Sheet'!C25/'Data Sheet'!C$17 -> 0.022433955 | E13: ='Data Sheet'!D25/'Data Sheet'!D$17 -> 0.019995186 | F13: ='Data Sheet'!E25/'Data Sheet'!E$17 -> 0.014229114 | G13: ='Data Sheet'!F25/'Data Sheet'!F$17 -> 0.017566949 | H13: ='Data Sheet'!G25/'Data Sheet'!G$17 -> 0.015274407 | I13: ='Data Sheet'!H25/'Data Sheet'!H$17 -> 0.01016725 | J13: ='Data Sheet'!I25/'Data Sheet'!I$17 -> 0.012510224 | ... L13: ='Data Sheet'!K25/'Data Sheet'!K$17 -> 0.010329261
B14: ='Data Sheet'!A26 -> Depreciation | C14: ='Data Sheet'!B26/'Data Sheet'!B$17 -> 0.019309827 | D14: ='Data Sheet'!C26/'Data Sheet'!C$17 -> 0.022227475 | E14: ='Data Sheet'!D26/'Data Sheet'!D$17 -> 0.021425239 | F14: ='Data Sheet'!E26/'Data Sheet'!E$17 -> 0.03233554 | G14: ='Data Sheet'!F26/'Data Sheet'!F$17 -> 0.038617107 | H14: ='Data Sheet'!G26/'Data Sheet'!G$17 -> 0.036442576 | I14: ='Data Sheet'!H26/'Data Sheet'!H$17 -> 0.028052374 | J14: ='Data Sheet'!I26/'Data Sheet'!I$17 -> 0.024878373 | ... L14: ='Data Sheet'!K26/'Data Sheet'!K$17 -> 0.030270498
B15: ='Data Sheet'!A27 -> Interest | C15: ='Data Sheet'!B27/'Data Sheet'!B$17 -> 0.0034334187 | D15: ='Data Sheet'!C27/'Data Sheet'!C$17 -> 0.0024784242 | E15: ='Data Sheet'!D27/'Data Sheet'!D$17 -> 0.0024648505 | F15: ='Data Sheet'!E27/'Data Sheet'!E$17 -> 0.0057416452 | G15: ='Data Sheet'!F27/'Data Sheet'!F$17 -> 0.0050630218 | H15: ='Data Sheet'!G27/'Data Sheet'!G$17 -> 0.0042200933 | I15: ='Data Sheet'!H27/'Data Sheet'!H$17 -> 0.0032785499 | J15: ='Data Sheet'!I27/'Data Sheet'!I$17 -> 0.0041883417 | ... L15: ='Data Sheet'!K27/'Data Sheet'!K$17 -> 0.0066956451
B16: ='Data Sheet'!A28 -> Profit before tax | C16: ='Data Sheet'!B28/'Data Sheet'!B$17 -> 0.18315186 | D16: ='Data Sheet'!C28/'Data Sheet'!C$17 -> 0.19649064 | E16: ='Data Sheet'!D28/'Data Sheet'!D$17 -> 0.18654169 | F16: ='Data Sheet'!E28/'Data Sheet'!E$17 -> 0.17183356 | G16: ='Data Sheet'!F28/'Data Sheet'!F$17 -> 0.17955545 | H16: ='Data Sheet'!G28/'Data Sheet'!G$17 -> 0.1982403 | I16: ='Data Sheet'!H28/'Data Sheet'!H$17 -> 0.14390157 | J16: ='Data Sheet'!I28/'Data Sheet'!I$17 -> 0.16494818 | ... L16: ='Data Sheet'!K28/'Data Sheet'!K$17 -> 0.15050809
... B19: ='Data Sheet'!A31 -> Dividend Amount | C19: ='Data Sheet'!B31/'Data Sheet'!B$17 -> 0.050408191 | D19: ='Data Sheet'!C31/'Data Sheet'!C$17 -> 0.065594254 | E19: ='Data Sheet'!D31/'Data Sheet'!D$17 -> 0.049600138 | F19: ='Data Sheet'!E31/'Data Sheet'!E$17 -> 0.05234684 | G19: ='Data Sheet'!F31/'Data Sheet'!F$17 -> 0.056950461 | H19: ='Data Sheet'!G31/'Data Sheet'!G$17 -> 0.078855366 | I19: ='Data Sheet'!H31/'Data Sheet'!H$17 -> 0.063119904 | J19: ='Data Sheet'!I31/'Data Sheet'!I$17 -> 0.071338086 | ... L19: ='Data Sheet'!K31/'Data Sheet'!K$17 -> 0.07016005
B20: EBIDTA | C20: =C18+C15+C14+C17 -> 0.20419942 | D20: =D18+D15+D14+D17 -> 0.21609628 | E20: =E18+E15+E14+E17 -> 0.20694937 | F20: =F18+F15+F14+F17 -> 0.20720182 | G20: =G18+G15+G14+G17 -> 0.21982064 | H20: =H18+H15+H14+H17 -> 0.23579604 | I20: =I18+I15+I14+I17 -> 0.17336866 | J20: =J18+J15+J14+J17 -> 0.19143781 | ... L20: =L18+L15+L14+L17 -> 0.18622134
B22: ="Common Size Balance Sheet "&" - "&'Data Sheet'!B1 -> Common Size Balance Sheet - ASIAN PAINTS LTD
B24: Particulars | C24: ='Data Sheet'!B16 -> 42460 | D24: ='Data Sheet'!C16 -> 42825 | E24: ='Data Sheet'!D16 -> 43190 | F24: ='Data Sheet'!E16 -> 43555 | G24: ='Data Sheet'!F16 -> 43921 | H24: ='Data Sheet'!G16 -> 44286 | I24: ='Data Sheet'!H16 -> 44651 | J24: ='Data Sheet'!I16 -> 45016 | ... L24: ='Data Sheet'!K16 -> 45747
B26: Total Liabilities | C26: ='Data Sheet'!B61/'Data Sheet'!B$61 -> 1 | D26: ='Data Sheet'!C61/'Data Sheet'!C$61 -> 1 | E26: ='Data Sheet'!D61/'Data Sheet'!D$61 -> 1 | F26: ='Data Sheet'!E61/'Data Sheet'!E$61 -> 1 | G26: ='Data Sheet'!F61/'Data Sheet'!F$61 -> 1 | H26: ='Data Sheet'!G61/'Data Sheet'!G$61 -> 1 | I26: ='Data Sheet'!H61/'Data Sheet'!H$61 -> 1 | J26: ='Data Sheet'!I61/'Data Sheet'!I$61 -> 1 | ... L26: ='Data Sheet'!K61/'Data Sheet'!K$61 -> 1
B27: ='Data Sheet'!A57 -> Equity Share Capital | C27: ='Data Sheet'!B62/'Data Sheet'!B$61 -> 0.32354771 | D27: ='Data Sheet'!C62/'Data Sheet'!C$61 -> 0.26631918 | E27: ='Data Sheet'!D62/'Data Sheet'!D$61 -> 0.27116979 | F27: ='Data Sheet'!E62/'Data Sheet'!E$61 -> 0.39981685 | G27: ='Data Sheet'!F62/'Data Sheet'!F$61 -> 0.38866784 | H27: ='Data Sheet'!G62/'Data Sheet'!G$61 -> 0.28781244 | I27: ='Data Sheet'!H62/'Data Sheet'!H$61 -> 0.24039362 | J27: ='Data Sheet'!I62/'Data Sheet'!I$61 -> 0.22384057 | ... L27: ='Data Sheet'!K62/'Data Sheet'!K$61 -> 0.30373988
B28: ='Data Sheet'!A58 -> Reserves | C28: ='Data Sheet'!B63/'Data Sheet'!B$61 -> 0.010094677 | D28: ='Data Sheet'!C63/'Data Sheet'!C$61 -> 0.020760665 | E28: ='Data Sheet'!D63/'Data Sheet'!D$61 -> 0.10208973 | F28: ='Data Sheet'!E63/'Data Sheet'!E$61 -> 0.01290369 | G28: ='Data Sheet'!F63/'Data Sheet'!F$61 -> 0.0086900645 | H28: ='Data Sheet'!G63/'Data Sheet'!G$61 -> 0.0089892873 | I28: ='Data Sheet'!H63/'Data Sheet'!H$61 -> 0.018574005 | J28: ='Data Sheet'!I63/'Data Sheet'!I$61 -> 0.039550679 | ... L28: ='Data Sheet'!K63/'Data Sheet'!K$61 -> 0.041326953
B29: ='Data Sheet'!A59 -> Borrowings | C29: ='Data Sheet'!B64/'Data Sheet'!B$61 -> 0.25685409 | D29: ='Data Sheet'!C64/'Data Sheet'!C$61 -> 0.21378068 | E29: ='Data Sheet'!D64/'Data Sheet'!D$61 -> 0.15553479 | F29: ='Data Sheet'!E64/'Data Sheet'!E$61 -> 0.15807775 | G29: ='Data Sheet'!F64/'Data Sheet'!F$61 -> 0.12509938 | H29: ='Data Sheet'!G64/'Data Sheet'!G$61 -> 0.23270552 | I29: ='Data Sheet'!H64/'Data Sheet'!H$61 -> 0.14145262 | J29: ='Data Sheet'!I64/'Data Sheet'!I$61 -> 0.165315 | ... L29: ='Data Sheet'!K64/'Data Sheet'!K$61 -> 0.15564853
B30: ='Data Sheet'!A60 -> Other Liabilities | C30: ='Data Sheet'!B65/'Data Sheet'!B$61 -> 0.40950352 | D30: ='Data Sheet'!C65/'Data Sheet'!C$61 -> 0.49913947 | E30: ='Data Sheet'!D65/'Data Sheet'!D$61 -> 0.47120568 | F30: ='Data Sheet'!E65/'Data Sheet'!E$61 -> 0.42920172 | G30: ='Data Sheet'!F65/'Data Sheet'!F$61 -> 0.47754271 | H30: ='Data Sheet'!G65/'Data Sheet'!G$61 -> 0.47049276 | I30: ='Data Sheet'!H65/'Data Sheet'!H$61 -> 0.59957976 | J30: ='Data Sheet'!I65/'Data Sheet'!I$61 -> 0.57129375 | ... L30: ='Data Sheet'!K65/'Data Sheet'!K$61 -> 0.49928464
B32: Total Assets | C32: ='Data Sheet'!B66/'Data Sheet'!B$66 -> 1 | D32: ='Data Sheet'!C66/'Data Sheet'!C$66 -> 1 | E32: ='Data Sheet'!D66/'Data Sheet'!D$66 -> 1 | F32: ='Data Sheet'!E66/'Data Sheet'!E$66 -> 1 | G32: ='Data Sheet'!F66/'Data Sheet'!F$66 -> 1 | H32: ='Data Sheet'!G66/'Data Sheet'!G$66 -> 1 | I32: ='Data Sheet'!H66/'Data Sheet'!H$66 -> 1 | J32: ='Data Sheet'!I66/'Data Sheet'!I$66 -> 1 | ... L32: ='Data Sheet'!K66/'Data Sheet'!K$66 -> 1
B33: Net Block | C33: ='Data Sheet'!B62/'Data Sheet'!B$66 -> 0.32354771 | D33: ='Data Sheet'!C62/'Data Sheet'!C$66 -> 0.26631918 | E33: ='Data Sheet'!D62/'Data Sheet'!D$66 -> 0.27116979 | F33: ='Data Sheet'!E62/'Data Sheet'!E$66 -> 0.39981685 | G33: ='Data Sheet'!F62/'Data Sheet'!F$66 -> 0.38866784 | H33: ='Data Sheet'!G62/'Data Sheet'!G$66 -> 0.28781244 | I33: ='Data Sheet'!H62/'Data Sheet'!H$66 -> 0.24039362 | J33: ='Data Sheet'!I62/'Data Sheet'!I$66 -> 0.22384057 | ... L33: ='Data Sheet'!K62/'Data Sheet'!K$66 -> 0.30373988
B34: Capital Work in Progress | C34: ='Data Sheet'!B63/'Data Sheet'!B$66 -> 0.010094677 | D34: ='Data Sheet'!C63/'Data Sheet'!C$66 -> 0.020760665 | E34: ='Data Sheet'!D63/'Data Sheet'!D$66 -> 0.10208973 | F34: ='Data Sheet'!E63/'Data Sheet'!E$66 -> 0.01290369 | G34: ='Data Sheet'!F63/'Data Sheet'!F$66 -> 0.0086900645 | H34: ='Data Sheet'!G63/'Data Sheet'!G$66 -> 0.0089892873 | I34: ='Data Sheet'!H63/'Data Sheet'!H$66 -> 0.018574005 | J34: ='Data Sheet'!I63/'Data Sheet'!I$66 -> 0.039550679 | ... L34: ='Data Sheet'!K63/'Data Sheet'!K$66 -> 0.041326953
B35: Investments | C35: ='Data Sheet'!B64/'Data Sheet'!B$66 -> 0.25685409 | D35: ='Data Sheet'!C64/'Data Sheet'!C$66 -> 0.21378068 | E35: ='Data Sheet'!D64/'Data Sheet'!D$66 -> 0.15553479 | F35: ='Data Sheet'!E64/'Data Sheet'!E$66 -> 0.15807775 | G35: ='Data Sheet'!F64/'Data Sheet'!F$66 -> 0.12509938 | H35: ='Data Sheet'!G64/'Data Sheet'!G$66 -> 0.23270552 | I35: ='Data Sheet'!H64/'Data Sheet'!H$66 -> 0.14145262 | J35: ='Data Sheet'!I64/'Data Sheet'!I$66 -> 0.165315 | ... L35: ='Data Sheet'!K64/'Data Sheet'!K$66 -> 0.15564853
B36: Receivables | C36: ='Data Sheet'!B67/'Data Sheet'!B$66 -> 0.11240048 | D36: ='Data Sheet'!C67/'Data Sheet'!C$66 -> 0.11661248 | E36: ='Data Sheet'!D67/'Data Sheet'!D$66 -> 0.12574073 | F36: ='Data Sheet'!E67/'Data Sheet'!E$66 -> 0.11738253 | G36: ='Data Sheet'!F67/'Data Sheet'!F$66 -> 0.111242 | H36: ='Data Sheet'!G67/'Data Sheet'!G$66 -> 0.12783722 | I36: ='Data Sheet'!H67/'Data Sheet'!H$66 -> 0.16862826 | J36: ='Data Sheet'!I67/'Data Sheet'!I$66 -> 0.17987046 | ... L36: ='Data Sheet'!K67/'Data Sheet'!K$66 -> 0.14210557
B37: Inventory | C37: ='Data Sheet'!B68/'Data Sheet'!B$66 -> 0.18924466 | D37: ='Data Sheet'!C68/'Data Sheet'!C$66 -> 0.21176137 | E37: ='Data Sheet'!D68/'Data Sheet'!D$66 -> 0.19314229 | F37: ='Data Sheet'!E68/'Data Sheet'!E$66 -> 0.19385138 | G37: ='Data Sheet'!F68/'Data Sheet'!F$66 -> 0.21005182 | H37: ='Data Sheet'!G68/'Data Sheet'!G$66 -> 0.18661442 | I37: ='Data Sheet'!H68/'Data Sheet'!H$66 -> 0.26800526 | J37: ='Data Sheet'!I68/'Data Sheet'!I$66 -> 0.24091549 | ... L37: ='Data Sheet'!K68/'Data Sheet'!K$66 -> 0.22135446
B38: Cash & Bank | C38: ='Data Sheet'!B69/'Data Sheet'!B$66 -> 0.040174145 | D38: ='Data Sheet'!C69/'Data Sheet'!C$66 -> 0.064586677 | E38: ='Data Sheet'!D69/'Data Sheet'!D$66 -> 0.029400268 | F38: ='Data Sheet'!E69/'Data Sheet'!E$66 -> 0.027379185 | G38: ='Data Sheet'!F69/'Data Sheet'!F$66 -> 0.048508579 | H38: ='Data Sheet'!G69/'Data Sheet'!G$66 -> 0.030004412 | I38: ='Data Sheet'!H69/'Data Sheet'!H$66 -> 0.037647609 | J38: ='Data Sheet'!I69/'Data Sheet'!I$66 -> 0.032732426 | ... L38: ='Data Sheet'!K69/'Data Sheet'!K$66 -> 0.025760947
B39: Other assets | C39: ='Data Sheet'!B74/'Data Sheet'!B$66 -> 0.067684248 | D39: ='Data Sheet'!C74/'Data Sheet'!C$66 -> 0.10617895 | E39: ='Data Sheet'!D74/'Data Sheet'!D$66 -> 0.1229224 | F39: ='Data Sheet'!E74/'Data Sheet'!E$66 -> 0.09058862 | G39: ='Data Sheet'!F74/'Data Sheet'!F$66 -> 0.10774032 | H39: ='Data Sheet'!G74/'Data Sheet'!G$66 -> 0.12603671 | I39: ='Data Sheet'!H74/'Data Sheet'!H$66 -> 0.12529864 | J39: ='Data Sheet'!I74/'Data Sheet'!I$66 -> 0.11777536 | ... L39: ='Data Sheet'!K74/'Data Sheet'!K$66 -> 0.11006366

Sheet Intrinsic Growth
B2: Calculation of ROIC | E2: ='[1]Data Room>'!I1 -> 44256 | F2: ='[1]Data Room>'!J1 -> 44621 | G2: ='[1]Data Room>'!K1 -> 44986 | H2: ='[1]Data Room>'!L1 -> 45352 | I2: ='[1]Data Room>'!M1 -> 45717
B4: Current Assets
B5: ='[1]Data Room>'!A32 -> Inventories | E5: ='[1]Data Room>'!I32 -> 3799 | F5: ='[1]Data Room>'!J32 -> 6153 | G5: ='[1]Data Room>'!K32 -> 6211 | H5: ='[1]Data Room>'!L32 -> 5923 | I5: ='[1]Data Room>'!M32 -> 6719
B6: ='[1]Data Room>'!A33 -> Trade receivables - | E6: ='[1]Data Room>'!I33 -> 2602 | F6: ='[1]Data Room>'!J33 -> 3871 | G6: ='[1]Data Room>'!K33 -> 4637 | H6: ='[1]Data Room>'!L33 -> 4889 | I6: ='[1]Data Room>'!M33 -> 4314
B7: ='[1]Data Room>'!A34 -> Prov for Doubtful | E7: ='[1]Data Room>'!I34 -> -185 | F7: ='[1]Data Room>'!J34 -> -241 | G7: ='[1]Data Room>'!K34 -> -305 | H7: ='[1]Data Room>'!L34 -> -422 | I7: ='[1]Data Room>'!M34 -> -663
B8: ='[1]Data Room>'!A36 -> Loans n Advances | E8: ='[1]Data Room>'!I36 -> 11 | F8: ='[1]Data Room>'!J36 -> 8 | G8: ='[1]Data Room>'!K36 -> 12 | H8: ='[1]Data Room>'!L36 -> 17 | I8: ='[1]Data Room>'!M36 -> 22
B9: ='[1]Data Room>'!A37 -> Other asset items | E9: ='[1]Data Room>'!I37 -> 2555 | F9: ='[1]Data Room>'!J37 -> 2869 | G9: ='[1]Data Room>'!K37 -> 3024 | H9: ='[1]Data Room>'!L37 -> 3555 | I9: ='[1]Data Room>'!M37 -> 3319
B10: Total Current Assets | E10: =SUM(E5:E9) -> 8782 | F10: =SUM(F5:F9) -> 12660 | G10: =SUM(G5:G9) -> 13579 | H10: =SUM(H5:H9) -> 13962 | I10: =SUM(I5:I9) -> 13711
B13: Current Liabilities
B14: ='[1]Data Room>'!A11 -> Trade Payables | E14: ='[1]Data Room>'!I11 -> 3379 | F14: ='[1]Data Room>'!J11 -> 4164 | G14: ='[1]Data Room>'!K11 -> 3635 | H14: ='[1]Data Room>'!L11 -> 3831 | I14: ='[1]Data Room>'!M11 -> 3848
B15: ='[1]Data Room>'!A12 -> Advance from Customers | E15: ='[1]Data Room>'!I12 -> 41 | F15: ='[1]Data Room>'!J12 -> 76 | G15: ='[1]Data Room>'!K12 -> 108 | H15: ='[1]Data Room>'!L12 -> 154 | I15: ='[1]Data Room>'!M12 -> 173
B16: ='[1]Data Room>'!A13 -> Other liability items | E16: ='[1]Data Room>'!I13 -> 2613 | F16: ='[1]Data Room>'!J13 -> 2932 | G16: ='[1]Data Room>'!K13 -> 3657 | H16: ='[1]Data Room>'!L13 -> 4017 | I16: ='[1]Data Room>'!M13 -> 3985
B17: Total Current Liabilities | E17: =SUM(E14:E16) -> 6033 | F17: =SUM(F14:F16) -> 7172 | G17: =SUM(G14:G16) -> 7400 | H17: =SUM(H14:H16) -> 8002 | I17: =SUM(I14:I16) -> 8006
A19: # | B19: Net Working Capital | E19: =E10-E17 -> 2749 | F19: =F10-F17 -> 5488 | G19: =G10-G17 -> 6179 | H19: =H10-H17 -> 5960 | I19: =I10-I17 -> 5705
B21: Non-current Assets
B22: ='[1]Data Room>'!A16 -> Land | E22: ='[1]Data Room>'!I16 -> 644 | F22: ='[1]Data Room>'!J16 -> 644 | G22: ='[1]Data Room>'!K16 -> 804 | H22: ='[1]Data Room>'!L16 -> 1126 | I22: ='[1]Data Room>'!M16 -> 1050
B23: ='[1]Data Room>'!A17 -> Building | E23: ='[1]Data Room>'!I17 -> 2249 | F23: ='[1]Data Room>'!J17 -> 2325 | G23: ='[1]Data Room>'!K17 -> 2883 | H23: ='[1]Data Room>'!L17 -> 3390 | I23: ='[1]Data Room>'!M17 -> 4136
B24: ='[1]Data Room>'!A18 -> Plant Machinery | E24: ='[1]Data Room>'!I18 -> 4340 | F24: ='[1]Data Room>'!J18 -> 4531 | G24: ='[1]Data Room>'!K18 -> 4825 | H24: ='[1]Data Room>'!L18 -> 5422 | I24: ='[1]Data Room>'!M18 -> 7576
B25: ='[1]Data Room>'!A19 -> Equipments | E25: ='[1]Data Room>'!I19 -> 243 | F25: ='[1]Data Room>'!J19 -> 253 | G25: ='[1]Data Room>'!K19 -> 270 | H25: ='[1]Data Room>'!L19 -> 298 | I25: ='[1]Data Room>'!M19 -> 325
B26: ='[1]Data Room>'!A20 -> Furniture n fittings | E26: ='[1]Data Room>'!I20 -> 99 | F26: ='[1]Data Room>'!J20 -> 113 | G26: ='[1]Data Room>'!K20 -> 146 | H26: ='[1]Data Room>'!L20 -> 175 | I26: ='[1]Data Room>'!M20 -> 203
B27: ='[1]Data Room>'!A21 -> Vehicles | E27: ='[1]Data Room>'!I21 -> 38 | F27: ='[1]Data Room>'!J21 -> 32 | G27: ='[1]Data Room>'!K21 -> 36 | H27: ='[1]Data Room>'!L21 -> 40 | I27: ='[1]Data Room>'!M21 -> 39
B28: ='[1]Data Room>'!A22 -> Intangible Assets | E28: ='[1]Data Room>'!I22 -> 476 | F28: ='[1]Data Room>'!J22 -> 345 | G28: ='[1]Data Room>'!K22 -> 422 | H28: ='[1]Data Room>'!L22 -> 850 | I28: ='[1]Data Room>'!M22 -> 827
B29: ='[1]Data Room>'!A23 -> Other fixed assets | E29: ='[1]Data Room>'!I23 -> 302 | F29: ='[1]Data Room>'!J23 -> 294 | G29: ='[1]Data Room>'!K23 -> 289 | H29: ='[1]Data Room>'!L23 -> 321 | I29: ='[1]Data Room>'!M23 -> 328
B30: Gross Block | E30: =SUM(E22:E29) -> 8391 | F30: =SUM(F22:F29) -> 8537 | G30: =SUM(G22:G29) -> 9675 | H30: =SUM(H22:H29) -> 11622 | I30: =SUM(I22:I29) -> 14484
B31: Accumulated Depreceation | E31: ='[1]Data Room>'!B25 -> 1242 | F31: ='[1]Data Room>'!C25 -> 1452 | G31: ='[1]Data Room>'!D25 -> 327 | H31: ='[1]Data Room>'!E25 -> 610 | I31: ='[1]Data Room>'!F25 -> 973
B32: Net non-current assets | E32: =E30-E31 -> 7149 | F32: =F30-F31 -> 7085 | G32: =G30-G31 -> 9348 | H32: =H30-H31 -> 11012 | I32: =I30-I31 -> 13511
A34: # | B34: Invested Capital | E34: =E32+E19 -> 9898 | F34: =F32+F19 -> 12573 | G34: =G32+G19 -> 15527 | H34: =H32+H19 -> 16972 | I34: =I32+I19 -> 19216
B35: EBIT | E35: ='Historical FS'!C25+'Historical FS'!C19 -> 2449.46 | F35: ='Historical FS'!D25+'Historical FS'!D19 -> 1601.77 | G35: ='Historical FS'!E25+'Historical FS'!E19 -> 3127.8 | H35: ='Historical FS'!F25+'Historical FS'!F19 -> 2556.28 | I35: ='Historical FS'!G25+'Historical FS'!G19 -> 2898.02
A37: # | B37: ROIC | E37: =E35/E34 -> 0.2474702 | F37: =F35/F34 -> 0.1273976 | G37: =G35/G34 -> 0.20144265 | H37: =H35/H34 -> 0.15061749 | I37: =I35/I34 -> 0.15081286
B39: Calculation of Reinvestment Rate | E39: ='Data Room >'!I1 -> 44256 | F39: ='Data Room >'!J1 -> 44621 | G39: ='Data Room >'!K1 -> 44986 | H39: ='Data Room >'!L1 -> 45352 | I39: ='Data Room >'!M1 -> 45717
B41: Net Capex | E41: =-SUM('Raw FS'!I13:I14) -> 280 | F41: =-SUM('Raw FS'!J13:J14) -> 192 | G41: =-SUM('Raw FS'!K13:K14) -> 388 | H41: =-SUM('Raw FS'!L13:L14) -> 1208 | I41: =-SUM('Raw FS'!M13:M14) -> 2185
B42: Change in working capital | F42: =F19-E19 -> 2739 | G42: =G19-F19 -> 691 | H42: =H19-G19 -> -219 | I42: =I19-H19 -> -255
B44: EBIT | E44: =E35 -> 2449.46 | F44: =F35 -> 1601.77 | G44: =G35 -> 3127.8 | H44: =H35 -> 2556.28 | I44: =I35 -> 2898.02
B45: Marginal tax rate | E45: 0.25 | F45: 0.25 | G45: 0.25 | H45: 0.25 | I45: 0.25
B46: EBIT(1-T) | E46: =E44*(1-E45) -> 1837.095 | F46: =F44*(1-F45) -> 1201.3275 | G46: =G44*(1-G45) -> 2345.85 | H46: =H44*(1-H45) -> 1917.21 | I46: =I44*(1-I45) -> 2173.515
B48: Reinvestment | F48: =SUM(F41:F42) -> 2931 | G48: =SUM(G41:G42) -> 1079 | H48: =SUM(H41:H42) -> 989 | I48: =SUM(I41:I42) -> 1930
B49: Reinvestment Rate | F49: =F48/F42 -> 1.0700986 | G49: =G48/G42 -> 1.5615051 | H49: =H48/H42 -> -4.5159817 | I49: =I48/I42 -> -7.5686275
G51: 4 - year average | I51: =AVERAGE(F49:I49) -> -2.3632514
G52: 4 - year median | I52: =MEDIAN(F49:I49) -> -1.7229416
B54: Calculation of Growth Rate | E54: 44256 | F54: 44621 | G54: 44986 | H54: 45352 | I54: 45717
...

Sheet DCF
B2: Calculation of PV of FCFF | F2: ='Cashflow Data'!N2 -> 45717 | G2: =F2+365 -> 46082 | H2: =G2+365 -> 46447 | I2: =H2+365 -> 46812 | J2: =I2+365 -> 47177 | K2: =J2+365 -> 47542
B4: EBIT | F4: ='Historical FS'!L16-'Historical FS'!L22 -> 4569.87 | G4: =F4*(1+$F$14) -> 5518.118 | H4: =G4*(1+$F$14) -> 6663.1275 | I4: =H4*(1+$F$14) -> 8045.7265 | J4: =I4*(1+$F$14) -> 9715.2147 | K4: =J4*(1+$F$14) -> 11731.122
B5: Tax Rate | F5: 0.25 | G5: 0.25 | H5: 0.25 | I5: 0.25 | J5: 0.25 | K5: 0.25
B6: EBIT (1-T) | F6: =F4*(1-F5) -> 3427.4025 | G6: =G4*(1-G5) -> 4138.5885 | H6: =H4*(1-H5) -> 4997.3456 | I6: =I4*(1-I5) -> 6034.2949 | J6: =J4*(1-J5) -> 7286.411 | K6: =K4*(1-K5) -> 8798.3413
B7: Less : Reinvestment Rate | F7: 0.4914 | G7: 0.4914 | H7: 0.4914 | I7: 0.4914 | J7: 0.4914 | K7: 0.4914
B8: Free Cashflow to firm | F8: =F6*(1-F7) -> 1743.1769 | G8: =G6*(1-G7) -> 2104.8861 | H8: =H6*(1-H7) -> 2541.65 | I8: =I6*(1-I7) -> 3069.0424 | J8: =J6*(1-J7) -> 3705.8687 | K8: =K6*(1-K7) -> 4474.8364
B9: Mid year convention | G9: 0.5 | H9: =G9+1 -> 1.5 | I9: =H9+1 -> 2.5 | J9: =I9+1 -> 3.5 | K9: =J9+1 -> 4.5
B10: Discounting factor | G10: =1/(1+$F$16)^G9 -> 0.91271882 | H10: =1/(1+$F$16)^H9 -> 0.76034557 | I10: =1/(1+$F$16)^I9 -> 0.63341017 | J10: =1/(1+$F$16)^J9 -> 0.52766592 | K10: =1/(1+$F$16)^K9 -> 0.43957508
B12: PV of FCFF | G12: =G8*G10 -> 1921.1692 | H12: =H8*H10 -> 1932.5323 | I12: =I8*I10 -> 1943.9626 | J12: =J8*J10 -> 1955.4606 | K12: =K8*K10 -> 1967.0265
B14: Expected growth (Sector growth) | F14: 0.2075
B15: Terminal growth (GDP growth rate) | F15: 0.0578
B16: WACC | F16: 0.2004
B18: Calculation of Terminal Value
B20: FCFF (n+1) | E20: =K8*(1+F14) -> 5403.365
B21: WACC | E21: =F16 -> 0.2004
B22: Terminal Growth | E22: =F15 -> 0.0578
B24: Terminal Value | E24: =E20/(E21-E22) -> 37891.76
B27: Calculation of Equity value per share
B29: PV of FCFF | E29: =SUM(G12:K12) -> 9720.1513
B30: PV of terminal value | E30: =E24*K10 -> 16656.273
B31: Value of operating assets | E31: =SUM(E29:E30) -> 26376.424
B33: Add: Cash | E33: ='Data Sheet'!K69 -> 781.98
B34: Less : Debt | E34: =SUM('Data Room >'!M5:M6) -> 864
B35: Value of Equity | E35: =E31+E33-E34 -> 26294.404
B37: No. of shares | E37: ='Data Sheet'!K57 -> 95.92
B39: Equity value per share | E39: =E35/E37 -> 274.12849

Sheet Historical FS
B2: ="Historical Financial Statements - "&'Data Sheet'!B1 -> Historical Financial Statements - ASIAN PAINTS LTD
B3: Years | C3: ='Data Sheet'!B16 -> 42460 | D3: ='Data Sheet'!C16 -> 42825 | E3: ='Data Sheet'!D16 -> 43190 | F3: ='Data Sheet'!E16 -> 43555 | G3: ='Data Sheet'!F16 -> 43921 | H3: ='Data Sheet'!G16 -> 44286 | I3: ='Data Sheet'!H16 -> 44651 | J3: ='Data Sheet'!I16 -> 45016 | ... L3: ='Data Sheet'!K16 -> 45747 | M3: LTM
A4: # | B4: Income Statement
B5: Sales | C5: =IFERROR('Data Sheet'!B17,0) -> 14271.49 | D5: =IFERROR('Data Sheet'!C17,0) -> 15061.99 | E5: =IFERROR('Data Sheet'!D17,0) -> 16824.55 | F5: =IFERROR('Data Sheet'!E17,0) -> 19240.13 | G5: =IFERROR('Data Sheet'!F17,0) -> 20211.25 | H5: =IFERROR('Data Sheet'!G17,0) -> 21712.79 | I5: =IFERROR('Data Sheet'!H17,0) -> 29101.28 | J5: =IFERROR('Data Sheet'!I17,0) -> 34488.59 | ... L5: =IFERROR('Data Sheet'!K17,0) -> 33905.62 | M5: =IFERROR(SUM('Data Sheet'!H42:K42),0) -> 33874.44
B6: Sales Growth | C6: ="-" -> - | D6: =IFERROR((D5-C5)/C5,0) -> 0.055390152 | E6: =IFERROR((E5-D5)/D5,0) -> 0.11702039 | F6: =IFERROR((F5-E5)/E5,0) -> 0.14357472 | G6: =IFERROR((G5-F5)/F5,0) -> 0.050473671 | H6: =IFERROR((H5-G5)/G5,0) -> 0.074292288 | I6: =IFERROR((I5-H5)/H5,0) -> 0.34028285 | J6: =IFERROR((J5-I5)/I5,0) -> 0.18512278 | K6: =IFERROR((K5-J5)/J5,0) -> 0.029173127 | ... M6: =IFERROR((M5-L5)/L5,0) -> -0.00091961156
B8: COGS | C8: =IFERROR(SUM('Data Sheet'!B18,'Data Sheet'!B20:B22,-1*'Data Sheet'!B19),0) -> 9413.84 | D8: =IFERROR(SUM('Data Sheet'!C18:C22),0) -> 10789.86 | E8: =IFERROR(SUM('Data Sheet'!D18:D22),0) -> 10909.91 | F8: =IFERROR(SUM('Data Sheet'!E18:E22),0) -> 13492.33 | G8: =IFERROR(SUM('Data Sheet'!F18:F22),0) -> 13636.32 | H8: =IFERROR(SUM('Data Sheet'!G18:G22),0) -> 14219.97 | I8: =IFERROR(SUM('Data Sheet'!H18:H22),0) -> 23240.51 | J8: =IFERROR(SUM('Data Sheet'!I18:I22),0) -> 24386.16 | K8: =IFERROR(SUM('Data Sheet'!J18:J22),0) -> 22282.39 | L8: =IFERROR(SUM('Data Sheet'!K18:K22),0) -> 23151.27 | M8: =IFERROR(SUM('Data Sheet'!H43:K43),0) -> 27937.03
B9: COGS % Sales | C9: =C8/C5 -> 0.65962559 | D9: =D8/D5 -> 0.71636351 | E9: =E8/E5 -> 0.64845182 | F9: =F8/F5 -> 0.70125981 | G9: =G8/G5 -> 0.67468959 | H9: =H8/H5 -> 0.65491215 | I9: =I8/I5 -> 0.79860783 | J9: =J8/J5 -> 0.70707907 | ... M9: =M8/M5 -> 0.82472301
B11: Gross Profit | C11: =C5-C8 -> 4857.65 | D11: =D5-D8 -> 4272.13 | E11: =E5-E8 -> 5914.64 | F11: =F5-F8 -> 5747.8 | G11: =G5-G8 -> 6574.93 | H11: =H5-H8 -> 7492.82 | I11: =I5-I8 -> 5860.77 | J11: =J5-J8 -> 10102.43 | ... M11: =M5-M8 -> 5937.41
B13: Selling and general expenses | C13: =IFERROR(SUM('Data Sheet'!B23:B24),0) -> 2132.61 | D13: =IFERROR(SUM('Data Sheet'!C23:C24),0) -> 2335.57 | E13: =IFERROR(SUM('Data Sheet'!D23:D24),0) -> 2426.37 | F13: =IFERROR(SUM('Data Sheet'!E23:E24),0) -> 2569.38 | G13: =IFERROR(SUM('Data Sheet'!F23:F24),0) -> 2896.41 | H13: =IFERROR(SUM('Data Sheet'!G23:G24),0) -> 2822.12 | I13: =IFERROR(SUM('Data Sheet'!H23:H24),0) -> 3707.1 | J13: =IFERROR(SUM('Data Sheet'!I23:I24),0) -> 4462.05 | ... M13: =IFERROR(SUM('Data Sheet'!L23:L24),0) -> 0
B14: S&G Expenses % Sales | C14: =C13/C5 -> 0.14943149 | D14: =D13/D5 -> 0.15506384 | E14: =E13/E5 -> 0.14421604 | F14: =F13/F5 -> 0.13354276 | G14: =G13/G5 -> 0.14330682 | H14: =H13/H5 -> 0.12997501 | I14: =I13/I5 -> 0.12738615 | J14: =J13/J5 -> 0.12937757 | ... M14: =M13/M5 -> 0
B16: EBIDTA | C16: =C11-C13 -> 2725.04 | D16: =D11-D13 -> 1936.56 | E16: =E11-E13 -> 3488.27 | F16: =F11-F13 -> 3178.42 | G16: =G11-G13 -> 3678.52 | H16: =H11-H13 -> 4670.7 | I16: =I11-I13 -> 2153.67 | J16: =J11-J13 -> 5640.38 | ... M16: =M11-M13 -> 5937.41
B17: EBIDTA % Margins | C17: =C16/C5 -> 0.19094292 | D17: =D16/D5 -> 0.12857265 | E17: =E16/E5 -> 0.20733214 | F17: =F16/F5 -> 0.16519743 | G17: =G16/G5 -> 0.18200359 | H17: =H16/H5 -> 0.21511284 | I17: =I16/I5 -> 0.074006023 | J17: =J16/J5 -> 0.16354336 | ... M17: =M16/M5 -> 0.17527699
B19: Interest | C19: =IFERROR('Data Sheet'!B27,0) -> 49 | D19: =IFERROR('Data Sheet'!C27,0) -> 37.33 | E19: =IFERROR('Data Sheet'!D27,0) -> 41.47 | F19: =IFERROR('Data Sheet'!E27,0) -> 110.47 | G19: =IFERROR('Data Sheet'!F27,0) -> 102.33 | H19: =IFERROR('Data Sheet'!G27,0) -> 91.63 | I19: =IFERROR('Data Sheet'!H27,0) -> 95.41 | J19: =IFERROR('Data Sheet'!I27,0) -> 144.45 | ... L19: =IFERROR('Data Sheet'!K27,0) -> 227.02 | M19: =IFERROR(SUM('Data Sheet'!H46:K46),0) -> 216.14
B20: Interest % Sales | C20: =C19/C5 -> 0.0034334187 | D20: =D19/D5 -> 0.0024784242 | E20: =E19/E5 -> 0.0024648505 | F20: =F19/F5 -> 0.0057416452 | G20: =G19/G5 -> 0.0050630218 | H20: =H19/H5 -> 0.0042200933 | I20: =I19/I5 -> 0.0032785499 | J20: =J19/J5 -> 0.0041883417 | ... M20: =M19/M5 -> 0.0063806221
B22: Depreciation | C22: =IFERROR('Data Sheet'!B26,0) -> 275.58 | D22: =IFERROR('Data Sheet'!C26,0) -> 334.79 | E22: =IFERROR('Data Sheet'!D26,0) -> 360.47 | F22: =IFERROR('Data Sheet'!E26,0) -> 622.14 | G22: =IFERROR('Data Sheet'!F26,0) -> 780.5 | H22: =IFERROR('Data Sheet'!G26,0) -> 791.27 | I22: =IFERROR('Data Sheet'!H26,0) -> 816.36 | J22: =IFERROR('Data Sheet'!I26,0) -> 858.02 | ... L22: =IFERROR('Data Sheet'!K26,0) -> 1026.34 | M22: =IFERROR(SUM('Data Sheet'!H45:K45),0) -> 1099.51
B23: Depreciation % Sales | C23: =IFERROR(C22/C5,0) -> 0.019309827 | D23: =IFERROR(D22/D5,0) -> 0.022227475 | E23: =IFERROR(E22/E5,0) -> 0.021425239 | F23: =IFERROR(F22/F5,0) -> 0.03233554 | G23: =IFERROR(G22/G5,0) -> 0.038617107 | H23: =IFERROR(H22/H5,0) -> 0.036442576 | I23: =IFERROR(I22/I5,0) -> 0.028052374 | J23: =IFERROR(J22/J5,0) -> 0.024878373 | ... M23: =IFERROR(M22/M5,0) -> 0.032458396
B25: Earnings before taxes | C25: =IFERROR(C16-SUM(C19,C22),0) -> 2400.46 | D25: =IFERROR(D16-SUM(D19,D22),0) -> 1564.44 | E25: =IFERROR(E16-SUM(E19,E22),0) -> 3086.33 | F25: =IFERROR(F16-SUM(F19,F22),0) -> 2445.81 | G25: =IFERROR(G16-SUM(G19,G22),0) -> 2795.69 | H25: =IFERROR(H16-SUM(H19,H22),0) -> 3787.8 | I25: =IFERROR(I16-SUM(I19,I22),0) -> 1241.9 | J25: =IFERROR(J16-SUM(J19,J22),0) -> 4637.91 | ... M25: =IFERROR(M16-SUM(M19,M22),0) -> 4621.76
B26: EBT % Sales | C26: =IFERROR(C25/C5,0) -> 0.16819968 | D26: =IFERROR(D25/D5,0) -> 0.10386675 | E26: =IFERROR(E25/E5,0) -> 0.18344205 | F26: =IFERROR(F25/F5,0) -> 0.12712024 | G26: =IFERROR(G25/G5,0) -> 0.13832346 | H26: =IFERROR(H25/H5,0) -> 0.17445017 | I26: =IFERROR(I25/I5,0) -> 0.042675099 | J26: =IFERROR(J25/J5,0) -> 0.13447665 | ... M26: =IFERROR(M25/M5,0) -> 0.13643798
B28: Tax | C28: =IFERROR('Data Sheet'!B29,0) -> 844.49 | D28: =IFERROR('Data Sheet'!C29,0) -> 943.29 | E28: =IFERROR('Data Sheet'!D29,0) -> 1040.96 | F28: =IFERROR('Data Sheet'!E29,0) -> 1098.06 | G28: =IFERROR('Data Sheet'!F29,0) -> 854.85 | H28: =IFERROR('Data Sheet'!G29,0) -> 1097.6 | I28: =IFERROR('Data Sheet'!H29,0) -> 1102.91 | J28: =IFERROR('Data Sheet'!I29,0) -> 1493.5 | ... L28: =IFERROR('Data Sheet'!K29,0) -> 1393.36 | M28: =IFERROR(SUM('Data Sheet'!H48:K48),0) -> 1368.19
B29: Effective tax rate | C29: =IFERROR(C28/C25,0) -> 0.3518034 | D29: =IFERROR(D28/D25,0) -> 0.60295697 | E29: =IFERROR(E28/E25,0) -> 0.33728085 | F29: =IFERROR(F28/F25,0) -> 0.44895556 | G29: =IFERROR(G28/G25,0) -> 0.30577425 | H29: =IFERROR(H28/H25,0) -> 0.28977243 | I29: =IFERROR(I28/I25,0) -> 0.88808278 | J29: =IFERROR(J28/J25,0) -> 0.32202005 | ... M29: =IFERROR(M28/M25,0) -> 0.29603225
B31: Net Profit | C31: =IFERROR(C25-C28,0) -> 1555.97 | D31: =IFERROR(D25-D28,0) -> 621.15 | E31: =IFERROR(E25-E28,0) -> 2045.37 | F31: =IFERROR(F25-F28,0) -> 1347.75 | G31: =IFERROR(G25-G28,0) -> 1940.84 | H31: =IFERROR(H25-H28,0) -> 2690.2 | I31: =IFERROR(I25-I28,0) -> 138.99 | J31: =IFERROR(J25-J28,0) -> 3144.41 | ... L31: =IFERROR(L25-L28,0) -> 2949.49 | M31: =IFERROR(SUM('Data Sheet'!H49:K49),0) -> 3597.02
B32: Net Margins | C32: =IFERROR(C31/C5,0) -> 0.10902646 | D32: =IFERROR(D31/D5,0) -> 0.041239571 | E32: =IFERROR(E31/E5,0) -> 0.12157056 | F32: =IFERROR(F31/F5,0) -> 0.070048903 | G32: =IFERROR(G31/G5,0) -> 0.096027707 | H32: =IFERROR(H31/H5,0) -> 0.12389932 | I32: =IFERROR(I31/I5,0) -> 0.0047760786 | J32: =IFERROR(J31/J5,0) -> 0.091172472 | ... M32: =IFERROR(M31/M5,0) -> 0.10618685
B34: No. of Equity Shares | C34: =IFERROR('Data Sheet'!B70/10000000,0) -> 95.919779 | D34: =IFERROR('Data Sheet'!C70/10000000,0) -> 95.919779 | E34: =IFERROR('Data Sheet'!D70/10000000,0) -> 95.919779 | F34: =IFERROR('Data Sheet'!E70/10000000,0) -> 95.919779 | G34: =IFERROR('Data Sheet'!F70/10000000,0) -> 95.919779 | H34: =IFERROR('Data Sheet'!G70/10000000,0) -> 95.919779 | I34: =IFERROR('Data Sheet'!H70/10000000,0) -> 95.919779 | J34: =IFERROR('Data Sheet'!I70/10000000,0) -> 95.919779 | ... L34: =IFERROR('Data Sheet'!K70/10000000,0) -> 95.919779
B36: EPS | C36: =IFERROR(C31/C34,0) -> 16.221576 | D36: =IFERROR(D31/D34,0) -> 6.4757238 | E36: =IFERROR(E31/E34,0) -> 21.323756 | F36: =IFERROR(F31/F34,0) -> 14.050804 | G36: =IFERROR(G31/G34,0) -> 20.233992 | H36: =IFERROR(H31/H34,0) -> 28.046353 | I36: =IFERROR(I31/I34,0) -> 1.4490234 | J36: =IFERROR(J31/J34,0) -> 32.781664 | ... L36: =IFERROR(L31/L34,0) -> 30.74955
B37: EPS growth % | D37: =IFERROR((D36/C36)-1,0) -> -0.60079565 | E37: =IFERROR((E36/D36)-1,0) -> 2.2928761 | F37: =IFERROR((F36/E36)-1,0) -> -0.34107276 | G37: =IFERROR((G36/F36)-1,0) -> 0.44005936 | H37: =IFERROR((H36/G36)-1,0) -> 0.38610086 | I37: =IFERROR((I36/H36)-1,0) -> -0.9483347 | J37: =IFERROR((J36/I36)-1,0) -> 21.623282 | K37: =IFERROR((K36/J36)-1,0) -> 0.73779183 | L37: =IFERROR((L36/K36)-1,0) -> -0.46022843
