Workbook
Name UPDATE: 'Data Sheet'!$E$1

Sheet Input Sheet
B2: company Description | C2: ITC Limited is an Indian conglomerate, headquartered in Kolkata. It has a presence across six business segments, namely FMCG, agribusiness, information technology, paper products, and packaging. It generates a plurality of its revenue from tobacco products.

Sheet share price
B2: Chart
B3: Date | C3: ITCEQN | E3: DATE | F3: VOLUME
B4: 44200 | C4: 213.9 | E4: 46024 | F4: 118790358
B5: 44201 | C5: 211.75 | E5: 46023 | F5: 282626710
B6: 44202 | C6: 205.3 | E6: 46022 | F6: 9945109
B7: 44203 | C7: 203.25 | E7: 46021 | F7: 12340527
B8: 44204 | C8: 202.1 | E8: 46020 | F8: 6647710
B9: 44207 | C9: 202.65 | E9: 46017 | F9: 3152453
B10: 44208 | C10: 206.5 | E10: 46015 | F10: 5777430
B11: 44209 | C11: 211.2 | E11: 46014 | F11: 10081997
B12: 44210 | C12: 214.1 | E12: 46013 | F12: 6847871
B13: 44211 | C13: 217.9 | E13: 46010 | F13: 10654835
B14: 44214 | C14: 218.05 | E14: 46009 | F14: 7227668
B15: 44215 | C15: 218.95 | E15: 46008 | F15: 8087490
... B252: 44565 | C252: 219.8 | E252: 45660 | F252: 37072992
B253: 44566 | C253: 220.35
B254: 44567 | C254: 218.75
B255: 44568 | C255: 218.45
B256: 44571 | C256: 223.3
B257: 44572 | C257: 222
B258: 44573 | C258: 222.5
B259: 44574 | C259: 223.9
B260: 44575 | C260: 222.9
B261: 44578 | C261: 224.75
B262: 44579 | C262: 220.6
B263: 44580 | C263: 220.4
B264: 44581 | C264: 219.1
... B1244: 46024 | C1244: 350.1

Sheet teaser
B2: ='Data Sheet'!B1&" One Page Profile" -> ITC LTD One Page Profile
C4: ='Input Sheet'!C2 -> ITC Limited is an Indian conglomerate, headquartered in Kolkata. It has a presence across six business segments, namely FMCG, agribusiness, information technology, paper products, and packaging. It generates a plurality of its revenue from tobacco products.
B5: INR(Crs)
B6: Key Financial Metrics | C6: ='Data Sheet'!G16 -> 44286 | D6: ='Data Sheet'!H16 -> 44651 | E6: ='Data Sheet'!I16 -> 45016 | F6: ='Data Sheet'!J16 -> 45382 | G6: ='Data Sheet'!K16 -> 45747 | I6: Share Price 5Y
B8: Total Sales | C8: ='Data Sheet'!G17 -> 49257.45 | D8: ='Data Sheet'!H17 -> 60644.54 | E8: ='Data Sheet'!I17 -> 70919.03 | F8: ='Data Sheet'!J17 -> 67931.94 | G8: ='Data Sheet'!K17 -> 75323.34
B9: Sales growth (y-o-y) | C9: ='Data Sheet'!G95 -> 0.0013504499 | D9: ='Data Sheet'!H95 -> 0.001178019 | E9: ='Data Sheet'!I95 -> 0.0084961009 | F9: ='Data Sheet'!J95 -> 0.0045622787 | G9: ='Data Sheet'!K95 -> 0.0023548824
B10: Gross Profit Margins (%) | C10: ='Data Sheet'!G98 -> 0.51867748 | D10: ='Data Sheet'!H98 -> 0.49650026 | E10: ='Data Sheet'!I98 -> 0.53068887 | F10: ='Data Sheet'!J98 -> 0.54582484 | G10: ='Data Sheet'!K98 -> 0.51209373
B11: EBIDTA Margins (%) | C11: ='Data Sheet'!G99 -> 0.41868083 | D11: ='Data Sheet'!H99 -> 0.42385118 | E11: ='Data Sheet'!I99 -> 0.35515897 | F11: ='Data Sheet'!J99 -> 0.38037262 | G11: ='Data Sheet'!K99 -> 0.35038874
B12: EBIT Margins (%) | C12: ='Data Sheet'!G100 -> 0.31303265 | D12: ='Data Sheet'!H100 -> 0.31149944 | E12: ='Data Sheet'!I100 -> 0.33693707 | F12: ='Data Sheet'!J100 -> 0.34842932 | G12: ='Data Sheet'!K100 -> 0.32119035
B13: Net Profit Margins (%) | C13: ='Data Sheet'!G101 -> 0.26719187 | D13: ='Data Sheet'!H101 -> 0.25134431 | E13: ='Data Sheet'!I101 -> 0.27061368 | F13: ='Data Sheet'!J101 -> 0.30116584 | G13: ='Data Sheet'!K101 -> 0.46129964
B14: Earnings Per Share (in Rs) | C14: ='Profit & Loss'!G13 -> 10.692505 | D14: ='Profit & Loss'!H13 -> 12.368976 | E14: ='Profit & Loss'!I13 -> 15.442276 | F14: ='Profit & Loss'!J13 -> 16.387082 | G14: ='Profit & Loss'!K13 -> 27.765984
B15: EPS growth( y-o-y) | C15: ='Data Sheet'!G102 -> -0.14130126 | D15: ='Data Sheet'!H102 -> 0.15678939 | E15: ='Data Sheet'!I102 -> 0.2484684 | F15: ='Data Sheet'!J102 -> 0.0611831 | G15: ='Data Sheet'!K102 -> 0.69438246
B16: Dividend Per Share (in Rs) | C16: ='Data Sheet'!G103 -> 10.75 | D16: ='Data Sheet'!H103 -> 11.500004 | E16: ='Data Sheet'!I103 -> 15.5 | F16: ='Data Sheet'!J103 -> 13.749998 | G16: ='Data Sheet'!K103 -> 14.349997
B17: Dividend Growth (y-o-y) | C17: ='Data Sheet'!G104 -> 0.059113555 | D17: ='Data Sheet'!H104 -> 0.069767819 | E17: ='Data Sheet'!I104 -> 0.34782561 | F17: ='Data Sheet'!J104 -> -0.11290335 | G17: ='Data Sheet'!K104 -> 0.043636312
B19: Key Financial Ratios | C19: 44286 | D19: 44651 | E19: 45016 | F19: 45382 | G19: 45747 | I19: Volume 1 Y
B21: Price to earnings | C21: ='Profit & Loss'!G14 -> 19.155475 | D21: ='Profit & Loss'!H14 -> 18.995914 | E21: ='Profit & Loss'!I14 -> 23.2796 | F21: ='Profit & Loss'!J14 -> 24.502837 | G21: ='Profit & Loss'!K14 -> 14.757266
B22: EV / EBIDTA | C22: ='Profit & Loss'!E31 -> 18.202942 | D22: ='Profit & Loss'!F31 -> 9.8659847 | E22: ='Profit & Loss'!G31 -> 14.516487 | F22: ='Profit & Loss'!H31 -> 13.826369 | G22: ='Profit & Loss'!I31 -> 17.203375
B23: EV / Sales | C23: ='Profit & Loss'!C32 -> 7.3946458 | D23: ='Profit & Loss'!D32 -> 6.6613663 | E23: ='Profit & Loss'!E32 -> 6.9805125 | F23: ='Profit & Loss'!F32 -> 3.8641822 | G23: ='Profit & Loss'!G32 -> 5.0291002
B24: Price to Book Value | C24: ='Profit & Loss'!G33 -> 4.1776297 | D24: ='Profit & Loss'!H33 -> 4.6360678 | E24: ='Profit & Loss'!I33 -> 6.460451 | F24: ='Profit & Loss'!J33 -> 6.7282022 | G24: ='Profit & Loss'!K33 -> 7.3220746
B25: Return on Equity (%) | C25: ='Balance Sheet'!G23 -> 0.21809064 | D25: ='Balance Sheet'!H23 -> 0.24405605 | E25: ='Balance Sheet'!I23 -> 0.27751555 | F25: ='Balance Sheet'!J23 -> 0.2745887 | G25: ='Balance Sheet'!K23 -> 0.49616743
B26: Return on Capital Employed (%) | C26: ='Balance Sheet'!G24 -> 0.28527066 | D26: ='Balance Sheet'!H24 -> 0.33733253 | E26: ='Balance Sheet'!I24 -> 0.39333609 | F26: ='Balance Sheet'!J24 -> 0.37429273 | G26: ='Balance Sheet'!K24 -> 0.57864605
B28: Top 10 Shareholders | C28: N. shares (in crs) | E28: % holding | F28: Market Value(in Crs) | I28: Holding Pattern
B30: {=L38:L47} -> Tobacco Manufacturers (India) Limited | C30: =M38 -> 222.84959 | E30: =(N38)/100 -> 0.1779 | F30: =O38 -> 78019.64
B31: Life Insurance Corporation of India | C31: =M39 -> 198.58072 | E31: =(N39)/100 -> 0.1586 | F31: =O39 -> 69523.111
B32: Specified Undertaking of the Unit Trust of India | C32: =M40 -> 97.453143 | E32: =(N40)/100 -> 0.0778 | F32: =O40 -> 34118.345
B33: Myddleton Investment Company Limited | C33: =M41 -> 48.631194 | E33: =(N41)/100 -> 0.0388 | F33: =O41 -> 17025.781
B34: SBI Mutual Funds | C34: =M42 -> 40.798409 | E34: =(N42)/100 -> 0.0326 | F34: =O42 -> 14283.523
B35: QIB - Insurance Company Registered | C35: =M43 -> 33.990466 | E35: =(N43)/100 -> 0.0271 | F35: =O43 -> 11900.062 | N35: 100
B36: ICICI Prudential Mutual Funds | C36: =M44 -> 28.535049 | E36: =(N44)/100 -> 0.0228 | F36: =O44 -> 9990.1208 | N36: 10000000
B37: GQG Partners Emerging Markets Equity Fund | C37: =M45 -> 26.34344 | E37: =(N45)/100 -> 0.021 | F37: =O45 -> 9222.8383 | L37: Shareholder's name | M37: Total Shares Held (In Crs) | N37: (% holding) | O37: Market Value (in Crs.)
B38: General Insurance Corporation of India | C38: =M46 -> 21.708551 | E38: =(N46)/100 -> 0.0173 | F38: =O46 -> 7600.1636 | L38: Tobacco Manufacturers (India) Limited | M38: =(2228495863)/10000000 -> 222.84959 | N38: 17.79 | O38: =350.1*M38 -> 78019.64
B39: Goldman Sachs Trust II | C39: =M47 -> 20.70918 | E39: =(N47)/100 -> 0.0165 | F39: =O47 -> 7250.2837 | L39: Life Insurance Corporation of India | M39: =(1985807233)/10000000 -> 198.58072 | N39: 15.86 | O39: =350.1*M39 -> 69523.111
L40: Specified Undertaking of the Unit Trust of India | M40: =(974531427)/10000000 -> 97.453143 | N40: 7.78 | O40: =350.1*M40 -> 34118.345
B41: Managerial Remuneration | C41: Designation | E41: Remuneration | F41: X of Median Salary | I41: Capital Structure | L41: Myddleton Investment Company Limited | M41: =(486311940)/10000000 -> 48.631194 | N41: 3.88 | O41: =350.1*M41 -> 17025.781
B42: Mr. Sanjeev Puri | C42: Chairman and MD | E42: 25.66 | F42: 377 | L42: SBI Mutual Funds | M42: 40.798409 | N42: 3.26 | O42: =350.1*M42 -> 14283.523
B43: Mr. Supritam Dutta | C43: Exe. Dir. (ED) & CFO | E43: 8.53 | F43: 132 | I43: Share Price on xxx | K43: ='Data Sheet'!B8 -> 363.95 | L43: QIB - Insurance Company Registered | M43: =(339904658)/10000000 -> 33.990466 | N43: 2.71 | O43: =350.1*M43 -> 11900.062
B44: N Anand | C44: ED | E44: 8.87 | F44: 99 | I44: No. of shares outstanding | K44: ='Data Sheet'!B6 -> 1252.896 | L44: ICICI Prudential Mutual Funds | M44: 28.535049 | N44: 2.28 | O44: =350.1*M44 -> 9990.1208
B45: B Sumant | C45: ED | E45: 9.56 | F45: 174 | I45: Market Capitalzation | K45: =K43*K44 -> 455991.5 | L45: GQG Partners Emerging Markets Equity Fund | M45: =(263434398)/10000000 -> 26.34344 | N45: 2.1 | O45: =350.1*M45 -> 9222.8383
I46: Less : cash and cash eq. | K46: ='Data Sheet'!K69*-1 -> -4012.36 | L46: General Insurance Corporation of India | M46: =(217085508)/10000000 -> 21.708551 | N46: 1.73 | O46: =350.1*M46 -> 7600.1636
I47: Add : total debt | K47: ='Data Sheet'!K59 -> 284.54 | L47: Goldman Sachs Trust II | M47: =(207091795)/10000000 -> 20.70918 | N47: 1.65 | O47: =350.1*M47 -> 7250.2837
...

Sheet Profit & Loss
A1: ='Data Sheet'!B1 -> ITC LTD | H1: =UPDATE | M1: SCREENER.IN
A3: Narration | B3: ='Data Sheet'!B16 -> 42460 | C3: ='Data Sheet'!C16 -> 42825 | D3: ='Data Sheet'!D16 -> 43190 | E3: ='Data Sheet'!E16 -> 43555 | F3: ='Data Sheet'!F16 -> 43921 | G3: ='Data Sheet'!G16 -> 44286 | H3: ='Data Sheet'!H16 -> 44651 | I3: ='Data Sheet'!I16 -> 45016 | ... K3: ='Data Sheet'!K16 -> 45747 | L3: Trailing | M3: Best Case | N3: Worst Case
A4: Sales | B4: ='Data Sheet'!B17 -> 39192.1 | C4: ='Data Sheet'!C17 -> 42767.6 | D4: ='Data Sheet'!D17 -> 43448.94 | E4: ='Data Sheet'!E17 -> 48339.58 | F4: ='Data Sheet'!F17 -> 49387.7 | G4: ='Data Sheet'!G17 -> 49257.45 | H4: ='Data Sheet'!H17 -> 60644.54 | I4: ='Data Sheet'!I17 -> 70919.03 | ... K4: ='Data Sheet'!K17 -> 75323.34 | L4: =SUM(Quarters!H4:K4) -> 78551.59 | M4: =$K4+M23*K4 -> 83518.968 | N4: =$K4+N23*L4 -> 81209.036
A5: Expenses | B5: =SUM('Data Sheet'!B18,'Data Sheet'!B20:B24, -1*'Data Sheet'!B19) -> 24660.61 | C5: =SUM('Data Sheet'!C18,'Data Sheet'!C20:C24, -1*'Data Sheet'!C19) -> 27298.09 | D5: =SUM('Data Sheet'!D18,'Data Sheet'!D20:D24, -1*'Data Sheet'!D19) -> 26928.35 | E5: =SUM('Data Sheet'!E18,'Data Sheet'!E20:E24, -1*'Data Sheet'!E19) -> 29802.19 | F5: =SUM('Data Sheet'!F18,'Data Sheet'!F20:F24, -1*'Data Sheet'!F19) -> 30044.16 | G5: =SUM('Data Sheet'!G18,'Data Sheet'!G20:G24, -1*'Data Sheet'!G19) -> 32192.67 | H5: =SUM('Data Sheet'!H18,'Data Sheet'!H20:H24, -1*'Data Sheet'!H19) -> 40021.39 | I5: =SUM('Data Sheet'!I18,'Data Sheet'!I20:I24, -1*'Data Sheet'!I19) -> 45214.77 | ... K5: =SUM('Data Sheet'!K18,'Data Sheet'!K20:K24, -1*'Data Sheet'!K19) -> 49483.89 | L5: =SUM(Quarters!H5:K5) -> 52159.14 | M5: =M4-M6 -> 53597.014 | N5: =N4-N6 -> 53923.714
A6: Operating Profit | B6: =B4-B5 -> 14531.49 | C6: =C4-C5 -> 15469.51 | D6: =D4-D5 -> 16520.59 | E6: =E4-E5 -> 18537.39 | F6: =F4-F5 -> 19343.54 | G6: =G4-G5 -> 17064.78 | H6: =H4-H5 -> 20623.15 | I6: =I4-I5 -> 25704.26 | ... K6: =K4-K5 -> 25839.45 | L6: =SUM(Quarters!H6:K6) -> 26392.45 | M6: =M4*M24 -> 29921.955 | N6: =N4*N24 -> 27285.322
A7: Other Income | B7: ='Data Sheet'!B25 -> 1483.11 | C7: ='Data Sheet'!C25 -> 1758.63 | D7: ='Data Sheet'!D25 -> 2239.81 | E7: ='Data Sheet'!E25 -> 2080.44 | F7: ='Data Sheet'!F25 -> 2417.32 | G7: ='Data Sheet'!G25 -> 2576.95 | H7: ='Data Sheet'!H25 -> 1909.72 | I7: ='Data Sheet'!I25 -> 2097.64 | ... K7: ='Data Sheet'!K25 -> 17794.88 | L7: =SUM(Quarters!H7:K7) -> 17684.49 | M7: 0 | N7: 0
A8: Depreciation | B8: ='Data Sheet'!B26 -> 1077.4 | C8: ='Data Sheet'!C26 -> 1152.79 | D8: ='Data Sheet'!D26 -> 1236.28 | E8: ='Data Sheet'!E26 -> 1396.61 | F8: ='Data Sheet'!F26 -> 1644.91 | G8: ='Data Sheet'!G26 -> 1645.59 | H8: ='Data Sheet'!H26 -> 1732.41 | I8: ='Data Sheet'!I26 -> 1809.01 | ... K8: ='Data Sheet'!K26 -> 1646.32 | L8: =SUM(Quarters!H8:K8) -> 1684.77 | M8: =+$L8 -> 1684.77 | N8: =+$L8 -> 1684.77
A9: Interest | B9: ='Data Sheet'!B27 -> 78.13 | C9: ='Data Sheet'!C27 -> 49.03 | D9: ='Data Sheet'!D27 -> 115.01 | E9: ='Data Sheet'!E27 -> 71.4 | F9: ='Data Sheet'!F27 -> 81.38 | G9: ='Data Sheet'!G27 -> 57.97 | H9: ='Data Sheet'!H27 -> 59.99 | I9: ='Data Sheet'!I27 -> 77.77 | ... K9: ='Data Sheet'!K27 -> 45.06 | L9: =SUM(Quarters!H9:K9) -> 57.25 | M9: =+$L9 -> 57.25 | N9: =+$L9 -> 57.25
A10: Profit before tax | B10: ='Data Sheet'!B28 -> 14859.07 | C10: ='Data Sheet'!C28 -> 16026.32 | D10: ='Data Sheet'!D28 -> 17409.11 | E10: ='Data Sheet'!E28 -> 19149.82 | F10: ='Data Sheet'!F28 -> 20034.57 | G10: ='Data Sheet'!G28 -> 17938.17 | H10: ='Data Sheet'!H28 -> 20740.47 | I10: ='Data Sheet'!I28 -> 25915.12 | ... K10: ='Data Sheet'!K28 -> 41942.95 | L10: =SUM(Quarters!H10:K10) -> 42334.92 | M10: =M6+M7-SUM(M8:M9) -> 28179.935 | N10: =N6+N7-SUM(N8:N9) -> 25543.302
A11: Tax | B11: ='Data Sheet'!B29 -> 5358.21 | C11: ='Data Sheet'!C29 -> 5549.09 | D11: ='Data Sheet'!D29 -> 5916.43 | E11: ='Data Sheet'!E29 -> 6313.92 | F11: ='Data Sheet'!F29 -> 4441.79 | G11: ='Data Sheet'!G29 -> 4555.29 | H11: ='Data Sheet'!H29 -> 5237.34 | I11: ='Data Sheet'!I29 -> 6438.4 | ... K11: ='Data Sheet'!K29 -> 6890.47 | L11: =SUM(Quarters!H11:K11) -> 6983.9 | M11: =IF($L10>0,$L11/$L10,0) -> 0.16496783 | N11: =IF($L10>0,$L11/$L10,0) -> 0.16496783
A12: Net profit | B12: ='Data Sheet'!B30 -> 9344.45 | C12: ='Data Sheet'!C30 -> 10289.44 | D12: ='Data Sheet'!D30 -> 11271.2 | E12: ='Data Sheet'!E30 -> 12592.33 | F12: ='Data Sheet'!F30 -> 15306.23 | G12: ='Data Sheet'!G30 -> 13161.19 | H12: ='Data Sheet'!H30 -> 15242.66 | I12: ='Data Sheet'!I30 -> 19191.66 | ... K12: ='Data Sheet'!K30 -> 34746.63 | L12: =SUM(Quarters!H12:K12) -> 35032.48 | M12: =M10-M11*M10 -> 23531.152 | N12: =N10-N11*N10 -> 21329.479
A13: EPS | B13: =IF('Data Sheet'!B93>0,B12/'Data Sheet'!B93,0) -> 7.7413676 | C13: =IF('Data Sheet'!C93>0,C12/'Data Sheet'!C93,0) -> 8.4704875 | D13: =IF('Data Sheet'!D93>0,D12/'Data Sheet'!D93,0) -> 9.2354334 | E13: =IF('Data Sheet'!E93>0,E12/'Data Sheet'!E93,0) -> 10.272242 | F13: =IF('Data Sheet'!F93>0,F12/'Data Sheet'!F93,0) -> 12.451986 | G13: =IF('Data Sheet'!G93>0,G12/'Data Sheet'!G93,0) -> 10.692505 | H13: =IF('Data Sheet'!H93>0,H12/'Data Sheet'!H93,0) -> 12.368976 | I13: =IF('Data Sheet'!I93>0,I12/'Data Sheet'!I93,0) -> 15.442276 | ... K13: =IF('Data Sheet'!K93>0,K12/'Data Sheet'!K93,0) -> 27.765984 | L13: =IF('Data Sheet'!$B6>0,'Profit & Loss'!L12/'Data Sheet'!$B6,0) -> 27.961203 | M13: =IF('Data Sheet'!$B6>0,'Profit & Loss'!M12/'Data Sheet'!$B6,0) -> 18.781409 | N13: =IF('Data Sheet'!$B6>0,'Profit & Loss'!N12/'Data Sheet'!$B6,0) -> 17.024142
A14: Price to earning | B14: =IF(B15>0,B15/B13,"") -> 26.497902 | C14: =IF(C15>0,C15/C13,"") -> 31.019466 | D14: =IF(D15>0,D15/D13,"") -> 25.93273 | E14: =IF(E15>0,E15/E13,"") -> 27.12553 | F14: =IF(F15>0,F15/F13,"") -> 12.925649 | G14: =IF(G15>0,G15/G13,"") -> 19.155475 | H14: =IF(H15>0,H15/H13,"") -> 18.995914 | I14: =IF(I15>0,I15/I13,"") -> 23.2796 | ... K14: =IF(K15>0,K15/K13,"") -> 14.757266 | L14: =IF(L13>0,L15/L13,0) -> 13.016249 | M14: =M25 -> 18.888988 | N14: =N25 -> 13.016249
A15: Price | B15: ='Data Sheet'!B90 -> 205.13 | C15: ='Data Sheet'!C90 -> 262.75 | D15: ='Data Sheet'!D90 -> 239.5 | E15: ='Data Sheet'!E90 -> 278.64 | F15: ='Data Sheet'!F90 -> 160.95 | G15: ='Data Sheet'!G90 -> 204.82 | H15: ='Data Sheet'!H90 -> 234.96 | I15: ='Data Sheet'!I90 -> 359.49 | ... K15: ='Data Sheet'!K90 -> 409.75 | L15: ='Data Sheet'!B8 -> 363.95 | M15: =M13*M14 -> 354.76181 | N15: =N13*N14 -> 221.59047
A17: RATIOS:
A18: Dividend Payout | B18: =IF('Data Sheet'!B30>0, 'Data Sheet'!B31/'Data Sheet'!B30, 0) -> 0.73199814 | C18: =IF('Data Sheet'!C30>0, 'Data Sheet'!C31/'Data Sheet'!C30, 0) -> 0.56077104 | D18: =IF('Data Sheet'!D30>0, 'Data Sheet'!D31/'Data Sheet'!D30, 0) -> 0.5576345 | E18: =IF('Data Sheet'!E30>0, 'Data Sheet'!E31/'Data Sheet'!E30, 0) -> 0.55976138 | F18: =IF('Data Sheet'!F30>0, 'Data Sheet'!F31/'Data Sheet'!F30, 0) -> 0.81513083 | G18: =IF('Data Sheet'!G30>0, 'Data Sheet'!G31/'Data Sheet'!G30, 0) -> 1.0053772 | H18: =IF('Data Sheet'!H30>0, 'Data Sheet'!H31/'Data Sheet'!H30, 0) -> 0.92974586 | I18: =IF('Data Sheet'!I30>0, 'Data Sheet'!I31/'Data Sheet'!I30, 0) -> 1.0037381 | ... K18: =IF('Data Sheet'!K30>0, 'Data Sheet'!K31/'Data Sheet'!K30, 0) -> 0.51681933
A19: OPM | B19: =IF(B6>0,B6/B4,0) -> 0.370776 | C19: =IF(C6>0,C6/C4,0) -> 0.36171097 | D19: =IF(D6>0,D6/D4,0) -> 0.38022999 | E19: =IF(E6>0,E6/E4,0) -> 0.38348265 | F19: =IF(F6>0,F6/F4,0) -> 0.39166716 | G19: =IF(G6>0,G6/G4,0) -> 0.34644059 | H19: =IF(H6>0,H6/H4,0) -> 0.34006606 | I19: =IF(I6>0,I6/I4,0) -> 0.36244517 | ... L19: =IF(L6>0,L6/L4,0) -> 0.33598874
G22: TRENDS: | H22: 10 YEARS | I22: 7 YEARS | J22: 5 YEARS | K22: 3 YEARS | L22: RECENT | M22: BEST | N22: WORST
G23: Sales Growth | H23: =IF(B4=0,"",POWER($K4/B4,1/9)-1) -> 0.075290157 | I23: =IF(D4=0,"",POWER($K4/D4,1/7)-1) -> 0.081772082 | J23: =IF(F4=0,"",POWER($K4/F4,1/5)-1) -> 0.088083322 | K23: =IF(H4=0,"",POWER($K4/H4, 1/3)-1) -> 0.074927782 | L23: =IF(ISERROR(MAX(IF(J4=0,"",(K4-J4)/J4),IF(K4=0,"",(L4-K4)/K4))),"",MAX(IF(J4=0,"",(K4-J4)/J4),IF(K4=0,"",(L4-K4)/K4))) -> 0.10880596 | M23: =MAX(K23:L23) -> 0.10880596 | N23: =MIN(H23:L23) -> 0.074927782
G24: OPM | H24: =IF(SUM(B4:$K$4)=0,"",SUMPRODUCT(B19:$K$19,B4:$K$4)/SUM(B4:$K$4)) -> 0.36333562 | I24: =IF(SUM(E4:$K$4)=0,"",SUMPRODUCT(E19:$K$19,E4:$K$4)/SUM(E4:$K$4)) -> 0.36106877 | J24: =IF(SUM(G4:$K$4)=0,"",SUMPRODUCT(G19:$K$19,G4:$K$4)/SUM(G4:$K$4)) -> 0.35306244 | K24: =IF(SUM(I4:$K$4)=0, "", SUMPRODUCT(I19:$K$19,I4:$K$4)/SUM(I4:$K$4)) -> 0.35826538 | L24: =L19 -> 0.33598874 | M24: =MAX(K24:L24) -> 0.35826538 | N24: =MIN(H24:L24) -> 0.33598874
G25: Price to Earning | H25: =IF(ISERROR(AVERAGEIF(B14:$L14,">0")),"",AVERAGEIF(B14:$L14,">0")) -> 21.56442 | I25: =IF(ISERROR(AVERAGEIF(E14:$L14,">0")),"",AVERAGEIF(E14:$L14,">0")) -> 19.219815 | J25: =IF(ISERROR(AVERAGEIF(G14:$L14,">0")),"",AVERAGEIF(G14:$L14,">0")) -> 18.951224 | K25: =IF(ISERROR(AVERAGEIF(I14:$L14,">0")),"",AVERAGEIF(I14:$L14,">0")) -> 18.888988 | L25: =L14 -> 13.016249 | M25: =MAX(K25:L25) -> 18.888988 | N25: =MIN(H25:L25) -> 13.016249
A27: Market Capitalization | B27: ='Data Sheet'!B90*'Data Sheet'!B93 -> 247608.32 | C27: ='Data Sheet'!C90*'Data Sheet'!C93 -> 319172.93 | D27: ='Data Sheet'!D90*'Data Sheet'!D93 -> 292292.99 | E27: ='Data Sheet'!E90*'Data Sheet'!E93 -> 341573.63 | F27: ='Data Sheet'!F90*'Data Sheet'!F93 -> 197842.96 | G27: ='Data Sheet'!G90*'Data Sheet'!G93 -> 252108.84 | H27: ='Data Sheet'!H90*'Data Sheet'!H93 -> 289548.26 | I27: ='Data Sheet'!I90*'Data Sheet'!I93 -> 446774.17 | ... K27: ='Data Sheet'!K90*'Data Sheet'!K93 -> 512765.25
A28: Debt | B28: ='Balance Sheet'!B6 -> 83.78 | C28: ='Balance Sheet'!C6 -> 45.72 | D28: ='Balance Sheet'!D6 -> 35.92 | E28: ='Balance Sheet'!E6 -> 13.44 | F28: ='Balance Sheet'!F6 -> 277.45 | G28: ='Balance Sheet'!G6 -> 270.83 | H28: ='Balance Sheet'!H6 -> 249.44 | I28: ='Balance Sheet'!I6 -> 306.04 | ... K28: ='Balance Sheet'!K6 -> 284.54
A29: Cash | B29: ='Data Sheet'!B69 -> 6063.3 | C29: ='Data Sheet'!C69 -> 2967.4 | D29: ='Data Sheet'!D69 -> 2899.6 | E29: ='Data Sheet'!E69 -> 4152.03 | F29: ='Data Sheet'!F69 -> 7277.34 | G29: ='Data Sheet'!G69 -> 4659.02 | H29: ='Data Sheet'!H69 -> 4654.42 | I29: ='Data Sheet'!I69 -> 4880.19 | ... K29: ='Data Sheet'!K69 -> 4012.36
A30: Enterprise Value | B30: =B27+B28-B29 -> 241628.8 | C30: =C27+C28-C29 -> 316251.25 | D30: =D27+D28-D29 -> 289429.31 | E30: =E27+E28-E29 -> 337435.04 | F30: =F27+F28-F29 -> 190843.07 | G30: =G27+G28-G29 -> 247720.65 | H30: =H27+H28-H29 -> 285143.28 | I30: =I27+I28-I29 -> 442200.02 | ... K30: =K27+K28-K29 -> 509037.43
A31: EV/EBIDTA | B31: =B30/B6 -> 16.627944 | C31: =C30/C6 -> 20.443521 | D31: =D30/D6 -> 17.519308 | E31: =E30/E6 -> 18.202942 | F31: =F30/F6 -> 9.8659847 | G31: =G30/G6 -> 14.516487 | H31: =H30/H6 -> 13.826369 | I31: =I30/I6 -> 17.203375 | ... K31: =K30/K6 -> 19.70001
A32: EV/Sales | B32: =B30/B4 -> 6.1652425 | C32: =C30/C4 -> 7.3946458 | D32: =D30/D4 -> 6.6613663 | E32: =E30/E4 -> 6.9805125 | F32: =F30/F4 -> 3.8641822 | G32: =G30/G4 -> 5.0291002 | H32: =H30/H4 -> 4.7018788 | I32: =I30/I4 -> 6.2352802 | ... K32: =K30/K4 -> 6.7580305
A33: P/B | B33: =B27/'Balance Sheet'!B26 -> 5.8015723 | C33: =C27/'Balance Sheet'!C26 -> 6.8768107 | D33: =D27/'Balance Sheet'!D26 -> 5.5664135 | E33: =E27/'Balance Sheet'!E26 -> 5.7755936 | F33: =F27/'Balance Sheet'!F26 -> 3.0309955 | G33: =G27/'Balance Sheet'!G26 -> 4.1776297 | H33: =H27/'Balance Sheet'!H26 -> 4.6360678 | I33: =I27/'Balance Sheet'!I26 -> 6.460451 | ... K33: =K27/'Balance Sheet'!K26 -> 7.3220746

Sheet Quarters
A1: ='Profit & Loss'!A1 -> ITC LTD | E1: =UPDATE | J1: SCREENER.IN
A3: Narration | B3: ='Data Sheet'!B41 -> 45107 | C3: ='Data Sheet'!C41 -> 45199 | D3: ='Data Sheet'!D41 -> 45291 | E3: ='Data Sheet'!E41 -> 45382 | F3: ='Data Sheet'!F41 -> 45473 | G3: ='Data Sheet'!G41 -> 45565 | H3: ='Data Sheet'!H41 -> 45657 | I3: ='Data Sheet'!I41 -> 45747 | ... K3: ='Data Sheet'!K41 -> 45930
A4: Sales | B4: ='Data Sheet'!B42 -> 17164.46 | C4: ='Data Sheet'!C42 -> 17774.47 | D4: ='Data Sheet'!D42 -> 17195.24 | E4: ='Data Sheet'!E42 -> 17037.8 | F4: ='Data Sheet'!F42 -> 17777.81 | G4: ='Data Sheet'!G42 -> 19990.36 | H4: ='Data Sheet'!H42 -> 18790.17 | I4: ='Data Sheet'!I42 -> 18765 | ... K4: ='Data Sheet'!K42 -> 19501.63
A5: Expenses | B5: ='Data Sheet'!B43 -> 10494.39 | C5: ='Data Sheet'!C43 -> 11320.23 | D5: ='Data Sheet'!D43 -> 10985.01 | E5: ='Data Sheet'!E43 -> 10735.73 | F5: ='Data Sheet'!F43 -> 11232.97 | G5: ='Data Sheet'!G43 -> 13438.28 | H5: ='Data Sheet'!H43 -> 12428.27 | I5: ='Data Sheet'!I43 -> 12245.61 | ... K5: ='Data Sheet'!K43 -> 12806.94
A6: Operating Profit | B6: ='Data Sheet'!B50 -> 6670.07 | C6: ='Data Sheet'!C50 -> 6454.24 | D6: ='Data Sheet'!D50 -> 6210.23 | E6: ='Data Sheet'!E50 -> 6302.07 | F6: ='Data Sheet'!F50 -> 6544.84 | G6: ='Data Sheet'!G50 -> 6552.08 | H6: ='Data Sheet'!H50 -> 6361.9 | I6: ='Data Sheet'!I50 -> 6519.39 | ... K6: ='Data Sheet'!K50 -> 6694.69
A7: Other Income | B7: ='Data Sheet'!B44 -> 722.3 | C7: ='Data Sheet'!C44 -> 673.5 | D7: ='Data Sheet'!D44 -> 820.26 | E7: ='Data Sheet'!E44 -> 868 | F7: ='Data Sheet'!F44 -> 771.13 | G7: ='Data Sheet'!G44 -> 690.31 | H7: ='Data Sheet'!H44 -> 803.4 | I7: ='Data Sheet'!I44 -> 15391.28 | ... K7: ='Data Sheet'!K44 -> 738.84
A8: Depreciation | B8: ='Data Sheet'!B45 -> 442.46 | C8: ='Data Sheet'!C45 -> 453.04 | D8: ='Data Sheet'!D45 -> 384.04 | E8: ='Data Sheet'!E45 -> 385.09 | F8: ='Data Sheet'!F45 -> 403.13 | G8: ='Data Sheet'!G45 -> 416.18 | H8: ='Data Sheet'!H45 -> 415.98 | I8: ='Data Sheet'!I45 -> 411.03 | ... K8: ='Data Sheet'!K45 -> 434.8
A9: Interest | B9: ='Data Sheet'!B46 -> 9.9 | C9: ='Data Sheet'!C46 -> 9.87 | D9: ='Data Sheet'!D46 -> 11.94 | E9: ='Data Sheet'!E46 -> 10.72 | F9: ='Data Sheet'!F46 -> 9.6 | G9: ='Data Sheet'!G46 -> 14.73 | H9: ='Data Sheet'!H46 -> 9.82 | I9: ='Data Sheet'!I46 -> 10.91 | ... K9: ='Data Sheet'!K46 -> 20.05
A10: Profit before tax | B10: ='Data Sheet'!B47 -> 6940.01 | C10: ='Data Sheet'!C47 -> 6664.83 | D10: ='Data Sheet'!D47 -> 6634.51 | E10: ='Data Sheet'!E47 -> 6774.26 | F10: ='Data Sheet'!F47 -> 6903.24 | G10: ='Data Sheet'!G47 -> 6811.48 | H10: ='Data Sheet'!H47 -> 6739.5 | I10: ='Data Sheet'!I47 -> 21488.73 | ... K10: ='Data Sheet'!K47 -> 6978.68
A11: Tax | B11: ='Data Sheet'!B48 -> 1759.89 | C11: ='Data Sheet'!C48 -> 1700.31 | D11: ='Data Sheet'!D48 -> 1227.99 | E11: ='Data Sheet'!E48 -> 1583.55 | F11: ='Data Sheet'!F48 -> 1726.25 | G11: ='Data Sheet'!G48 -> 1757.05 | H11: ='Data Sheet'!H48 -> 1726.32 | I11: ='Data Sheet'!I48 -> 1680.85 | ... K11: ='Data Sheet'!K48 -> 1792.13
A12: Net profit | B12: ='Data Sheet'!B49 -> 5104.93 | C12: ='Data Sheet'!C49 -> 4898.07 | D12: ='Data Sheet'!D49 -> 5335.23 | E12: ='Data Sheet'!E49 -> 5120.55 | F12: ='Data Sheet'!F49 -> 5091.59 | G12: ='Data Sheet'!G49 -> 4992.87 | H12: ='Data Sheet'!H49 -> 4934.8 | I12: ='Data Sheet'!I49 -> 19727.37 | ... K12: ='Data Sheet'!K49 -> 5126.11
A14: OPM | B14: =IF(B4>0,B6/B4,"") -> 0.38859772 | C14: =IF(C4>0,C6/C4,"") -> 0.36311856 | D14: =IF(D4>0,D6/D4,"") -> 0.36115983 | E14: =IF(E4>0,E6/E4,"") -> 0.36988754 | F14: =IF(F4>0,F6/F4,"") -> 0.36814658 | G14: =IF(G4>0,G6/G4,"") -> 0.32776198 | H14: =IF(H4>0,H6/H4,"") -> 0.33857597 | I14: =IF(I4>0,I6/I4,"") -> 0.34742286 | ... K14: =IF(K4>0,K6/K4,"") -> 0.34328874

Sheet Balance Sheet
A1: ='Profit & Loss'!A1 -> ITC LTD | E1: =UPDATE | J1: SCREENER.IN
A3: Narration | B3: ='Data Sheet'!B56 -> 42460 | C3: ='Data Sheet'!C56 -> 42825 | D3: ='Data Sheet'!D56 -> 43190 | E3: ='Data Sheet'!E56 -> 43555 | F3: ='Data Sheet'!F56 -> 43921 | G3: ='Data Sheet'!G56 -> 44286 | H3: ='Data Sheet'!H56 -> 44651 | I3: ='Data Sheet'!I56 -> 45016 | ... K3: ='Data Sheet'!K56 -> 45747
A4: Equity Share Capital | B4: ='Data Sheet'!B57 -> 804.72 | C4: ='Data Sheet'!C57 -> 1214.74 | D4: ='Data Sheet'!D57 -> 1220.43 | E4: ='Data Sheet'!E57 -> 1225.86 | F4: ='Data Sheet'!F57 -> 1229.22 | G4: ='Data Sheet'!G57 -> 1230.88 | H4: ='Data Sheet'!H57 -> 1232.33 | I4: ='Data Sheet'!I57 -> 1242.8 | ... K4: ='Data Sheet'!K57 -> 1251.41
A5: Reserves | B5: ='Data Sheet'!B58 -> 41874.8 | C5: ='Data Sheet'!C58 -> 45198.19 | D5: ='Data Sheet'!D58 -> 51289.68 | E5: ='Data Sheet'!E58 -> 57915.01 | F5: ='Data Sheet'!F58 -> 64044.04 | G5: ='Data Sheet'!G58 -> 59116.46 | H5: ='Data Sheet'!H58 -> 61223.24 | I5: ='Data Sheet'!I58 -> 67912.46 | ... K5: ='Data Sheet'!K58 -> 68778.64
A6: Borrowings | B6: ='Data Sheet'!B59 -> 83.78 | C6: ='Data Sheet'!C59 -> 45.72 | D6: ='Data Sheet'!D59 -> 35.92 | E6: ='Data Sheet'!E59 -> 13.44 | F6: ='Data Sheet'!F59 -> 277.45 | G6: ='Data Sheet'!G59 -> 270.83 | H6: ='Data Sheet'!H59 -> 249.44 | I6: ='Data Sheet'!I59 -> 306.04 | ... K6: ='Data Sheet'!K59 -> 284.54
A7: Other Liabilities | B7: ='Data Sheet'!B60 -> 8888.04 | C7: ='Data Sheet'!C60 -> 9439.67 | D7: ='Data Sheet'!D60 -> 11694.85 | E7: ='Data Sheet'!E60 -> 12584.73 | F7: ='Data Sheet'!F60 -> 11760.04 | G7: ='Data Sheet'!G60 -> 13142.59 | H7: ='Data Sheet'!H60 -> 14491.01 | I7: ='Data Sheet'!I60 -> 16369.66 | ... K7: ='Data Sheet'!K60 -> 17688.11
A8: Total | B8: ='Data Sheet'!B61 -> 51651.34 | C8: ='Data Sheet'!C61 -> 55898.32 | D8: ='Data Sheet'!D61 -> 64240.88 | E8: ='Data Sheet'!E61 -> 71739.04 | F8: ='Data Sheet'!F61 -> 77310.75 | G8: ='Data Sheet'!G61 -> 73760.76 | H8: ='Data Sheet'!H61 -> 77196.02 | I8: ='Data Sheet'!I61 -> 85830.96 | ... K8: ='Data Sheet'!K61 -> 88002.7
A10: Net Block | B10: ='Data Sheet'!B62 -> 15106.63 | C10: ='Data Sheet'!C62 -> 15893.48 | D10: ='Data Sheet'!D62 -> 16523.96 | E10: ='Data Sheet'!E62 -> 19374.19 | F10: ='Data Sheet'!F62 -> 21713.34 | G10: ='Data Sheet'!G62 -> 23298.48 | H10: ='Data Sheet'!H62 -> 24231.59 | I10: ='Data Sheet'!I62 -> 25851.27 | ... K10: ='Data Sheet'!K62 -> 21954.85
A11: Capital Work in Progress | B11: ='Data Sheet'!B63 -> 2559.72 | C11: ='Data Sheet'!C63 -> 3729.89 | D11: ='Data Sheet'!D63 -> 5508.33 | E11: ='Data Sheet'!E63 -> 4136.42 | F11: ='Data Sheet'!F63 -> 3256.46 | G11: ='Data Sheet'!G63 -> 4011.29 | H11: ='Data Sheet'!H63 -> 3225.54 | I11: ='Data Sheet'!I63 -> 3003.3 | ... K11: ='Data Sheet'!K63 -> 1090.91
A12: Investments | B12: ='Data Sheet'!B64 -> 11747.59 | C12: ='Data Sheet'!C64 -> 17581.38 | D12: ='Data Sheet'!D64 -> 22052.86 | E12: ='Data Sheet'!E64 -> 25043.49 | F12: ='Data Sheet'!F64 -> 28663.35 | G12: ='Data Sheet'!G64 -> 24870.87 | H12: ='Data Sheet'!H64 -> 24841.01 | I12: ='Data Sheet'!I64 -> 29415.02 | ... K12: ='Data Sheet'!K64 -> 34719.82
A13: Other Assets | B13: ='Data Sheet'!B65 -> 22237.4 | C13: ='Data Sheet'!C65 -> 18693.57 | D13: ='Data Sheet'!D65 -> 20155.73 | E13: ='Data Sheet'!E65 -> 23184.94 | F13: ='Data Sheet'!F65 -> 23677.6 | G13: ='Data Sheet'!G65 -> 21580.12 | H13: ='Data Sheet'!H65 -> 24897.88 | I13: ='Data Sheet'!I65 -> 27561.37 | ... K13: ='Data Sheet'!K65 -> 30237.12
A14: Total | B14: ='Data Sheet'!B66 -> 51651.34 | C14: ='Data Sheet'!C66 -> 55898.32 | D14: ='Data Sheet'!D66 -> 64240.88 | E14: ='Data Sheet'!E66 -> 71739.04 | F14: ='Data Sheet'!F66 -> 77310.75 | G14: ='Data Sheet'!G66 -> 73760.76 | H14: ='Data Sheet'!H66 -> 77196.02 | I14: ='Data Sheet'!I66 -> 85830.96 | ... K14: ='Data Sheet'!K66 -> 88002.7
A16: Working Capital | B16: =B13-B7 -> 13349.36 | C16: =C13-C7 -> 9253.9 | D16: =D13-D7 -> 8460.88 | E16: =E13-E7 -> 10600.21 | F16: =F13-F7 -> 11917.56 | G16: =G13-G7 -> 8437.53 | H16: =H13-H7 -> 10406.87 | I16: =I13-I7 -> 11191.71 | ... K16: =K13-K7 -> 12549.01
A17: Debtors | B17: ='Data Sheet'!B67 -> 1917.18 | C17: ='Data Sheet'!C67 -> 2474.29 | D17: ='Data Sheet'!D67 -> 2682.29 | E17: ='Data Sheet'!E67 -> 4035.28 | F17: ='Data Sheet'!F67 -> 2562.48 | G17: ='Data Sheet'!G67 -> 2501.7 | H17: ='Data Sheet'!H67 -> 2461.9 | I17: ='Data Sheet'!I67 -> 2956.17 | ... K17: ='Data Sheet'!K67 -> 4719.67
A18: Inventory | B18: ='Data Sheet'!B68 -> 9062.1 | C18: ='Data Sheet'!C68 -> 8116.1 | D18: ='Data Sheet'!D68 -> 7495.09 | E18: ='Data Sheet'!E68 -> 7859.56 | F18: ='Data Sheet'!F68 -> 8879.33 | G18: ='Data Sheet'!G68 -> 10397.16 | H18: ='Data Sheet'!H68 -> 10864.15 | I18: ='Data Sheet'!I68 -> 11771.16 | ... K18: ='Data Sheet'!K68 -> 15637.56
A20: Debtor Days | B20: =IF('Profit & Loss'!B4>0,'Balance Sheet'!B17/('Profit & Loss'!B4/365),0) -> 17.854892 | C20: =IF('Profit & Loss'!C4>0,'Balance Sheet'!C17/('Profit & Loss'!C4/365),0) -> 21.116823 | D20: =IF('Profit & Loss'!D4>0,'Balance Sheet'!D17/('Profit & Loss'!D4/365),0) -> 22.53302 | E20: =IF('Profit & Loss'!E4>0,'Balance Sheet'!E17/('Profit & Loss'!E4/365),0) -> 30.469383 | F20: =IF('Profit & Loss'!F4>0,'Balance Sheet'!F17/('Profit & Loss'!F4/365),0) -> 18.938019 | G20: =IF('Profit & Loss'!G4>0,'Balance Sheet'!G17/('Profit & Loss'!G4/365),0) -> 18.537714 | H20: =IF('Profit & Loss'!H4>0,'Balance Sheet'!H17/('Profit & Loss'!H4/365),0) -> 14.817385 | I20: =IF('Profit & Loss'!I4>0,'Balance Sheet'!I17/('Profit & Loss'!I4/365),0) -> 15.214563 | ... K20: =IF('Profit & Loss'!K4>0,'Balance Sheet'!K17/('Profit & Loss'!K4/365),0) -> 22.870462
A21: Inventory Turnover | B21: =IF('Balance Sheet'!B18>0,'Profit & Loss'!B4/'Balance Sheet'!B18,0) -> 4.3248364 | C21: =IF('Balance Sheet'!C18>0,'Profit & Loss'!C4/'Balance Sheet'!C18,0) -> 5.2694767 | D21: =IF('Balance Sheet'!D18>0,'Profit & Loss'!D4/'Balance Sheet'!D18,0) -> 5.7969871 | E21: =IF('Balance Sheet'!E18>0,'Profit & Loss'!E4/'Balance Sheet'!E18,0) -> 6.1504181 | F21: =IF('Balance Sheet'!F18>0,'Profit & Loss'!F4/'Balance Sheet'!F18,0) -> 5.5620976 | G21: =IF('Balance Sheet'!G18>0,'Profit & Loss'!G4/'Balance Sheet'!G18,0) -> 4.737587 | H21: =IF('Balance Sheet'!H18>0,'Profit & Loss'!H4/'Balance Sheet'!H18,0) -> 5.5820787 | I21: =IF('Balance Sheet'!I18>0,'Profit & Loss'!I4/'Balance Sheet'!I18,0) -> 6.0248123 | ... K21: =IF('Balance Sheet'!K18>0,'Profit & Loss'!K4/'Balance Sheet'!K18,0) -> 4.8168218
A23: Return on Equity | B23: =IF(SUM('Balance Sheet'!B4:B5)>0,'Profit & Loss'!B12/SUM('Balance Sheet'!B4:B5),"") -> 0.21894459 | C23: =IF(SUM('Balance Sheet'!C4:C5)>0,'Profit & Loss'!C12/SUM('Balance Sheet'!C4:C5),"") -> 0.22169339 | D23: =IF(SUM('Balance Sheet'!D4:D5)>0,'Profit & Loss'!D12/SUM('Balance Sheet'!D4:D5),"") -> 0.21464819 | E23: =IF(SUM('Balance Sheet'!E4:E5)>0,'Profit & Loss'!E12/SUM('Balance Sheet'!E4:E5),"") -> 0.21292095 | F23: =IF(SUM('Balance Sheet'!F4:F5)>0,'Profit & Loss'!F12/SUM('Balance Sheet'!F4:F5),"") -> 0.23449465 | G23: =IF(SUM('Balance Sheet'!G4:G5)>0,'Profit & Loss'!G12/SUM('Balance Sheet'!G4:G5),"") -> 0.21809064 | H23: =IF(SUM('Balance Sheet'!H4:H5)>0,'Profit & Loss'!H12/SUM('Balance Sheet'!H4:H5),"") -> 0.24405605 | I23: =IF(SUM('Balance Sheet'!I4:I5)>0,'Profit & Loss'!I12/SUM('Balance Sheet'!I4:I5),"") -> 0.27751555 | ... K23: =IF(SUM('Balance Sheet'!K4:K5)>0,'Profit & Loss'!K12/SUM('Balance Sheet'!K4:K5),"") -> 0.49616743
A24: Return on Capital Emp | C24: =IF((B4+B5+B6+C4+C5+C6)>0,('Profit & Loss'!C10+'Profit & Loss'!C9)*2/(B4+B5+B6+C4+C5+C6),"") -> 0.36034518 | D24: =IF((C4+C5+C6+D4+D5+D6)>0,('Profit & Loss'!D10+'Profit & Loss'!D9)*2/(C4+C5+C6+D4+D5+D6),"") -> 0.35400589 | E24: =IF((D4+D5+D6+E4+E5+E6)>0,('Profit & Loss'!E10+'Profit & Loss'!E9)*2/(D4+D5+D6+E4+E5+E6),"") -> 0.34415688 | F24: =IF((E4+E5+E6+F4+F5+F6)>0,('Profit & Loss'!F10+'Profit & Loss'!F9)*2/(E4+E5+E6+F4+F5+F6),"") -> 0.32261652 | G24: =IF((F4+F5+F6+G4+G5+G6)>0,('Profit & Loss'!G10+'Profit & Loss'!G9)*2/(F4+F5+F6+G4+G5+G6),"") -> 0.28527066 | H24: =IF((G4+G5+G6+H4+H5+H6)>0,('Profit & Loss'!H10+'Profit & Loss'!H9)*2/(G4+G5+G6+H4+H5+H6),"") -> 0.33733253 | I24: =IF((H4+H5+H6+I4+I5+I6)>0,('Profit & Loss'!I10+'Profit & Loss'!I9)*2/(H4+H5+H6+I4+I5+I6),"") -> 0.39333609 | J24: =IF((I4+I5+I6+J4+J5+J6)>0,('Profit & Loss'!J10+'Profit & Loss'!J9)*2/(I4+I5+I6+J4+J5+J6),"") -> 0.37429273 | K24: =IF((J4+J5+J6+K4+K5+K6)>0,('Profit & Loss'!K10+'Profit & Loss'!K9)*2/(J4+J5+J6+K4+K5+K6),"") -> 0.57864605
A26: Book Value | B26: =B4+B5 -> 42679.52 | C26: =C4+C5 -> 46412.93 | D26: =D4+D5 -> 52510.11 | E26: =E4+E5 -> 59140.87 | F26: =F4+F5 -> 65273.26 | G26: =G4+G5 -> 60347.34 | H26: =H4+H5 -> 62455.57 | I26: =I4+I5 -> 69155.26 | ... K26: =K4+K5 -> 70030.05

Sheet Cash Flow
A1: ='Balance Sheet'!A1 -> ITC LTD | E1: =UPDATE | J1: SCREENER.IN
A3: Narration | B3: ='Data Sheet'!B81 -> 42460 | C3: ='Data Sheet'!C81 -> 42825 | D3: ='Data Sheet'!D81 -> 43190 | E3: ='Data Sheet'!E81 -> 43555 | F3: ='Data Sheet'!F81 -> 43921 | G3: ='Data Sheet'!G81 -> 44286 | H3: ='Data Sheet'!H81 -> 44651 | I3: ='Data Sheet'!I81 -> 45016 | ... K3: ='Data Sheet'!K81 -> 45747
A4: Cash from Operating Activity | B4: ='Data Sheet'!B82 -> 9799.04 | C4: ='Data Sheet'!C82 -> 10627.31 | D4: ='Data Sheet'!D82 -> 13169.4 | E4: ='Data Sheet'!E82 -> 12583.41 | F4: ='Data Sheet'!F82 -> 14689.66 | G4: ='Data Sheet'!G82 -> 12526.97 | H4: ='Data Sheet'!H82 -> 15775.51 | I4: ='Data Sheet'!I82 -> 18877.55 | ... K4: ='Data Sheet'!K82 -> 17627.04
A5: Cash from Investing Activity | B5: ='Data Sheet'!B83 -> -3920.73 | C5: ='Data Sheet'!C83 -> -3250.93 | D5: ='Data Sheet'!D83 -> -7113.89 | E5: ='Data Sheet'!E83 -> -5545.68 | F5: ='Data Sheet'!F83 -> -6174.02 | G5: ='Data Sheet'!G83 -> 5739.98 | H5: ='Data Sheet'!H83 -> -2238.49 | I5: ='Data Sheet'!I83 -> -5732.29 | ... K5: ='Data Sheet'!K83 -> -563.84
A6: Cash from Financing Activity | B6: ='Data Sheet'!B84 -> -5612.52 | C6: ='Data Sheet'!C84 -> -7301.03 | D6: ='Data Sheet'!D84 -> -6221.13 | E6: ='Data Sheet'!E84 -> -6868.64 | F6: ='Data Sheet'!F84 -> -8181.48 | G6: ='Data Sheet'!G84 -> -18633.83 | H6: ='Data Sheet'!H84 -> -13580.5 | I6: ='Data Sheet'!I84 -> -13006.03 | ... K6: ='Data Sheet'!K84 -> -17037.4
A7: Net Cash Flow | B7: ='Data Sheet'!B85 -> 265.79 | C7: ='Data Sheet'!C85 -> 75.35 | D7: ='Data Sheet'!D85 -> -165.62 | E7: ='Data Sheet'!E85 -> 169.09 | F7: ='Data Sheet'!F85 -> 334.16 | G7: ='Data Sheet'!G85 -> -366.88 | H7: ='Data Sheet'!H85 -> -43.48 | I7: ='Data Sheet'!I85 -> 139.23 | ... K7: ='Data Sheet'!K85 -> 25.8

Sheet Customization
A1: How to use it?
A3: You can customize this workbook as you want.
B4: You can add custom formating, add conditional formating, add your own formulas… do ANYTHING.
B5: Please don't edit the "Data Sheet" only.
A7: After customization, you can upload this back on Screener.
B8: Upload on: | C8: https://www.screener.in/excel/
A10: Download your customized workbooks now onwards.
B11: Now whenever you will "Export to excel" from Screener, it will export your customized file.
A14: TESTING:
B15: This is a testing feature currently.
B16: You can report any formula errors on the worksheet at: support@screener.in

Sheet Data Sheet
A1: COMPANY NAME | B1: ITC LTD | E1: =IF(B2<>B3, "A NEW VERSION OF THE WORKSHEET IS AVAILABLE", "")
A2: LATEST VERSION | B2: 2.1 | E2: PLEASE DO NOT MAKE ANY CHANGES TO THIS SHEET
A3: CURRENT VERSION | B3: 2.1
A5: META
A6: Number of shares | B6: =IF(B9>0, B9/B8, 0) -> 1252.896
A7: Face Value | B7: 1
A8: Current Price | B8: 363.95
A9: Market Capitalization | B9: 455991.5
A15: PROFIT & LOSS
A16: Report Date | B16: 42460 | C16: 42825 | D16: 43190 | E16: 43555 | F16: 43921 | G16: 44286 | H16: 44651 | I16: 45016 | J16: 45382 | K16: 45747
A17: Sales | B17: 39192.1 | C17: 42767.6 | D17: 43448.94 | E17: 48339.58 | F17: 49387.7 | G17: 49257.45 | H17: 60644.54 | I17: 70919.03 | J17: 67931.94 | K17: 75323.34
A18: Raw Material Cost | B18: 13763.88 | C18: 15456.59 | D18: 14827.72 | E18: 17623.52 | F18: 18048.6 | G18: 20776.71 | H18: 27071.07 | I18: 29364.36 | J18: 27348.57 | K18: 32704.37
A19: Change in Inventory | B19: 195.38 | C19: -592.57 | D19: -1027.76 | E19: 203.19 | F19: 703.13 | G19: 645.27 | H19: 686 | I19: 358.59 | J19: 367.77 | K19: 725.65
A20: Power and Fuel | B20: 571.88 | C20: 584.33 | D20: 653.5 | E20: 746.73 | F20: 780.85 | G20: 699.56 | H20: 889.77 | I20: 1232.34 | J20: 952.9 | K20: 975.35
A21: Other Mfr. Exp | B21: 1581.59 | C21: 1683.9 | D21: 1697.62 | E21: 1871.01 | F21: 1908.29 | G21: 1587.18 | H21: 1887.67 | I21: 2327.8 | J21: 2183.76 | K21: 2345.36
A22: Employee Cost | B22: 3440.97 | C22: 3631.73 | D22: 3760.9 | E22: 4177.88 | F22: 4295.79 | G22: 4463.33 | H22: 4890.55 | I22: 5736.22 | J22: 5548.53 | K22: 6169.78
A23: Selling and admin | B23: 4261.78 | C23: 4179.74 | D23: 3954.87 | E23: 4546.39 | F23: 4488.63 | G23: 4236.77 | H23: 4858.38 | I23: 5604.08 | J23: 5312.45 | K23: 5793.29
A24: Other Expenses | B24: 1235.89 | C24: 1169.23 | D24: 1005.98 | E24: 1039.85 | F24: 1225.13 | G24: 1074.39 | H24: 1109.95 | I24: 1308.56 | J24: 1765.97 | K24: 2221.39
A25: Other Income | B25: 1483.11 | C25: 1758.63 | D25: 2239.81 | E25: 2080.44 | F25: 2417.32 | G25: 2576.95 | H25: 1909.72 | I25: 2097.64 | J25: 3330.45 | K25: 17794.88
A26: Depreciation | B26: 1077.4 | C26: 1152.79 | D26: 1236.28 | E26: 1396.61 | F26: 1644.91 | G26: 1645.59 | H26: 1732.41 | I26: 1809.01 | J26: 1518.05 | K26: 1646.32
A27: Interest | B27: 78.13 | C27: 49.03 | D27: 115.01 | E27: 71.4 | F27: 81.38 | G27: 57.97 | H27: 59.99 | I27: 77.77 | J27: 39.11 | K27: 45.06
... A31: Dividend Amount | B31: 6840.12 | C31: 5770.02 | D31: 6285.21 | E31: 7048.7 | F31: 12476.58 | G31: 13231.96 | H31: 14171.8 | I31: 19263.4 | J31: 17166.46 | K31: 17957.73
A40: Quarters
A41: Report Date | B41: 45107 | C41: 45199 | D41: 45291 | E41: 45382 | F41: 45473 | G41: 45565 | H41: 45657 | I41: 45747 | J41: 45838 | K41: 45930
A42: Sales | B42: 17164.46 | C42: 17774.47 | D42: 17195.24 | E42: 17037.8 | F42: 17777.81 | G42: 19990.36 | H42: 18790.17 | I42: 18765 | J42: 21494.79 | K42: 19501.63
A43: Expenses | B43: 10494.39 | C43: 11320.23 | D43: 10985.01 | E43: 10735.73 | F43: 11232.97 | G43: 13438.28 | H43: 12428.27 | I43: 12245.61 | J43: 14678.32 | K43: 12806.94
A44: Other Income | B44: 722.3 | C44: 673.5 | D44: 820.26 | E44: 868 | F44: 771.13 | G44: 690.31 | H44: 803.4 | I44: 15391.28 | J44: 750.97 | K44: 738.84
A45: Depreciation | B45: 442.46 | C45: 453.04 | D45: 384.04 | E45: 385.09 | F45: 403.13 | G45: 416.18 | H45: 415.98 | I45: 411.03 | J45: 422.96 | K45: 434.8
A46: Interest | B46: 9.9 | C46: 9.87 | D46: 11.94 | E46: 10.72 | F46: 9.6 | G46: 14.73 | H46: 9.82 | I46: 10.91 | J46: 16.47 | K46: 20.05
A47: Profit before tax | B47: 6940.01 | C47: 6664.83 | D47: 6634.51 | E47: 6774.26 | F47: 6903.24 | G47: 6811.48 | H47: 6739.5 | I47: 21488.73 | J47: 7128.01 | K47: 6978.68
A48: Tax | B48: 1759.89 | C48: 1700.31 | D48: 1227.99 | E48: 1583.55 | F48: 1726.25 | G48: 1757.05 | H48: 1726.32 | I48: 1680.85 | J48: 1784.6 | K48: 1792.13
A49: Net profit | B49: 5104.93 | C49: 4898.07 | D49: 5335.23 | E49: 5120.55 | F49: 5091.59 | G49: 4992.87 | H49: 4934.8 | I49: 19727.37 | J49: 5244.2 | K49: 5126.11
A50: Operating Profit | B50: 6670.07 | C50: 6454.24 | D50: 6210.23 | E50: 6302.07 | F50: 6544.84 | G50: 6552.08 | H50: 6361.9 | I50: 6519.39 | J50: 6816.47 | K50: 6694.69
A55: BALANCE SHEET
A56: Report Date | B56: 42460 | C56: 42825 | D56: 43190 | E56: 43555 | F56: 43921 | G56: 44286 | H56: 44651 | I56: 45016 | J56: 45382 | K56: 45747
A57: Equity Share Capital | B57: 804.72 | C57: 1214.74 | D57: 1220.43 | E57: 1225.86 | F57: 1229.22 | G57: 1230.88 | H57: 1232.33 | I57: 1242.8 | J57: 1248.47 | K57: 1251.41
A58: Reserves | B58: 41874.8 | C58: 45198.19 | D58: 51289.68 | E58: 57915.01 | F58: 64044.04 | G58: 59116.46 | H58: 61223.24 | I58: 67912.46 | J58: 73258.53 | K58: 68778.64
A59: Borrowings | B59: 83.78 | C59: 45.72 | D59: 35.92 | E59: 13.44 | F59: 277.45 | G59: 270.83 | H59: 249.44 | I59: 306.04 | J59: 303.43 | K59: 284.54
A60: Other Liabilities | B60: 8888.04 | C60: 9439.67 | D60: 11694.85 | E60: 12584.73 | F60: 11760.04 | G60: 13142.59 | H60: 14491.01 | I60: 16369.66 | J60: 16943.54 | K60: 17688.11
A61: Total | B61: 51651.34 | C61: 55898.32 | D61: 64240.88 | E61: 71739.04 | F61: 77310.75 | G61: 73760.76 | H61: 77196.02 | I61: 85830.96 | J61: 91753.97 | K61: 88002.7
...
