Workbook
Name UPDATE: 'Data Sheet'!$E$1

Sheet Financials

Sheet Altman's Z Score
B3: AVENUE SUPERMARTS LTD
B4: (Avenue Supermart | BSE Code : 540376)
B5: INR 4054
B6: 52 Week ( High - 4949.50 & Low - 4069.20)
B9: Avenue Supermarts Limited, d/b/a DMart, is an Indian retail corporation that operates a chain of supermarkets and hypermarkets. The company was founded by Radhakishan Damani and is based in Mumbai. As of March 2025, DMart has 415 stores across 12 states and union territories in India.
B14: Financial Summary
B60: Working Capital / Total Assets
D61: 43525 | E61: 43891 | F61: 44256 | G61: 44621 | H61: 44986 | I61: 45352 | J61: 45717
B62: Working Capital | D62: ='Data Sheet'!E65-'Data Sheet'!E60 -> 7465.87 | E62: ='Data Sheet'!F65-'Data Sheet'!F60 -> 8828.26 | F62: ='Data Sheet'!G65-'Data Sheet'!G60 -> 13085.47 | G62: ='Data Sheet'!H65-'Data Sheet'!H60 -> 12524.2 | H62: ='Data Sheet'!I65-'Data Sheet'!I60 -> 6701.81 | I62: ='Data Sheet'!J65-'Data Sheet'!J60 -> 12228 | J62: ='Data Sheet'!K65-'Data Sheet'!K60 -> -29475
B63: Total Assets | D63: ='Data Sheet'!E66 -> 305703.49 | E63: ='Data Sheet'!F66 -> 320179.39 | F63: ='Data Sheet'!G66 -> 341569.91 | G63: ='Data Sheet'!H66 -> 329061.49 | H63: ='Data Sheet'!I66 -> 334674.43 | I63: ='Data Sheet'!J66 -> 369521 | J63: ='Data Sheet'!K66 -> 376973
B64: Working Capital / Total Assets (A) | D64: =D62/D63 -> 0.024421933 | E64: =E62/E63 -> 0.027572855 | F64: =F62/F63 -> 0.038309786 | G64: =G62/G63 -> 0.038060364 | H64: =H62/H63 -> 0.020024864 | I64: =I62/I63 -> 0.033091489 | J64: =J62/J63 -> -0.078188624
B66: Retained Earnings / Total Assets
D67: 43525 | E67: 43891 | F67: 44256 | G67: 44621 | H67: 44986 | I67: 45352 | J67: 45717
B68: Retained Earnings | D68: ='Historical FS'!F34*'Historical FS'!F36*'Historical FS'!F42 -> 1859.11 | E68: ='Historical FS'!G34*'Historical FS'!G36*'Historical FS'!G42 -> 0 | F68: ='Historical FS'!H34*'Historical FS'!H36*'Historical FS'!H42 -> 7470.01 | G68: ='Historical FS'!I34*'Historical FS'!I36*'Historical FS'!I42 -> 0 | H68: ='Historical FS'!J34*'Historical FS'!J36*'Historical FS'!J42 -> 0 | I68: ='Historical FS'!K34*'Historical FS'!K36*'Historical FS'!K42 -> 21582 | J68: ='Historical FS'!L34*'Historical FS'!L36*'Historical FS'!L42 -> 19839
B69: Total Assets | D69: =D63 -> 305703.49 | E69: =E63 -> 320179.39 | F69: =F63 -> 341569.91 | G69: =G63 -> 329061.49 | H69: =H63 -> 334674.43 | I69: =I63 -> 369521 | J69: =J63 -> 376973
B70: =_xlfn.CONCAT(B66," ","(B)") -> Retained Earnings / Total Assets (B) | D70: =D68/D69 -> 0.0060814157 | E70: =E68/E69 -> 0 | F70: =F68/F69 -> 0.021869637 | G70: =G68/G69 -> 0 | H70: =H68/H69 -> 0 | I70: =I68/I69 -> 0.058405341 | J70: =J68/J69 -> 0.052627111
B72: EBIT / Total Assets
B73: EBIT | D73: ='Historical FS'!E16-'Historical FS'!E22 -> 5810.93 | E73: ='Historical FS'!F16-'Historical FS'!F22 -> 5180.26 | F73: ='Historical FS'!G16-'Historical FS'!G22 -> 1024.02 | G73: ='Historical FS'!H16-'Historical FS'!H22 -> 18109.04 | H73: ='Historical FS'!I16-'Historical FS'!I22 -> 3065.38 | I73: ='Historical FS'!J16-'Historical FS'!J22 -> -2607.8 | J73: ='Historical FS'!K16-'Historical FS'!K22 -> 27453
B74: Average Total Asset | D74: =D63 -> 305703.49 | E74: =E63 -> 320179.39 | F74: =F63 -> 341569.91 | G74: =G63 -> 329061.49 | H74: =H63 -> 334674.43 | I74: =I63 -> 369521 | J74: =J63 -> 376973
B75: =_xlfn.CONCAT(B72," ","(C)") -> EBIT / Total Assets (C) | D75: =D73/D74 -> 0.019008386 | E75: =E73/E74 -> 0.016179243 | F75: =F73/F74 -> 0.0029979807 | G75: =G73/G74 -> 0.055032389 | H75: =H73/H74 -> 0.0091592895 | I75: =I73/I74 -> -0.0070572444 | J75: =J73/J74 -> 0.072824844
B77: Market Cap / Long term liabilities
B78: Market Cap | D78: =('Data Sheet'!E90*'Data Sheet'!E70)/10000000 -> 59177.055 | E78: =('Data Sheet'!F90*'Data Sheet'!F70)/10000000 -> 25561.845 | F78: =('Data Sheet'!G90*'Data Sheet'!G70)/10000000 -> 115561.05 | G78: =('Data Sheet'!H90*'Data Sheet'!H70)/10000000 -> 166100.87 | H78: =('Data Sheet'!I90*'Data Sheet'!I70)/10000000 -> 161170.49 | I78: =('Data Sheet'!J90*'Data Sheet'!J70)/10000000 -> 380489.8 | J78: =('Data Sheet'!K90*'Data Sheet'!K70)/10000000 -> 248288.57
B79: Long Term Liabilities | D79: ='Data Sheet'!E59 -> 106175.34 | E79: ='Data Sheet'!F59 -> 124787.64 | F79: ='Data Sheet'!G59 -> 142130.57 | G79: ='Data Sheet'!H59 -> 146449.03 | H79: ='Data Sheet'!I59 -> 134113.44 | I79: ='Data Sheet'!J59 -> 107264 | J79: ='Data Sheet'!K59 -> 71540
B80: =_xlfn.CONCAT(B77," ","(D)") -> Market Cap / Long term liabilities (D) | D80: =D78/D79 -> 0.55735216 | E80: =E78/E79 -> 0.20484276 | F80: =F78/F79 -> 0.8130626 | G80: =G78/G79 -> 1.1341889 | H80: =H78/H79 -> 1.2017475 | I80: =I78/I79 -> 3.5472274 | J80: =J78/J79 -> 3.4706257
B82: Sales / Total Assets
D83: 43525 | E83: 43891 | F83: 44256 | G83: 44621 | H83: 44986 | I83: 45352 | J83: 45717
B84: Sales | D84: ='Data Sheet'!E17 -> 301938.4 | E84: ='Data Sheet'!F17 -> 261067.97 | F84: ='Data Sheet'!G17 -> 249794.75 | G84: ='Data Sheet'!H17 -> 278453.62 | H84: ='Data Sheet'!I17 -> 345966.97 | I84: ='Data Sheet'!J17 -> 434016 | J84: ='Data Sheet'!K17 -> 439695
B85: Total Asset | D85: ='Data Sheet'!E66 -> 305703.49 | E85: ='Data Sheet'!F66 -> 320179.39 | F85: ='Data Sheet'!G66 -> 341569.91 | G85: ='Data Sheet'!H66 -> 329061.49 | H85: ='Data Sheet'!I66 -> 334674.43 | I85: ='Data Sheet'!J66 -> 369521 | J85: ='Data Sheet'!K66 -> 376973
B86: =_xlfn.CONCAT(B82," ","(E)") -> Sales / Total Assets (E) | D86: =D84/D85 -> 0.98768385 | E86: =E84/E85 -> 0.81538031 | F86: =F84/F85 -> 0.73131369 | G86: =G84/G85 -> 0.84620543 | H86: =H84/H85 -> 1.0337419 | I86: =I84/I85 -> 1.1745368 | J86: =J84/J85 -> 1.1663833
B88: Altman's Z Score
D89: 43525 | E89: 43891 | F89: 44256 | G89: 44621 | H89: 44986 | I89: 45352 | J89: 45717
B90: Final Score | D90: =(1.2*D64)+(1.4*D70)+(3.3*D75)+(0.6*D80)+(1*D86) -> 1.4226431 | E90: =(1.2*E64)+(1.4*E70)+(3.3*E75)+(0.6*E80)+(1*E86) -> 1.0247649 | F90: =(1.2*F64)+(1.4*F70)+(3.3*F75)+(0.6*F80)+(1*F86) -> 1.3056338 | G90: =(1.2*G64)+(1.4*G70)+(3.3*G75)+(0.6*G80)+(1*G86) -> 1.7539981 | H90: =(1.2*H64)+(1.4*H70)+(3.3*H75)+(0.6*H80)+(1*H86) -> 1.8090459 | I90: =(1.2*I64)+(1.4*I70)+(3.3*I75)+(0.6*I80)+(1*I86) -> 3.4010615 | J90: =(1.2*J64)+(1.4*J70)+(3.3*J75)+(0.6*J80)+(1*J86) -> 3.4689323
B91: Financial Stability | D91: =IF(D90<1.81,"Distressed",IF(D90>3,"Strong","Grey Zone")) -> Distressed | E91: =IF(E90<1.81,"Distressed",IF(E90>3,"Strong","Grey Zone")) -> Distressed | F91: =IF(F90<1.81,"Distressed",IF(F90>3,"Strong","Grey Zone")) -> Distressed | G91: =IF(G90<1.81,"Distressed",IF(G90>3,"Strong","Grey Zone")) -> Distressed | H91: =IF(H90<1.81,"Distressed",IF(H90>3,"Strong","Grey Zone")) -> Distressed | I91: =IF(I90<1.81,"Distressed",IF(I90>3,"Strong","Grey Zone")) -> Strong | J91: =IF(J90<1.81,"Distressed",IF(J90>3,"Strong","Grey Zone")) -> Strong

Sheet Dupont Analysis
B3: AVENUE SUPERMARTS LTD
B4: (Avenue Supermart | BSE Code : 540376)
B5: INR 4054
B6: 52 Week ( High - 4949.50 & Low - 4069.20)
B8: About the company
B9: Avenue Supermarts Limited, d/b/a DMart, is an Indian retail corporation that operates a chain of supermarkets and hypermarkets. The company was founded by Radhakishan Damani and is based in Mumbai. As of March 2025, DMart has 415 stores across 12 states and union territories in India.
B14: Financial Summary
B60: Return on Equity (ROE)
D61: 43525 | E61: 43891 | F61: 44256 | G61: 44621 | H61: 44986 | I61: 45352 | J61: 45717
B62: Net Profit | D62: ='Historical FS'!F31 -> 1859.11 | E62: ='Historical FS'!G31 -> -6614.56 | F62: ='Historical FS'!H31 -> 7470.01 | G62: ='Historical FS'!I31 -> -10477.77 | H62: ='Historical FS'!J31 -> -13537.34 | I62: ='Historical FS'!K31 -> 23883 | J62: ='Historical FS'!L31 -> 22047
B63: Average Shareholder Equity | D63: =(('Historical FS'!F45+'Historical FS'!F46)+('Historical FS'!E45+'Historical FS'!E46))/2 -> 77803.735 | E63: =(('Historical FS'!G45+'Historical FS'!G46)+('Historical FS'!F45+'Historical FS'!F46))/2 -> 61629.045 | F63: =(('Historical FS'!H45+'Historical FS'!H46)+('Historical FS'!G45+'Historical FS'!G46))/2 -> 59162.625 | G63: =(('Historical FS'!I45+'Historical FS'!I46)+('Historical FS'!H45+'Historical FS'!H46))/2 -> 49903.98 | H63: =(('Historical FS'!J45+'Historical FS'!J46)+('Historical FS'!I45+'Historical FS'!I46))/2 -> 44941.515 | I63: =(('Historical FS'!K45+'Historical FS'!K46)+('Historical FS'!J45+'Historical FS'!J46))/2 -> 65119.895 | J63: =(('Historical FS'!L45+'Historical FS'!L46)+('Historical FS'!K45+'Historical FS'!K46))/2 -> 100531
B64: Return on Equity | D64: =D62/D63 -> 0.023894868 | E64: =E62/E63 -> -0.10732861 | F64: =F62/F63 -> 0.12626232 | G64: =G62/G63 -> -0.2099586 | H64: =H62/H63 -> -0.30122127 | I64: =I62/I63 -> 0.36675428 | J64: =J62/J63 -> 0.21930549
B66: ROE - Dupont Equation
D67: 43525 | E67: 43891 | F67: 44256 | G67: 44621 | H67: 44986 | I67: 45352 | J67: 45717
B68: =B62 -> Net Profit | D68: =D62 -> 1859.11 | E68: =E62 -> -6614.56 | F68: =F62 -> 7470.01 | G68: =G62 -> -10477.77 | H68: =H62 -> -13537.34 | I68: =I62 -> 23883 | J68: =J62 -> 22047
B69: Revenue | D69: ='Historical FS'!F5 -> 301938.4 | E69: ='Historical FS'!G5 -> 261067.97 | F69: ='Historical FS'!H5 -> 249794.75 | G69: ='Historical FS'!I5 -> 278453.62 | H69: ='Historical FS'!J5 -> 345966.97 | I69: ='Historical FS'!K5 -> 434016 | J69: ='Historical FS'!L5 -> 439695
B70: Net Profit Margin (A) | D70: =D68/D69 -> 0.0061572493 | E70: =E68/E69 -> -0.025336544 | F70: =F68/F69 -> 0.029904592 | G70: =G68/G69 -> -0.037628421 | H70: =H68/H69 -> -0.039128995 | I70: =I68/I69 -> 0.055027925 | J70: =J68/J69 -> 0.050141575
B72: Revenue | D72: ='Historical FS'!F5 -> 301938.4 | E72: ='Historical FS'!G5 -> 261067.97 | F72: ='Historical FS'!H5 -> 249794.75 | G72: ='Historical FS'!I5 -> 278453.62 | H72: ='Historical FS'!J5 -> 345966.97 | I72: ='Historical FS'!K5 -> 434016 | J72: ='Historical FS'!L5 -> 439695
B73: Average Total Asset | D73: =('Historical FS'!F62+'Historical FS'!E62)/2 -> 316447.65 | E73: =('Historical FS'!G62+'Historical FS'!F62)/2 -> 312941.44 | F73: =('Historical FS'!H62+'Historical FS'!G62)/2 -> 330874.65 | G73: =('Historical FS'!I62+'Historical FS'!H62)/2 -> 335315.7 | H73: =('Historical FS'!J62+'Historical FS'!I62)/2 -> 331867.96 | I73: =('Historical FS'!K62+'Historical FS'!J62)/2 -> 352097.72 | J73: =('Historical FS'!L62+'Historical FS'!K62)/2 -> 373247
B74: Asset Turnover Ratio (B) | D74: =D72/D73 -> 0.9541496 | E74: =E72/E73 -> 0.83423905 | F74: =F72/F73 -> 0.75495282 | G74: =G72/G73 -> 0.83042226 | H74: =H72/H73 -> 1.0424838 | I74: =I72/I73 -> 1.2326578 | J74: =J72/J73 -> 1.1780269
B76: Average Total Asset | D76: =('Historical FS'!F62+'Historical FS'!E62)/2 -> 316447.65 | E76: =('Historical FS'!G62+'Historical FS'!F62)/2 -> 312941.44 | F76: =('Historical FS'!H62+'Historical FS'!G62)/2 -> 330874.65 | G76: =('Historical FS'!I62+'Historical FS'!H62)/2 -> 335315.7 | H76: =('Historical FS'!J62+'Historical FS'!I62)/2 -> 331867.96 | I76: =('Historical FS'!K62+'Historical FS'!J62)/2 -> 352097.72 | J76: =('Historical FS'!L62+'Historical FS'!K62)/2 -> 373247
B77: Average Shareholder Equity | D77: =(('Historical FS'!F45+'Historical FS'!F46)+('Historical FS'!E46+'Historical FS'!E45))/2 -> 77803.735 | E77: =(('Historical FS'!G45+'Historical FS'!G46)+('Historical FS'!F46+'Historical FS'!F45))/2 -> 61629.045 | F77: =(('Historical FS'!H45+'Historical FS'!H46)+('Historical FS'!G46+'Historical FS'!G45))/2 -> 59162.625 | G77: =(('Historical FS'!I45+'Historical FS'!I46)+('Historical FS'!H46+'Historical FS'!H45))/2 -> 49903.98 | H77: =(('Historical FS'!J45+'Historical FS'!J46)+('Historical FS'!I46+'Historical FS'!I45))/2 -> 44941.515 | I77: =(('Historical FS'!K45+'Historical FS'!K46)+('Historical FS'!J46+'Historical FS'!J45))/2 -> 65119.895 | J77: =(('Historical FS'!L45+'Historical FS'!L46)+('Historical FS'!K46+'Historical FS'!K45))/2 -> 100531
B78: Equity Multiplier | D78: =D76/D77 -> 4.0672553 | E78: =E76/E77 -> 5.0778239 | F78: =F76/F77 -> 5.5926296 | G78: =G76/G77 -> 6.7192176 | H78: =H76/H77 -> 7.3844409 | I78: =I76/I77 -> 5.4069147 | J78: =J76/J77 -> 3.7127553
B80: Return on Equity (A*B*C) | D80: =D70*D74*D78 -> 0.023894868 | E80: =E70*E74*E78 -> -0.10732861 | F80: =F70*F74*F78 -> 0.12626232 | G80: =G70*G74*G78 -> -0.2099586 | H80: =H70*H74*H78 -> -0.30122127 | I80: =I70*I74*I78 -> 0.36675428 | J80: =J70*J74*J78 -> 0.21930549
B82: Return on Asset (ROA)
D83: 43525 | E83: 43891 | F83: 44256 | G83: 44621 | H83: 44986 | I83: 45352 | J83: 45717
B84: Net Profit | D84: =D62 -> 1859.11 | E84: =E62 -> -6614.56 | F84: =F62 -> 7470.01 | G84: =G62 -> -10477.77 | H84: =H62 -> -13537.34 | I84: =I62 -> 23883 | J84: =J62 -> 22047
B85: Average Total Asset | D85: =D73 -> 316447.65 | E85: =E73 -> 312941.44 | F85: =F73 -> 330874.65 | G85: =G73 -> 335315.7 | H85: =H73 -> 331867.96 | I85: =I73 -> 352097.72 | J85: =J73 -> 373247
B86: Return on Asset | D86: =D84/D85 -> 0.005874937 | E86: =E84/E85 -> -0.021136734 | F86: =F84/F85 -> 0.022576556 | G86: =G84/G85 -> -0.031247478 | H86: =H84/H85 -> -0.040791344 | I86: =I84/I85 -> 0.067830602 | J86: =J84/J85 -> 0.059068124
B88: ROA - Dupont Equation
D89: 43525 | E89: 43891 | F89: 44256 | G89: 44621 | H89: 44986 | I89: 45352 | J89: 45717
B90: =B84 -> Net Profit | D90: =D84 -> 1859.11 | E90: =E84 -> -6614.56 | F90: =F84 -> 7470.01 | G90: =G84 -> -10477.77 | H90: =H84 -> -13537.34 | I90: =I84 -> 23883 | J90: =J84 -> 22047
B91: Revenue | D91: =D69 -> 301938.4 | E91: =E69 -> 261067.97 | F91: =F69 -> 249794.75 | G91: =G69 -> 278453.62 | H91: =H69 -> 345966.97 | I91: =I69 -> 434016 | J91: =J69 -> 439695
B92: Net Profit Margin (A) | D92: =D90/D91 -> 0.0061572493 | E92: =E90/E91 -> -0.025336544 | F92: =F90/F91 -> 0.029904592 | G92: =G90/G91 -> -0.037628421 | H92: =H90/H91 -> -0.039128995 | I92: =I90/I91 -> 0.055027925 | J92: =J90/J91 -> 0.050141575
B94: Revenue | D94: =D72 -> 301938.4 | E94: =E72 -> 261067.97 | F94: =F72 -> 249794.75 | G94: =G72 -> 278453.62 | H94: =H72 -> 345966.97 | I94: =I72 -> 434016 | J94: =J72 -> 439695
B95: Average Total Asset | D95: =D73 -> 316447.65 | E95: =E73 -> 312941.44 | F95: =F73 -> 330874.65 | G95: =G73 -> 335315.7 | H95: =H73 -> 331867.96 | I95: =I73 -> 352097.72 | J95: =J73 -> 373247
B96: Asset Turnover Ratio (B) | D96: =D94/D95 -> 0.9541496 | E96: =E94/E95 -> 0.83423905 | F96: =F94/F95 -> 0.75495282 | G96: =G94/G95 -> 0.83042226 | H96: =H94/H95 -> 1.0424838 | I96: =I94/I95 -> 1.2326578 | J96: =J94/J95 -> 1.1780269
B98: Return on Asset (A*B) | D98: =D92*D96 -> 0.005874937 | E98: =E92*E96 -> -0.021136734 | F98: =F92*F96 -> 0.022576556 | G98: =G92*G96 -> -0.031247478 | H98: =H92*H96 -> -0.040791344 | I98: =I92*I96 -> 0.067830602 | J98: =J92*J96 -> 0.059068124

Sheet Historical FS
B2: ="Historical Financial Statements - "&'Data Sheet'!B1 -> Historical Financial Statements - TATA MOTORS LTD
B3: Years | C3: ='Data Sheet'!B16 -> 42460 | D3: ='Data Sheet'!C16 -> 42825 | E3: ='Data Sheet'!D16 -> 43190 | F3: ='Data Sheet'!E16 -> 43555 | G3: ='Data Sheet'!F16 -> 43921 | H3: ='Data Sheet'!G16 -> 44286 | I3: ='Data Sheet'!H16 -> 44651 | J3: ='Data Sheet'!I16 -> 45016 | ... L3: ='Data Sheet'!K16 -> 45747 | M3: LTM
A4: # | B4: Income Statement
B5: Sales | C5: =IFERROR('Data Sheet'!B17,0) -> 273045.6 | D5: =IFERROR('Data Sheet'!C17,0) -> 269692.51 | E5: =IFERROR('Data Sheet'!D17,0) -> 291550.48 | F5: =IFERROR('Data Sheet'!E17,0) -> 301938.4 | G5: =IFERROR('Data Sheet'!F17,0) -> 261067.97 | H5: =IFERROR('Data Sheet'!G17,0) -> 249794.75 | I5: =IFERROR('Data Sheet'!H17,0) -> 278453.62 | J5: =IFERROR('Data Sheet'!I17,0) -> 345966.97 | ... L5: =IFERROR('Data Sheet'!K17,0) -> 439695 | M5: =IFERROR(SUM('Data Sheet'!H42:K42),0) -> 441609
B6: Sales Growth | C6: ="-" -> - | D6: =IFERROR((D5-C5)/C5,0) -> -0.01228033 | E6: =IFERROR((E5-D5)/D5,0) -> 0.081047746 | F6: =IFERROR((F5-E5)/E5,0) -> 0.035629919 | G6: =IFERROR((G5-F5)/F5,0) -> -0.13536016 | H6: =IFERROR((H5-G5)/G5,0) -> -0.043181168 | I6: =IFERROR((I5-H5)/H5,0) -> 0.11472967 | J6: =IFERROR((J5-I5)/I5,0) -> 0.24245815 | K6: =IFERROR((K5-J5)/J5,0) -> 0.25450126 | ... M6: =IFERROR((M5-L5)/L5,0) -> 0.0043530174
B8: COGS | C8: =IFERROR(SUM('Data Sheet'!B18,'Data Sheet'!B20:B22,-1*'Data Sheet'!B19),0) -> 205509.07 | D8: =IFERROR(SUM('Data Sheet'!C18:C22),0) -> 220254.08 | E8: =IFERROR(SUM('Data Sheet'!D18:D22),0) -> 232522.99 | F8: =IFERROR(SUM('Data Sheet'!E18:E22),0) -> 238738.97 | G8: =IFERROR(SUM('Data Sheet'!F18:F22),0) -> 205913.69 | H8: =IFERROR(SUM('Data Sheet'!G18:G22),0) -> 185957.72 | I8: =IFERROR(SUM('Data Sheet'!H18:H22),0) -> 220119.03 | J8: =IFERROR(SUM('Data Sheet'!I18:I22),0) -> 283966.88 | K8: =IFERROR(SUM('Data Sheet'!J18:J22),0) -> 337512 | L8: =IFERROR(SUM('Data Sheet'!K18:K22),0) -> 335137 | M8: =IFERROR(SUM('Data Sheet'!H43:K43),0) -> 384424
B9: COGS % Sales | C9: =C8/C5 -> 0.75265476 | D9: =D8/D5 -> 0.81668594 | E9: =E8/E5 -> 0.79753938 | F9: =F8/F5 -> 0.79068767 | G9: =G8/G5 -> 0.78873594 | H9: =H8/H5 -> 0.74444207 | I9: =I8/I5 -> 0.79050518 | J9: =J8/J5 -> 0.82079188 | ... M9: =M8/M5 -> 0.87050762
B11: Gross Profit | C11: =C5-C8 -> 67536.53 | D11: =D5-D8 -> 49438.43 | E11: =E5-E8 -> 59027.49 | F11: =F5-F8 -> 63199.43 | G11: =G5-G8 -> 55154.28 | H11: =H5-H8 -> 63837.03 | I11: =I5-I8 -> 58334.59 | J11: =J5-J8 -> 62000.09 | ... M11: =M5-M8 -> 57185
B13: Selling and general expenses | C13: =IFERROR(SUM('Data Sheet'!B23:B24),0) -> 29141.28 | D13: =IFERROR(SUM('Data Sheet'!C23:C24),0) -> 34649.58 | E13: =IFERROR(SUM('Data Sheet'!D23:D24),0) -> 31662.97 | F13: =IFERROR(SUM('Data Sheet'!E23:E24),0) -> 34428.54 | G13: =IFERROR(SUM('Data Sheet'!F23:F24),0) -> 32704.83 | H13: =IFERROR(SUM('Data Sheet'!G23:G24),0) -> 22181.28 | I13: =IFERROR(SUM('Data Sheet'!H23:H24),0) -> 30433.52 | J13: =IFERROR(SUM('Data Sheet'!I23:I24),0) -> 39747.53 | ... M13: =IFERROR(SUM('Data Sheet'!L23:L24),0) -> 0
B14: S&G Expenses % Sales | C14: =C13/C5 -> 0.10672679 | D14: =D13/D5 -> 0.1284781 | E14: =E13/E5 -> 0.10860202 | F14: =F13/F5 -> 0.11402505 | G14: =G13/G5 -> 0.12527324 | H14: =H13/H5 -> 0.088798023 | I14: =I13/I5 -> 0.10929475 | J14: =J13/J5 -> 0.11488822 | ... M14: =M13/M5 -> 0
B16: EBIDTA | C16: =C11-C13 -> 38395.25 | D16: =D11-D13 -> 14788.85 | E16: =E11-E13 -> 27364.52 | F16: =F11-F13 -> 28770.89 | G16: =G11-G13 -> 22449.45 | H16: =H11-H13 -> 41655.75 | I16: =I11-I13 -> 27901.07 | J16: =J11-J13 -> 22252.56 | ... M16: =M11-M13 -> 57185
B17: EBIDTA % Margins | C17: =C16/C5 -> 0.14061845 | D17: =D16/D5 -> 0.054835969 | E17: =E16/E5 -> 0.0938586 | F17: =F16/F5 -> 0.095287284 | G17: =G16/G5 -> 0.085990825 | H17: =H16/H5 -> 0.16675991 | I17: =I16/I5 -> 0.10020006 | J17: =J16/J5 -> 0.064319897 | ... M17: =M16/M5 -> 0.12949238
B19: Interest | C19: =IFERROR('Data Sheet'!B27,0) -> 4889.08 | D19: =IFERROR('Data Sheet'!C27,0) -> 4238.01 | E19: =IFERROR('Data Sheet'!D27,0) -> 4681.79 | F19: =IFERROR('Data Sheet'!E27,0) -> 5758.6 | G19: =IFERROR('Data Sheet'!F27,0) -> 7243.33 | H19: =IFERROR('Data Sheet'!G27,0) -> 8097.17 | I19: =IFERROR('Data Sheet'!H27,0) -> 9311.86 | J19: =IFERROR('Data Sheet'!I27,0) -> 10225.48 | ... L19: =IFERROR('Data Sheet'!K27,0) -> 5083 | M19: =IFERROR(SUM('Data Sheet'!H46:K46),0) -> 6317
B20: Interest % Sales | C20: =C19/C5 -> 0.017905727 | D20: =D19/D5 -> 0.01571423 | E20: =E19/E5 -> 0.016058248 | F20: =F19/F5 -> 0.019072102 | G20: =G19/G5 -> 0.027744997 | H20: =H19/H5 -> 0.032415293 | I20: =I19/I5 -> 0.033441332 | J20: =J19/J5 -> 0.029556232 | ... M20: =M19/M5 -> 0.014304509
B22: Depreciation | C22: =IFERROR('Data Sheet'!B26,0) -> 16710.78 | D22: =IFERROR('Data Sheet'!C26,0) -> 17904.99 | E22: =IFERROR('Data Sheet'!D26,0) -> 21553.59 | F22: =IFERROR('Data Sheet'!E26,0) -> 23590.63 | G22: =IFERROR('Data Sheet'!F26,0) -> 21425.43 | H22: =IFERROR('Data Sheet'!G26,0) -> 23546.71 | I22: =IFERROR('Data Sheet'!H26,0) -> 24835.69 | J22: =IFERROR('Data Sheet'!I26,0) -> 24860.36 | ... L22: =IFERROR('Data Sheet'!K26,0) -> 23256 | M22: =IFERROR(SUM('Data Sheet'!H45:K45),0) -> 23273
B23: Depreciation % Sales | C23: =IFERROR(C22/C5,0) -> 0.061201426 | D23: =IFERROR(D22/D5,0) -> 0.066390387 | E23: =IFERROR(E22/E5,0) -> 0.073927472 | F23: =IFERROR(F22/F5,0) -> 0.078130605 | G23: =IFERROR(G22/G5,0) -> 0.082068398 | H23: =IFERROR(H22/H5,0) -> 0.094264231 | I23: =IFERROR(I22/I5,0) -> 0.089191478 | J23: =IFERROR(J22/J5,0) -> 0.071857611 | ... M23: =IFERROR(M22/M5,0) -> 0.052700466
B25: Earnings before taxes | C25: =IFERROR(C16-SUM(C19,C22),0) -> 16795.39 | D25: =IFERROR(D16-SUM(D19,D22),0) -> -7354.15 | E25: =IFERROR(E16-SUM(E19,E22),0) -> 1129.14 | F25: =IFERROR(F16-SUM(F19,F22),0) -> -578.34 | G25: =IFERROR(G16-SUM(G19,G22),0) -> -6219.31 | H25: =IFERROR(H16-SUM(H19,H22),0) -> 10011.87 | I25: =IFERROR(I16-SUM(I19,I22),0) -> -6246.48 | J25: =IFERROR(J16-SUM(J19,J22),0) -> -12833.28 | ... M25: =IFERROR(M16-SUM(M19,M22),0) -> 27595
B26: EBT % Sales | C26: =IFERROR(C25/C5,0) -> 0.061511301 | D26: =IFERROR(D25/D5,0) -> -0.027268648 | E26: =IFERROR(E25/E5,0) -> 0.0038728799 | F26: =IFERROR(F25/F5,0) -> -0.0019154238 | G26: =IFERROR(G25/G5,0) -> -0.02382257 | H26: =IFERROR(H25/H5,0) -> 0.040080386 | I26: =IFERROR(I25/I5,0) -> -0.022432748 | J26: =IFERROR(J25/J5,0) -> -0.037093946 | ... M26: =IFERROR(M25/M5,0) -> 0.062487404
B28: Tax | C28: =IFERROR('Data Sheet'!B29,0) -> 3025.05 | D28: =IFERROR('Data Sheet'!C29,0) -> 3251.23 | E28: =IFERROR('Data Sheet'!D29,0) -> 4341.93 | F28: =IFERROR('Data Sheet'!E29,0) -> -2437.45 | G28: =IFERROR('Data Sheet'!F29,0) -> 395.25 | H28: =IFERROR('Data Sheet'!G29,0) -> 2541.86 | I28: =IFERROR('Data Sheet'!H29,0) -> 4231.29 | J28: =IFERROR('Data Sheet'!I29,0) -> 704.06 | ... L28: =IFERROR('Data Sheet'!K29,0) -> 10502 | M28: =IFERROR(SUM('Data Sheet'!H48:K48),0) -> 10563
B29: Effective tax rate | C29: =IFERROR(C28/C25,0) -> 0.18011192 | D29: =IFERROR(D28/D25,0) -> -0.4420946 | E29: =IFERROR(E28/E25,0) -> 3.8453425 | F29: =IFERROR(F28/F25,0) -> 4.2145624 | G29: =IFERROR(G28/G25,0) -> -0.063552066 | H29: =IFERROR(H28/H25,0) -> 0.25388464 | I29: =IFERROR(I28/I25,0) -> -0.6773879 | J29: =IFERROR(J28/J25,0) -> -0.054862046 | ... M29: =IFERROR(M28/M25,0) -> 0.38278674
B31: Net Profit | C31: =IFERROR(C25-C28,0) -> 13770.34 | D31: =IFERROR(D25-D28,0) -> -10605.38 | E31: =IFERROR(E25-E28,0) -> -3212.79 | F31: =IFERROR(F25-F28,0) -> 1859.11 | G31: =IFERROR(G25-G28,0) -> -6614.56 | H31: =IFERROR(H25-H28,0) -> 7470.01 | I31: =IFERROR(I25-I28,0) -> -10477.77 | J31: =IFERROR(J25-J28,0) -> -13537.34 | ... L31: =IFERROR(L25-L28,0) -> 22047 | M31: =IFERROR(SUM('Data Sheet'!H49:K49),0) -> 22785
B32: Net Margins | C32: =IFERROR(C31/C5,0) -> 0.050432382 | D32: =IFERROR(D31/D5,0) -> -0.039323969 | E32: =IFERROR(E31/E5,0) -> -0.01101967 | F32: =IFERROR(F31/F5,0) -> 0.0061572493 | G32: =IFERROR(G31/G5,0) -> -0.025336544 | H32: =IFERROR(H31/H5,0) -> 0.029904592 | I32: =IFERROR(I31/I5,0) -> -0.037628421 | J32: =IFERROR(J31/J5,0) -> -0.039128995 | ... M32: =IFERROR(M31/M5,0) -> 0.051595416
B34: No. of Equity Shares | C34: =IFERROR('Data Sheet'!B70/10000000,0) -> 339.59303 | D34: =IFERROR('Data Sheet'!C70/10000000,0) -> 339.61007 | E34: =IFERROR('Data Sheet'!D70/10000000,0) -> 339.61007 | F34: =IFERROR('Data Sheet'!E70/10000000,0) -> 339.61007 | G34: =IFERROR('Data Sheet'!F70/10000000,0) -> 359.77262 | H34: =IFERROR('Data Sheet'!G70/10000000,0) -> 382.90607 | I34: =IFERROR('Data Sheet'!H70/10000000,0) -> 382.94149 | J34: =IFERROR('Data Sheet'!I70/10000000,0) -> 383.00972 | ... L34: =IFERROR('Data Sheet'!K70/10000000,0) -> 368.13487
B36: EPS | C36: =IFERROR(C31/C34,0) -> 40.549537 | D36: =IFERROR(D31/D34,0) -> -31.228108 | E36: =IFERROR(E31/E34,0) -> -9.4602318 | F36: =IFERROR(F31/F34,0) -> 5.4742487 | G36: =IFERROR(G31/G34,0) -> -18.38539 | H36: =IFERROR(H31/H34,0) -> 19.508727 | I36: =IFERROR(I31/I34,0) -> -27.361282 | J36: =IFERROR(J31/J34,0) -> -35.344638 | ... L36: =IFERROR(L31/L34,0) -> 59.888377
B37: EPS growth % | D37: =IFERROR((D36/C36)-1,0) -> -1.7701224 | E37: =IFERROR((E36/D36)-1,0) -> -0.69706036 | F37: =IFERROR((F36/E36)-1,0) -> -1.578659 | G37: =IFERROR((G36/F36)-1,0) -> -4.358523 | H37: =IFERROR((H36/G36)-1,0) -> -2.0610994 | I37: =IFERROR((I36/H36)-1,0) -> -2.402515 | J37: =IFERROR((J36/I36)-1,0) -> 0.29177567 | K37: =IFERROR((K36/J36)-1,0) -> -2.763129 | L37: =IFERROR((L36/K36)-1,0) -> -0.038974508
B39: Dividend per share | C39: =IFERROR('Data Sheet'!B31/'Historical FS'!C34,0) -> 0.2000041 | D39: =IFERROR('Data Sheet'!C31/'Historical FS'!D34,0) -> 0 | E39: =IFERROR('Data Sheet'!D31/'Historical FS'!E34,0) -> 0 | F39: =IFERROR('Data Sheet'!E31/'Historical FS'!F34,0) -> 0 | G39: =IFERROR('Data Sheet'!F31/'Historical FS'!G34,0) -> 0 | H39: =IFERROR('Data Sheet'!G31/'Historical FS'!H34,0) -> 0 | I39: =IFERROR('Data Sheet'!H31/'Historical FS'!I34,0) -> 0 | J39: =IFERROR('Data Sheet'!I31/'Historical FS'!J34,0) -> 2.0000015 | ... L39: =IFERROR('Data Sheet'!K31/'Historical FS'!L34,0) -> 5.9978018
B40: dividend pay ratio | C40: =IFERROR(C39/C36,0) -> 0.0049323401 | D40: =IFERROR(D39/D36,0) -> 0 | E40: =IFERROR(E39/E36,0) -> 0 | F40: =IFERROR(F39/F36,0) -> 0 | G40: =IFERROR(G39/G36,0) -> 0 | H40: =IFERROR(H39/H36,0) -> 0 | I40: =IFERROR(I39/I36,0) -> 0 | J40: =IFERROR(J39/J36,0) -> -0.05658571 | ... L40: =IFERROR(L39/L36,0) -> 0.10014968
B42: Retained earnings | C42: =IFERROR(IF(C36>C39,1-C40,0),0) -> 0.99506766 | D42: =IFERROR(IF(D36>D39,1-D40,0),0) -> 0 | E42: =IFERROR(IF(E36>E39,1-E40,0),0) -> 0 | F42: =IFERROR(IF(F36>F39,1-F40,0),0) -> 1 | G42: =IFERROR(IF(G36>G39,1-G40,0),0) -> 0 | H42: =IFERROR(IF(H36>H39,1-H40,0),0) -> 1 | I42: =IFERROR(IF(I36>I39,1-I40,0),0) -> 0 | J42: =IFERROR(IF(J36>J39,1-J40,0),0) -> 0 | ... L42: =IFERROR(IF(L36>L39,1-L40,0),0) -> 0.89985032
A44: # | B44: Balance Sheet
B45: Equity Share Capital | C45: =IFERROR('Data Sheet'!B57,0) -> 679.18 | D45: =IFERROR('Data Sheet'!C57,0) -> 679.22 | E45: =IFERROR('Data Sheet'!D57,0) -> 679.22 | F45: =IFERROR('Data Sheet'!E57,0) -> 679.22 | G45: =IFERROR('Data Sheet'!F57,0) -> 719.54 | H45: =IFERROR('Data Sheet'!G57,0) -> 765.81 | I45: =IFERROR('Data Sheet'!H57,0) -> 765.88 | J45: =IFERROR('Data Sheet'!I57,0) -> 766.02 | ... L45: =IFERROR('Data Sheet'!K57,0) -> 736
B46: Reserves | C46: =IFERROR('Data Sheet'!B58,0) -> 78273.23 | D46: =IFERROR('Data Sheet'!C58,0) -> 57382.67 | E46: =IFERROR('Data Sheet'!D58,0) -> 94748.69 | F46: =IFERROR('Data Sheet'!E58,0) -> 59500.34 | G46: =IFERROR('Data Sheet'!F58,0) -> 62358.99 | H46: =IFERROR('Data Sheet'!G58,0) -> 54480.91 | I46: =IFERROR('Data Sheet'!H58,0) -> 43795.36 | J46: =IFERROR('Data Sheet'!I58,0) -> 44555.77 | ... L46: =IFERROR('Data Sheet'!K58,0) -> 115408
B47: Borrowings | C47: =IFERROR('Data Sheet'!B59,0) -> 69359.96 | D47: =IFERROR('Data Sheet'!C59,0) -> 78603.98 | E47: =IFERROR('Data Sheet'!D59,0) -> 88950.47 | F47: =IFERROR('Data Sheet'!E59,0) -> 106175.34 | G47: =IFERROR('Data Sheet'!F59,0) -> 124787.64 | H47: =IFERROR('Data Sheet'!G59,0) -> 142130.57 | I47: =IFERROR('Data Sheet'!H59,0) -> 146449.03 | J47: =IFERROR('Data Sheet'!I59,0) -> 134113.44 | ... L47: =IFERROR('Data Sheet'!K59,0) -> 71540
B48: Other Liabilities | C48: =IFERROR('Data Sheet'!B60,0) -> 114871.75 | D48: =IFERROR('Data Sheet'!C60,0) -> 135914.49 | E48: =IFERROR('Data Sheet'!D60,0) -> 142813.43 | F48: =IFERROR('Data Sheet'!E60,0) -> 139348.59 | G48: =IFERROR('Data Sheet'!F60,0) -> 132313.22 | H48: =IFERROR('Data Sheet'!G60,0) -> 144192.62 | I48: =IFERROR('Data Sheet'!H60,0) -> 138051.22 | J48: =IFERROR('Data Sheet'!I60,0) -> 155239.2 | ... L48: =IFERROR('Data Sheet'!K60,0) -> 189289
B49: Total liabilities | C49: =IFERROR('Data Sheet'!B61,0) -> 263184.12 | D49: =IFERROR('Data Sheet'!C61,0) -> 272580.36 | E49: =IFERROR('Data Sheet'!D61,0) -> 327191.81 | F49: =IFERROR('Data Sheet'!E61,0) -> 305703.49 | G49: =IFERROR('Data Sheet'!F61,0) -> 320179.39 | H49: =IFERROR('Data Sheet'!G61,0) -> 341569.91 | I49: =IFERROR('Data Sheet'!H61,0) -> 329061.49 | J49: =IFERROR('Data Sheet'!I61,0) -> 334674.43 | ... L49: =IFERROR('Data Sheet'!K61,0) -> 376973
B51: Fixed Assets Net Block | C51: =IFERROR('Data Sheet'!B62,0) -> 107231.76 | D51: =IFERROR('Data Sheet'!C62,0) -> 95944.08 | E51: =IFERROR('Data Sheet'!D62,0) -> 121413.86 | F51: =IFERROR('Data Sheet'!E62,0) -> 111234.47 | G51: =IFERROR('Data Sheet'!F62,0) -> 127107.14 | H51: =IFERROR('Data Sheet'!G62,0) -> 138707.61 | I51: =IFERROR('Data Sheet'!H62,0) -> 138855.45 | J51: =IFERROR('Data Sheet'!I62,0) -> 132079.76 | ... L51: =IFERROR('Data Sheet'!K62,0) -> 115697
B52: Capital Work in Progress | C52: =IFERROR('Data Sheet'!B63,0) -> 25918.94 | D52: =IFERROR('Data Sheet'!C63,0) -> 33698.84 | E52: =IFERROR('Data Sheet'!D63,0) -> 40033.5 | F52: =IFERROR('Data Sheet'!E63,0) -> 31883.84 | G52: =IFERROR('Data Sheet'!F63,0) -> 35622.29 | H52: =IFERROR('Data Sheet'!G63,0) -> 20963.93 | I52: =IFERROR('Data Sheet'!H63,0) -> 10251.09 | J52: =IFERROR('Data Sheet'!I63,0) -> 14274.5 | ... L52: =IFERROR('Data Sheet'!K63,0) -> 65806
B53: Investments | C53: =IFERROR('Data Sheet'!B64,0) -> 23767.02 | D53: =IFERROR('Data Sheet'!C64,0) -> 20337.92 | E53: =IFERROR('Data Sheet'!D64,0) -> 20812.75 | F53: =IFERROR('Data Sheet'!E64,0) -> 15770.72 | G53: =IFERROR('Data Sheet'!F64,0) -> 16308.48 | H53: =IFERROR('Data Sheet'!G64,0) -> 24620.28 | I53: =IFERROR('Data Sheet'!H64,0) -> 29379.53 | J53: =IFERROR('Data Sheet'!I64,0) -> 26379.16 | ... L53: =IFERROR('Data Sheet'!K64,0) -> 35656
B54: Other Assets | C54: =IFERROR('Data Sheet'!B65,0) -> 106266.4 | D54: =IFERROR('Data Sheet'!C65,0) -> 122599.52 | E54: =IFERROR('Data Sheet'!D65,0) -> 144931.7 | F54: =IFERROR('Data Sheet'!E65,0) -> 146814.46 | G54: =IFERROR('Data Sheet'!F65,0) -> 141141.48 | H54: =IFERROR('Data Sheet'!G65,0) -> 157278.09 | I54: =IFERROR('Data Sheet'!H65,0) -> 150575.42 | J54: =IFERROR('Data Sheet'!I65,0) -> 161941.01 | ... L54: =IFERROR('Data Sheet'!K65,0) -> 159814
B55: Total non - current Assets | C55: =IFERROR(SUM('Data Sheet'!B62:B65)-SUM('Data Sheet'!B67:B69),0) -> 186497.08 | D55: =IFERROR(SUM('Data Sheet'!C62:C65)-SUM('Data Sheet'!C67:C69),0) -> 187341.62 | E55: =IFERROR(SUM('Data Sheet'!D62:D65)-SUM('Data Sheet'!D67:D69),0) -> 230546.97 | F55: =IFERROR(SUM('Data Sheet'!E62:E65)-SUM('Data Sheet'!E67:E69),0) -> 215044.77 | G55: =IFERROR(SUM('Data Sheet'!F62:F65)-SUM('Data Sheet'!F67:F69),0) -> 237822.85 | H55: =IFERROR(SUM('Data Sheet'!G62:G65)-SUM('Data Sheet'!G67:G69),0) -> 246009.78 | I55: =IFERROR(SUM('Data Sheet'!H62:H65)-SUM('Data Sheet'!H67:H69),0) -> 240709.84 | J55: =IFERROR(SUM('Data Sheet'!I62:I65)-SUM('Data Sheet'!I67:I69),0) -> 241165.51 | ... L55: =IFERROR(SUM('Data Sheet'!K62:K65)-SUM('Data Sheet'!K67:K69),0) -> 275622
B57: Receivables | C57: =IFERROR('Data Sheet'!B67,0) -> 13570.91 | D57: =IFERROR('Data Sheet'!C67,0) -> 14075.55 | E57: =IFERROR('Data Sheet'!D67,0) -> 19893.3 | F57: =IFERROR('Data Sheet'!E67,0) -> 18996.17 | G57: =IFERROR('Data Sheet'!F67,0) -> 11172.69 | H57: =IFERROR('Data Sheet'!G67,0) -> 12679.08 | I57: =IFERROR('Data Sheet'!H67,0) -> 12442.12 | J57: =IFERROR('Data Sheet'!I67,0) -> 15737.97 | ... L57: =IFERROR('Data Sheet'!K67,0) -> 13248
...

Sheet Ratio analysis
B2: ="Ratio Analysis - "&'Data Sheet'!B1 -> Ratio Analysis - TATA MOTORS LTD
B3: Years | C3: ='Data Sheet'!B16 -> 42460 | D3: ='Data Sheet'!C16 -> 42825 | E3: ='Data Sheet'!D16 -> 43190 | F3: ='Data Sheet'!E16 -> 43555 | G3: ='Data Sheet'!F16 -> 43921 | H3: ='Data Sheet'!G16 -> 44286 | I3: ='Data Sheet'!H16 -> 44651 | J3: ='Data Sheet'!I16 -> 45016 | ... L3: ='Data Sheet'!K16 -> 45747 | M3: Trend | N3: Mean | O3: Median
B4: SalesGrowth | D4: =IFERROR('Historical FS'!D6,0) -> -0.01228033 | E4: =IFERROR('Historical FS'!E6,0) -> 0.081047746 | F4: =IFERROR('Historical FS'!F6,0) -> 0.035629919 | G4: =IFERROR('Historical FS'!G6,0) -> -0.13536016 | H4: =IFERROR('Historical FS'!H6,0) -> -0.043181168 | I4: =IFERROR('Historical FS'!I6,0) -> 0.11472967 | J4: =IFERROR('Historical FS'!J6,0) -> 0.24245815 | K4: =IFERROR('Historical FS'!K6,0) -> 0.25450126 | L4: =IFERROR('Historical FS'!L6,0) -> 0.013084771 | N4: =MEDIAN(C4:L4) -> 0.035629919 | O4: =AVERAGE(C4:L4) -> 0.061181096
B5: GrossMargin | D5: =IFERROR('Historical FS'!C11/'Historical FS'!C5,0) -> 0.24734524 | E5: =IFERROR('Historical FS'!D11/'Historical FS'!D5,0) -> 0.18331406 | F5: =IFERROR('Historical FS'!E11/'Historical FS'!E5,0) -> 0.20246062 | G5: =IFERROR('Historical FS'!F11/'Historical FS'!F5,0) -> 0.20931233 | H5: =IFERROR('Historical FS'!G11/'Historical FS'!G5,0) -> 0.21126406 | I5: =IFERROR('Historical FS'!H11/'Historical FS'!H5,0) -> 0.25555793 | J5: =IFERROR('Historical FS'!I11/'Historical FS'!I5,0) -> 0.20949482 | K5: =IFERROR('Historical FS'!J11/'Historical FS'!J5,0) -> 0.17920812 | L5: =IFERROR('Historical FS'!K11/'Historical FS'!K5,0) -> 0.22235125 | N5: =MEDIAN(C5:L5) -> 0.20949482 | O5: =AVERAGE(C5:L5) -> 0.2133676
B6: EBITDA Growth | D6: =IFERROR('Historical FS'!D16/'Historical FS'!C16-1,0) -> -0.61482605 | E6: =IFERROR('Historical FS'!E16/'Historical FS'!D16-1,0) -> 0.85034807 | F6: =IFERROR('Historical FS'!F16/'Historical FS'!E16-1,0) -> 0.051393922 | G6: =IFERROR('Historical FS'!G16/'Historical FS'!F16-1,0) -> -0.21971653 | H6: =IFERROR('Historical FS'!H16/'Historical FS'!G16-1,0) -> 0.85553544 | I6: =IFERROR('Historical FS'!I16/'Historical FS'!H16-1,0) -> -0.33019883 | J6: =IFERROR('Historical FS'!J16/'Historical FS'!I16-1,0) -> -0.20244779 | K6: =IFERROR('Historical FS'!K16/'Historical FS'!J16-1,0) -> 1.4577846 | L6: =IFERROR('Historical FS'!L16/'Historical FS'!K16-1,0) -> 0.11328896 | N6: =MEDIAN(C6:L6) -> 0.051393922 | O6: =AVERAGE(C6:L6) -> 0.21790687
B7: EBIT Growth | D7: =IFERROR('Historical FS'!D25/'Historical FS'!C25-1,0) -> -1.4378672 | E7: =IFERROR('Historical FS'!E25/'Historical FS'!D25-1,0) -> -1.1535378 | F7: =IFERROR('Historical FS'!F25/'Historical FS'!E25-1,0) -> -1.5121951 | G7: =IFERROR('Historical FS'!G25/'Historical FS'!F25-1,0) -> 9.7537262 | H7: =IFERROR('Historical FS'!H25/'Historical FS'!G25-1,0) -> -2.609804 | I7: =IFERROR('Historical FS'!I25/'Historical FS'!H25-1,0) -> -1.6239074 | J7: =IFERROR('Historical FS'!J25/'Historical FS'!I25-1,0) -> 1.0544819 | K7: =IFERROR('Historical FS'!K25/'Historical FS'!J25-1,0) -> -2.547461 | L7: =IFERROR('Historical FS'!L25/'Historical FS'!K25-1,0) -> 0.63900499 | N7: =MEDIAN(C7:L7) -> -1.4378672 | O7: =AVERAGE(C7:L7) -> 0.062493397
B8: Net Profit Growth | D8: =IFERROR('Historical FS'!D31/'Historical FS'!C31-1,0) -> -1.7701611 | E8: =IFERROR('Historical FS'!E31/'Historical FS'!D31-1,0) -> -0.69706036 | F8: =IFERROR('Historical FS'!F31/'Historical FS'!E31-1,0) -> -1.578659 | G8: =IFERROR('Historical FS'!G31/'Historical FS'!F31-1,0) -> -4.5579175 | H8: =IFERROR('Historical FS'!H31/'Historical FS'!G31-1,0) -> -2.1293283 | I8: =IFERROR('Historical FS'!I31/'Historical FS'!H31-1,0) -> -2.4026447 | J8: =IFERROR('Historical FS'!J31/'Historical FS'!I31-1,0) -> 0.29200584 | K8: =IFERROR('Historical FS'!K31/'Historical FS'!J31-1,0) -> -2.7642314 | L8: =IFERROR('Historical FS'!L31/'Historical FS'!K31-1,0) -> -0.076874764 | N8: =MEDIAN(C8:L8) -> -1.7701611 | O8: =AVERAGE(C8:L8) -> -1.7427635
B9: Dividend Growth | D9: =IFERROR('Historical FS'!D39/'Historical FS'!C39-1,0) -> -1 | E9: =IFERROR('Historical FS'!E39/'Historical FS'!D39-1,0) -> 0 | F9: =IFERROR('Historical FS'!F39/'Historical FS'!E39-1,0) -> 0 | G9: =IFERROR('Historical FS'!G39/'Historical FS'!F39-1,0) -> 0 | H9: =IFERROR('Historical FS'!H39/'Historical FS'!G39-1,0) -> 0 | I9: =IFERROR('Historical FS'!I39/'Historical FS'!H39-1,0) -> 0 | J9: =IFERROR('Historical FS'!J39/'Historical FS'!I39-1,0) -> 0 | K9: =IFERROR('Historical FS'!K39/'Historical FS'!J39-1,0) -> 2.0019611 | L9: =IFERROR('Historical FS'!L39/'Historical FS'!K39-1,0) -> -0.0010201355 | N9: =MEDIAN(C9:L9) -> 0 | O9: =AVERAGE(C9:L9) -> 0.11121566
B11: Gross Margin | C11: =IFERROR('Historical FS'!C11/'Historical FS'!C5,0) -> 0.24734524 | D11: =IFERROR('Historical FS'!D11/'Historical FS'!D5,0) -> 0.18331406 | E11: =IFERROR('Historical FS'!E11/'Historical FS'!E5,0) -> 0.20246062 | F11: =IFERROR('Historical FS'!F11/'Historical FS'!F5,0) -> 0.20931233 | G11: =IFERROR('Historical FS'!G11/'Historical FS'!G5,0) -> 0.21126406 | H11: =IFERROR('Historical FS'!H11/'Historical FS'!H5,0) -> 0.25555793 | I11: =IFERROR('Historical FS'!I11/'Historical FS'!I5,0) -> 0.20949482 | J11: =IFERROR('Historical FS'!J11/'Historical FS'!J5,0) -> 0.17920812 | ... L11: =IFERROR('Historical FS'!L11/'Historical FS'!L5,0) -> 0.23779665 | N11: =MEDIAN(C11:L11) -> 0.21037944 | O11: =AVERAGE(C11:L11) -> 0.21581051
B12: Operating Margin
B13: EBITDA Margin | C13: =IFERROR('Historical FS'!C17,0) -> 0.14061845 | D13: =IFERROR('Historical FS'!D17,0) -> 0.054835969 | E13: =IFERROR('Historical FS'!E17,0) -> 0.0938586 | F13: =IFERROR('Historical FS'!F17,0) -> 0.095287284 | G13: =IFERROR('Historical FS'!G17,0) -> 0.085990825 | H13: =IFERROR('Historical FS'!H17,0) -> 0.16675991 | I13: =IFERROR('Historical FS'!I17,0) -> 0.10020006 | J13: =IFERROR('Historical FS'!J17,0) -> 0.064319897 | ... L13: =IFERROR('Historical FS'!L17,0) -> 0.13847781 | N13: =MEDIAN(C13:L13) -> 0.097743673 | O13: =AVERAGE(C13:L13) -> 0.10663626
B14: EBIT Margin | C14: =IFERROR(('Historical FS'!C16-'Historical FS'!C22)/'Historical FS'!C5,0) -> 0.079417028 | D14: =IFERROR(('Historical FS'!D16-'Historical FS'!D22)/'Historical FS'!D5,0) -> -0.011554418 | E14: =IFERROR(('Historical FS'!E16-'Historical FS'!E22)/'Historical FS'!E5,0) -> 0.019931128 | F14: =IFERROR(('Historical FS'!F16-'Historical FS'!F22)/'Historical FS'!F5,0) -> 0.017156678 | G14: =IFERROR(('Historical FS'!G16-'Historical FS'!G22)/'Historical FS'!G5,0) -> 0.0039224268 | H14: =IFERROR(('Historical FS'!H16-'Historical FS'!H22)/'Historical FS'!H5,0) -> 0.072495679 | I14: =IFERROR(('Historical FS'!I16-'Historical FS'!I22)/'Historical FS'!I5,0) -> 0.011008584 | J14: =IFERROR(('Historical FS'!J16-'Historical FS'!J22)/'Historical FS'!J5,0) -> -0.0075377138 | ... L14: =IFERROR(('Historical FS'!L16-'Historical FS'!L22)/'Historical FS'!L5,0) -> 0.0855866 | N14: =MEDIAN(C14:L14) -> 0.018543903 | O14: =AVERAGE(C14:L14) -> 0.033367942
B15: EBT Margin | C15: =IFERROR('Historical FS'!C26,0) -> 0.061511301 | D15: =IFERROR('Historical FS'!D26,0) -> -0.027268648 | E15: =IFERROR('Historical FS'!E26,0) -> 0.0038728799 | F15: =IFERROR('Historical FS'!F26,0) -> -0.0019154238 | G15: =IFERROR('Historical FS'!G26,0) -> -0.02382257 | H15: =IFERROR('Historical FS'!H26,0) -> 0.040080386 | I15: =IFERROR('Historical FS'!I26,0) -> -0.022432748 | J15: =IFERROR('Historical FS'!J26,0) -> -0.037093946 | ... L15: =IFERROR('Historical FS'!L26,0) -> 0.074026314 | N15: =MEDIAN(C15:L15) -> 0.00097872806 | O15: =AVERAGE(C15:L15) -> 0.011271392
B16: Net Profit Margin | C16: =IFERROR('Historical FS'!C32,0) -> 0.050432382 | D16: =IFERROR('Historical FS'!D32,0) -> -0.039323969 | E16: =IFERROR('Historical FS'!E32,0) -> -0.01101967 | F16: =IFERROR('Historical FS'!F32,0) -> 0.0061572493 | G16: =IFERROR('Historical FS'!G32,0) -> -0.025336544 | H16: =IFERROR('Historical FS'!H32,0) -> 0.029904592 | I16: =IFERROR('Historical FS'!I32,0) -> -0.037628421 | J16: =IFERROR('Historical FS'!J32,0) -> -0.039128995 | ... L16: =IFERROR('Historical FS'!L32,0) -> 0.050141575 | N16: =MEDIAN(C16:L16) -> -0.0024312102 | O16: =AVERAGE(C16:L16) -> 0.0039226125
B18: SalesExpenses%Sales | C18: =IFERROR('Historical FS'!C14,0) -> 0.10672679 | D18: =IFERROR('Historical FS'!D14,0) -> 0.1284781 | E18: =IFERROR('Historical FS'!E14,0) -> 0.10860202 | F18: =IFERROR('Historical FS'!F14,0) -> 0.11402505 | G18: =IFERROR('Historical FS'!G14,0) -> 0.12527324 | H18: =IFERROR('Historical FS'!H14,0) -> 0.088798023 | I18: =IFERROR('Historical FS'!I14,0) -> 0.10929475 | J18: =IFERROR('Historical FS'!J14,0) -> 0.11488822 | ... L18: =IFERROR('Historical FS'!L14,0) -> 0.099318846 | N18: =MEDIAN(C18:L18) -> 0.10894839 | O18: =AVERAGE(C18:L18) -> 0.10917425
B19: Depreciation%Sales | C19: =IFERROR('Historical FS'!C23,0) -> 0.061201426 | D19: =IFERROR('Historical FS'!D23,0) -> 0.066390387 | E19: =IFERROR('Historical FS'!E23,0) -> 0.073927472 | F19: =IFERROR('Historical FS'!F23,0) -> 0.078130605 | G19: =IFERROR('Historical FS'!G23,0) -> 0.082068398 | H19: =IFERROR('Historical FS'!H23,0) -> 0.094264231 | I19: =IFERROR('Historical FS'!I23,0) -> 0.089191478 | J19: =IFERROR('Historical FS'!J23,0) -> 0.071857611 | ... L19: =IFERROR('Historical FS'!L23,0) -> 0.052891209 | N19: =MEDIAN(C19:L19) -> 0.072892542 | O19: =AVERAGE(C19:L19) -> 0.073268318
B20: OperatingIncome%Sales | C20: =C14 -> 0.079417028 | D20: =D14 -> -0.011554418 | E20: =E14 -> 0.019931128 | F20: =F14 -> 0.017156678 | G20: =G14 -> 0.0039224268 | H20: =H14 -> 0.072495679 | I20: =I14 -> 0.011008584 | J20: =J14 -> -0.0075377138 | ... L20: =L14 -> 0.0855866 | N20: =MEDIAN(C20:L20) -> 0.018543903 | O20: =AVERAGE(C20:L20) -> 0.033367942
B22: Return on Capital Employed | C22: =IFERROR(('Historical FS'!C16-'Historical FS'!C19) / SUM('Historical FS'!C45:C47),0) -> 0.22591622 | D22: =IFERROR(('Historical FS'!D16-'Historical FS'!D19) / SUM('Historical FS'!D45:D47),0) -> 0.077201718 | E22: =IFERROR(('Historical FS'!E16-'Historical FS'!E19) / SUM('Historical FS'!E45:E47),0) -> 0.12302272 | F22: =IFERROR(('Historical FS'!F16-'Historical FS'!F19) / SUM('Historical FS'!F45:F47),0) -> 0.1383325 | G22: =IFERROR(('Historical FS'!G16-'Historical FS'!G19) / SUM('Historical FS'!G45:G47),0) -> 0.080941236 | H22: =IFERROR(('Historical FS'!H16-'Historical FS'!H19) / SUM('Historical FS'!H45:H47),0) -> 0.1700225 | I22: =IFERROR(('Historical FS'!I16-'Historical FS'!I19) / SUM('Historical FS'!I45:I47),0) -> 0.097320474 | J22: =IFERROR(('Historical FS'!J16-'Historical FS'!J19) / SUM('Historical FS'!J45:J47),0) -> 0.067027417 | ... L22: =IFERROR(('Historical FS'!L16-'Historical FS'!L19) / SUM('Historical FS'!L45:L47),0) -> 0.29733488 | N22: =MEDIAN(C22:L22) -> 0.13067761 | O22: =AVERAGE(C22:L22) -> 0.15221894
B23: Retained Earnings% | C23: =IFERROR('Historical FS'!C42,0) -> 0.99506766 | D23: =IFERROR('Historical FS'!D42,0) -> 0 | E23: =IFERROR('Historical FS'!E42,0) -> 0 | F23: =IFERROR('Historical FS'!F42,0) -> 1 | G23: =IFERROR('Historical FS'!G42,0) -> 0 | H23: =IFERROR('Historical FS'!H42,0) -> 1 | I23: =IFERROR('Historical FS'!I42,0) -> 0 | J23: =IFERROR('Historical FS'!J42,0) -> 0 | ... L23: =IFERROR('Historical FS'!L42,0) -> 0.89985032 | N23: =MEDIAN(C23:L23) -> 0.44992516 | O23: =AVERAGE(C23:L23) -> 0.47985733
B24: Return on Equity% | C24: =IFERROR('Historical FS'!C31/SUM('Historical FS'!C45:C46),0) -> 0.17441317 | D24: =IFERROR('Historical FS'!D31/SUM('Historical FS'!D45:D46),0) -> -0.18265647 | E24: =IFERROR('Historical FS'!E31/SUM('Historical FS'!E45:E46),0) -> -0.033667194 | F24: =IFERROR('Historical FS'!F31/SUM('Historical FS'!F45:F46),0) -> 0.030892715 | G24: =IFERROR('Historical FS'!G31/SUM('Historical FS'!G45:G46),0) -> -0.1048623 | H24: =IFERROR('Historical FS'!H31/SUM('Historical FS'!H45:H46),0) -> 0.13521183 | I24: =IFERROR('Historical FS'!I31/SUM('Historical FS'!I45:I46),0) -> -0.23513192 | J24: =IFERROR('Historical FS'!J31/SUM('Historical FS'!J45:J46),0) -> -0.29869385 | ... L24: =IFERROR('Historical FS'!L31/SUM('Historical FS'!L45:L46),0) -> 0.1898247 | N24: =MEDIAN(C24:L24) -> -0.0013872397 | O24: =AVERAGE(C24:L24) -> -0.004342154
B25: Self Sustained Growth Rate | C25: =IFERROR(C23*C24,0) -> 0.1735529 | D25: =IFERROR(D23*D24,0) -> 0 | E25: =IFERROR(E23*E24,0) -> 0 | F25: =IFERROR(F23*F24,0) -> 0.030892715 | G25: =IFERROR(G23*G24,0) -> 0 | H25: =IFERROR(H23*H24,0) -> 0.13521183 | I25: =IFERROR(I23*I24,0) -> 0 | J25: =IFERROR(J23*J24,0) -> 0 | ... L25: =IFERROR(L23*L24,0) -> 0.17081382 | N25: =MEDIAN(C25:L25) -> 0.015446358 | O25: =AVERAGE(C25:L25) -> 0.076462233
B26: Interest Coverage Ratio | C26: =IFERROR(('Historical FS'!C16-'Historical FS'!C19)/'Historical FS'!C19,0) -> 6.8532669 | D26: =IFERROR(('Historical FS'!D16-'Historical FS'!D19)/'Historical FS'!D19,0) -> 2.4895741 | E26: =IFERROR(('Historical FS'!E16-'Historical FS'!E19)/'Historical FS'!E19,0) -> 4.8448841 | F26: =IFERROR(('Historical FS'!F16-'Historical FS'!F19)/'Historical FS'!F19,0) -> 3.9961605 | G26: =IFERROR(('Historical FS'!G16-'Historical FS'!G19)/'Historical FS'!G19,0) -> 2.0993272 | H26: =IFERROR(('Historical FS'!H16-'Historical FS'!H19)/'Historical FS'!H19,0) -> 4.1444826 | I26: =IFERROR(('Historical FS'!I16-'Historical FS'!I19)/'Historical FS'!I19,0) -> 1.996294 | J26: =IFERROR(('Historical FS'!J16-'Historical FS'!J19)/'Historical FS'!J19,0) -> 1.1761873 | ... L26: =IFERROR(('Historical FS'!L16-'Historical FS'!L19)/'Historical FS'!L19,0) -> 10.978753 | N26: =MEDIAN(C26:L26) -> 4.0703216 | O26: =AVERAGE(C26:L26) -> 4.4780931
B28: Debtor Turnover Ratio | C28: =IFERROR('Historical FS'!C5/'Historical FS'!C57,0) -> 20.119918 | D28: =IFERROR('Historical FS'!D5/'Historical FS'!D57,0) -> 19.160353 | E28: =IFERROR('Historical FS'!E5/'Historical FS'!E57,0) -> 14.655712 | F28: =IFERROR('Historical FS'!F5/'Historical FS'!F57,0) -> 15.894699 | G28: =IFERROR('Historical FS'!G5/'Historical FS'!G57,0) -> 23.366617 | H28: =IFERROR('Historical FS'!H5/'Historical FS'!H57,0) -> 19.701331 | I28: =IFERROR('Historical FS'!I5/'Historical FS'!I57,0) -> 22.379918 | J28: =IFERROR('Historical FS'!J5/'Historical FS'!J57,0) -> 21.982948 | ... L28: =IFERROR('Historical FS'!L5/'Historical FS'!L57,0) -> 33.189538 | N28: =MEDIAN(C28:L28) -> 21.051433 | O28: =AVERAGE(C28:L28) -> 21.605368
B29: Creditor Turnover Ratio | C29: =IFERROR('Historical FS'!C5/'Historical FS'!C48,0) -> 2.3769604 | D29: =IFERROR('Historical FS'!D5/'Historical FS'!D48,0) -> 1.9842808 | E29: =IFERROR('Historical FS'!E5/'Historical FS'!E48,0) -> 2.041478 | F29: =IFERROR('Historical FS'!F5/'Historical FS'!F48,0) -> 2.1667848 | G29: =IFERROR('Historical FS'!G5/'Historical FS'!G48,0) -> 1.9731057 | H29: =IFERROR('Historical FS'!H5/'Historical FS'!H48,0) -> 1.7323685 | I29: =IFERROR('Historical FS'!I5/'Historical FS'!I48,0) -> 2.0170312 | J29: =IFERROR('Historical FS'!J5/'Historical FS'!J48,0) -> 2.2286057 | ... L29: =IFERROR('Historical FS'!L5/'Historical FS'!L48,0) -> 2.3228767 | N29: =MEDIAN(C29:L29) -> 2.1041314 | O29: =AVERAGE(C29:L29) -> 2.1290872
B30: Inventory Turnover | C30: =IFERROR('Historical FS'!C5/'Historical FS'!C58,0) -> 8.3613381 | D30: =IFERROR('Historical FS'!D5/'Historical FS'!D58,0) -> 7.6867643 | E30: =IFERROR('Historical FS'!E5/'Historical FS'!E58,0) -> 6.9190052 | F30: =IFERROR('Historical FS'!F5/'Historical FS'!F58,0) -> 7.7392856 | G30: =IFERROR('Historical FS'!G5/'Historical FS'!G58,0) -> 6.9698269 | H30: =IFERROR('Historical FS'!H5/'Historical FS'!H58,0) -> 6.9217099 | I30: =IFERROR('Historical FS'!I5/'Historical FS'!I58,0) -> 7.9015588 | J30: =IFERROR('Historical FS'!J5/'Historical FS'!J58,0) -> 8.4888642 | ... L30: =IFERROR('Historical FS'!L5/'Historical FS'!L58,0) -> 9.3019738 | N30: =MEDIAN(C30:L30) -> 7.8204222 | O30: =AVERAGE(C30:L30) -> 7.937244
B31: Fixed Asset Turnover | C31: =IFERROR('Historical FS'!C5/'Historical FS'!C51,0) -> 2.5463128 | D31: =IFERROR('Historical FS'!D5/'Historical FS'!D51,0) -> 2.8109343 | E31: =IFERROR('Historical FS'!E5/'Historical FS'!E51,0) -> 2.4012949 | F31: =IFERROR('Historical FS'!F5/'Historical FS'!F51,0) -> 2.714432 | G31: =IFERROR('Historical FS'!G5/'Historical FS'!G51,0) -> 2.0539206 | H31: =IFERROR('Historical FS'!H5/'Historical FS'!H51,0) -> 1.8008727 | I31: =IFERROR('Historical FS'!I5/'Historical FS'!I51,0) -> 2.0053489 | J31: =IFERROR('Historical FS'!J5/'Historical FS'!J51,0) -> 2.6193792 | ... L31: =IFERROR('Historical FS'!L5/'Historical FS'!L51,0) -> 3.800401 | N31: =MEDIAN(C31:L31) -> 2.582846 | O31: =AVERAGE(C31:L31) -> 2.6331377
B32: Capital Turnover Ratio | C32: =IFERROR('Historical FS'!C5/SUM('Historical FS'!C45:C47),0) -> 1.841017 | D32: =IFERROR('Historical FS'!D5/SUM('Historical FS'!D45:D47),0) -> 1.9733713 | E32: =IFERROR('Historical FS'!E5/SUM('Historical FS'!E45:E47),0) -> 1.5812618 | F32: =IFERROR('Historical FS'!F5/SUM('Historical FS'!F45:F47),0) -> 1.8150256 | G32: =IFERROR('Historical FS'!G5/SUM('Historical FS'!G45:G47),0) -> 1.3896487 | H32: =IFERROR('Historical FS'!H5/SUM('Historical FS'!H45:H47),0) -> 1.2655699 | I32: =IFERROR('Historical FS'!I5/SUM('Historical FS'!I45:I47),0) -> 1.457794 | J32: =IFERROR('Historical FS'!J5/SUM('Historical FS'!J45:J47),0) -> 1.9280883 | ... L32: =IFERROR('Historical FS'!L5/SUM('Historical FS'!L45:L47),0) -> 2.342741 | N32: =MEDIAN(C32:L32) -> 1.8280213 | O32: =AVERAGE(C32:L32) -> 1.7852877
B35: Debtor Days | C35: =IFERROR(365/C28,0) -> 18.141227 | D35: =IFERROR(365/D28,0) -> 19.049753 | E35: =IFERROR(365/E28,0) -> 24.904965 | F35: =IFERROR(365/F28,0) -> 22.963631 | G35: =IFERROR(365/G28,0) -> 15.620575 | H35: =IFERROR(365/H28,0) -> 18.526667 | I35: =IFERROR(365/I28,0) -> 16.309265 | J35: =IFERROR(365/J28,0) -> 16.603779 | ... L35: =IFERROR(365/L28,0) -> 10.997441 | N35: =MEDIAN(C35:L35) -> 17.372503 | O35: =AVERAGE(C35:L35) -> 17.737364
B36: Payable Days | C36: =IFERROR(365/C29,0) -> 153.55746 | D36: =IFERROR(365/D29,0) -> 183.94574 | E36: =IFERROR(365/E29,0) -> 178.79203 | F36: =IFERROR(365/F29,0) -> 168.45236 | G36: =IFERROR(365/G29,0) -> 184.98755 | H36: =IFERROR(365/H29,0) -> 210.69421 | I36: =IFERROR(365/I29,0) -> 180.95902 | J36: =IFERROR(365/J29,0) -> 163.77953 | ... L36: =IFERROR(365/L29,0) -> 157.13275 | N36: =MEDIAN(C36:L36) -> 173.62219 | O36: =AVERAGE(C36:L36) -> 173.14397
B37: Inventory Days | C37: =IFERROR(365/C30,0) -> 43.6533 | D37: =IFERROR(365/D30,0) -> 47.484219 | E37: =IFERROR(365/E30,0) -> 52.753249 | F37: =IFERROR(365/F30,0) -> 47.161976 | G37: =IFERROR(365/G30,0) -> 52.368589 | H37: =IFERROR(365/H30,0) -> 52.732635 | I37: =IFERROR(365/I30,0) -> 46.193417 | J37: =IFERROR(365/J30,0) -> 42.997507 | ... L37: =IFERROR(365/L30,0) -> 39.238984 | N37: =MEDIAN(C37:L37) -> 46.677696 | O37: =AVERAGE(C37:L37) -> 46.477276
B38: Cash Conversion Cycle (in days) | C38: =IFERROR(SUM(C35,C37)-C36,0) -> -91.762933 | D38: =IFERROR(SUM(D35,D37)-D36,0) -> -117.41177 | E38: =IFERROR(SUM(E35,E37)-E36,0) -> -101.13382 | F38: =IFERROR(SUM(F35,F37)-F36,0) -> -98.326751 | G38: =IFERROR(SUM(G35,G37)-G36,0) -> -116.99839 | H38: =IFERROR(SUM(H35,H37)-H36,0) -> -139.4349 | I38: =IFERROR(SUM(I35,I37)-I36,0) -> -118.45634 | J38: =IFERROR(SUM(J35,J37)-J36,0) -> -104.17824 | ... L38: =IFERROR(SUM(L35,L37)-L36,0) -> -106.89633 | N38: =MEDIAN(C38:L38) -> -105.53729 | O38: =AVERAGE(C38:L38) -> -108.92933
B40: CFO/Sales | C40: =IFERROR('Historical FS'!C76/'Historical FS'!C5,0) -> 0.0070501045 | D40: =IFERROR('Historical FS'!D76/'Historical FS'!D5,0) -> 0.0050464879 | E40: =IFERROR('Historical FS'!E76/'Historical FS'!E5,0) -> 0.014361149 | F40: =IFERROR('Historical FS'!F76/'Historical FS'!F5,0) -> 0.021862075 | G40: =IFERROR('Historical FS'!G76/'Historical FS'!G5,0) -> -0.012475678 | H40: =IFERROR('Historical FS'!H76/'Historical FS'!H5,0) -> 0.045893679 | I40: =IFERROR('Historical FS'!I76/'Historical FS'!I5,0) -> 0.028859384 | J40: =IFERROR('Historical FS'!J76/'Historical FS'!J5,0) -> 0.013611126 | ... L40: =IFERROR('Historical FS'!L76/'Historical FS'!L5,0) -> 0.02494229 | N40: =MEDIAN(C40:L40) -> 0.017603002 | O40: =AVERAGE(C40:L40) -> 0.016999547
B41: CFO/Total Assets | C41: =IFERROR('Historical FS'!C76/'Historical FS'!C62,0) -> 0.0073142711 | D41: =IFERROR('Historical FS'!D76/'Historical FS'!D62,0) -> 0.004993023 | E41: =IFERROR('Historical FS'!E76/'Historical FS'!E62,0) -> 0.012796775 | F41: =IFERROR('Historical FS'!F76/'Historical FS'!F62,0) -> 0.021592819 | G41: =IFERROR('Historical FS'!G76/'Historical FS'!G62,0) -> -0.010172422 | H41: =IFERROR('Historical FS'!H76/'Historical FS'!H62,0) -> 0.033562675 | I41: =IFERROR('Historical FS'!I76/'Historical FS'!I62,0) -> 0.024420968 | J41: =IFERROR('Historical FS'!J76/'Historical FS'!J62,0) -> 0.014070391 | ... L41: =IFERROR('Historical FS'!L76/'Historical FS'!L62,0) -> 0.029092269 | N41: =MEDIAN(C41:L41) -> 0.017831605 | O41: =AVERAGE(C41:L41) -> 0.016215382
B42: CFO/Total Debt | C42: =IFERROR('Historical FS'!C76/'Historical FS'!C47,0) -> 0.027753765 | D42: =IFERROR('Historical FS'!D76/'Historical FS'!D47,0) -> 0.017314645 | E42: =IFERROR('Historical FS'!E76/'Historical FS'!E47,0) -> 0.04707114 | F42: =IFERROR('Historical FS'!F76/'Historical FS'!F47,0) -> 0.062170745 | G42: =IFERROR('Historical FS'!G76/'Historical FS'!G47,0) -> -0.026100341 | H42: =IFERROR('Historical FS'!H76/'Historical FS'!H47,0) -> 0.080658229 | I42: =IFERROR('Historical FS'!I76/'Historical FS'!I47,0) -> 0.054872333 | J42: =IFERROR('Historical FS'!J76/'Historical FS'!J47,0) -> 0.035112066 | ... L42: =IFERROR('Historical FS'!L76/'Historical FS'!L47,0) -> 0.15329885 | N42: =MEDIAN(C42:L42) -> 0.050971737 | O42: =AVERAGE(C42:L42) -> 0.053649474

Sheet Forecasting
B2: ='Data Sheet'!B1&" - "&'Data Sheet'!A17 -> TATA MOTORS LTD - Sales | H2: ='Data Sheet'!B1&" - "&'Historical FS'!B16 -> TATA MOTORS LTD - EBIDTA
B3: Year Weight | C3: Year | D3: Sales | E3: Sales growth | H3: Year Weight | I3: Year | J3: EBIDTA | K3: EBIDTA growth
B4: =1 -> 1 | C4: ='Data Sheet'!B16 -> 42460 | D4: {=TRANSPOSE('Data Sheet'!B17:K17)} -> 273045.6 | H4: =1 -> 1 | I4: ='Data Sheet'!B16 -> 42460 | J4: {=TRANSPOSE('Historical FS'!C16:L16)} -> 38395.25
B5: =B4+1 -> 2 | C5: =C4+365 -> 42825 | D5: 269692.51 | E5: =(D5-D4)/D4 -> -0.01228033 | H5: =H4+1 -> 2 | I5: =I4+365 -> 42825 | J5: 14788.85 | K5: =(J5-J4)/J4 -> -0.61482605
B6: =B5+1 -> 3 | C6: =C5+365 -> 43190 | D6: 291550.48 | E6: =(D6-D5)/D5 -> 0.081047746 | H6: =H5+1 -> 3 | I6: =I5+365 -> 43190 | J6: 27364.52 | K6: =(J6-J5)/J5 -> 0.85034807
B7: =B6+1 -> 4 | C7: =C6+365 -> 43555 | D7: 301938.4 | E7: =(D7-D6)/D6 -> 0.035629919 | H7: =H6+1 -> 4 | I7: =I6+365 -> 43555 | J7: 28770.89 | K7: =(J7-J6)/J6 -> 0.051393922
B8: =B7+1 -> 5 | C8: =C7+365 -> 43920 | D8: 261067.97 | E8: =(D8-D7)/D7 -> -0.13536016 | H8: =H7+1 -> 5 | I8: =I7+365 -> 43920 | J8: 22449.45 | K8: =(J8-J7)/J7 -> -0.21971653
B9: =B8+1 -> 6 | C9: =C8+365 -> 44285 | D9: 249794.75 | E9: =(D9-D8)/D8 -> -0.043181168 | H9: =H8+1 -> 6 | I9: =I8+365 -> 44285 | J9: 41655.75 | K9: =(J9-J8)/J8 -> 0.85553544
B10: =B9+1 -> 7 | C10: =C9+365 -> 44650 | D10: 278453.62 | E10: =(D10-D9)/D9 -> 0.11472967 | H10: =H9+1 -> 7 | I10: =I9+365 -> 44650 | J10: 27901.07 | K10: =(J10-J9)/J9 -> -0.33019883
B11: =B10+1 -> 8 | C11: =C10+365 -> 45015 | D11: 345966.97 | E11: =(D11-D10)/D10 -> 0.24245815 | H11: =H10+1 -> 8 | I11: =I10+365 -> 45015 | J11: 22252.56 | K11: =(J11-J10)/J10 -> -0.20244779
B12: =B11+1 -> 9 | C12: =C11+365 -> 45380 | D12: 434016 | E12: =(D12-D11)/D11 -> 0.25450126 | H12: =H11+1 -> 9 | I12: =I11+365 -> 45380 | J12: 54692 | K12: =(J12-J11)/J11 -> 1.4577846
B13: =B12+1 -> 10 | C13: =C12+365 -> 45745 | D13: 439695 | E13: =(D13-D12)/D12 -> 0.013084771 | H13: =H12+1 -> 10 | I13: =I12+365 -> 45745 | J13: 60888 | K13: =(J13-J12)/J12 -> 0.11328896
B14: =B13+1 -> 11 | C14: =C13+365 -> 46110 | D14: =_xlfn.FORECAST.LINEAR(B14,_xlfn.ANCHORARRAY($D$4),$B$4:$B$13) -> 409204.26 | E14: =(D14-D13)/D13 -> -0.069345204 | H14: =H13+1 -> 11 | I14: =I13+365 -> 46110 | J14: =_xlfn.FORECAST.LINEAR(H14,_xlfn.ANCHORARRAY($J$4),$H$4:$H$13) -> 49675.629 | K14: =(J14-J13)/J13 -> -0.18414747
B15: =B14+1 -> 12 | C15: =C14+365 -> 46475 | D15: =_xlfn.FORECAST.LINEAR(B15,_xlfn.ANCHORARRAY($D$4),$B$4:$B$13) -> 426419.19 | E15: =(D15-D14)/D14 -> 0.04206929 | H15: =H14+1 -> 12 | I15: =I14+365 -> 46475 | J15: =_xlfn.FORECAST.LINEAR(H15,_xlfn.ANCHORARRAY($J$4),$H$4:$H$13) -> 52541.046 | K15: =(J15-J14)/J14 -> 0.057682556
B16: =B15+1 -> 13 | C16: =C15+365 -> 46840 | D16: =_xlfn.FORECAST.LINEAR(B16,_xlfn.ANCHORARRAY($D$4),$B$4:$B$13) -> 443634.13 | E16: =(D16-D15)/D15 -> 0.040370915 | H16: =H15+1 -> 13 | I16: =I15+365 -> 46840 | J16: =_xlfn.FORECAST.LINEAR(H16,_xlfn.ANCHORARRAY($J$4),$H$4:$H$13) -> 55406.463 | K16: =(J16-J15)/J15 -> 0.054536737
B17: =B16+1 -> 14 | C17: =C16+365 -> 47205 | D17: =_xlfn.FORECAST.LINEAR(B17,_xlfn.ANCHORARRAY($D$4),$B$4:$B$13) -> 460849.06 | E17: =(D17-D16)/D16 -> 0.038804348 | H17: =H16+1 -> 14 | I17: =I16+365 -> 47205 | J17: =_xlfn.FORECAST.LINEAR(H17,_xlfn.ANCHORARRAY($J$4),$H$4:$H$13) -> 58271.88 | K17: =(J17-J16)/J16 -> 0.051716299
B18: =B17+1 -> 15 | C18: =C17+365 -> 47570 | D18: =_xlfn.FORECAST.LINEAR(B18,_xlfn.ANCHORARRAY($D$4),$B$4:$B$13) -> 478063.99 | E18: =(D18-D17)/D17 -> 0.037354818 | H18: =H17+1 -> 15 | I18: =I17+365 -> 47570 | J18: =_xlfn.FORECAST.LINEAR(H18,_xlfn.ANCHORARRAY($J$4),$H$4:$H$13) -> 61137.298 | K18: =(J18-J17)/J17 -> 0.049173241

Sheet Common Size Statement
B2: ="Common Size Statement"&" "&" - "&'Data Sheet'!B1 -> Common Size Statement - TATA MOTORS LTD
B4: Particulars | C4: ='Data Sheet'!B16 -> 42460 | D4: ='Data Sheet'!C16 -> 42825 | E4: ='Data Sheet'!D16 -> 43190 | F4: ='Data Sheet'!E16 -> 43555 | G4: ='Data Sheet'!F16 -> 43921 | H4: ='Data Sheet'!G16 -> 44286 | I4: ='Data Sheet'!H16 -> 44651 | J4: ='Data Sheet'!I16 -> 45016 | ... L4: ='Data Sheet'!K16 -> 45747
B5: ='Data Sheet'!A17 -> Sales | C5: ='Data Sheet'!B17/'Data Sheet'!B$17 -> 1 | D5: ='Data Sheet'!C17/'Data Sheet'!C$17 -> 1 | E5: ='Data Sheet'!D17/'Data Sheet'!D$17 -> 1 | F5: ='Data Sheet'!E17/'Data Sheet'!E$17 -> 1 | G5: ='Data Sheet'!F17/'Data Sheet'!F$17 -> 1 | H5: ='Data Sheet'!G17/'Data Sheet'!G$17 -> 1 | I5: ='Data Sheet'!H17/'Data Sheet'!H$17 -> 1 | J5: ='Data Sheet'!I17/'Data Sheet'!I$17 -> 1 | ... L5: ='Data Sheet'!K17/'Data Sheet'!K$17 -> 1
B6: ='Data Sheet'!A18 -> Raw Material Cost | C6: ='Data Sheet'!B18/'Data Sheet'!B$17 -> 0.60844786 | D6: ='Data Sheet'!C18/'Data Sheet'!C$17 -> 0.64256171 | E6: ='Data Sheet'!D18/'Data Sheet'!D$17 -> 0.64447357 | F6: ='Data Sheet'!E18/'Data Sheet'!E$17 -> 0.64340246 | G6: ='Data Sheet'!F18/'Data Sheet'!F$17 -> 0.63163559 | H6: ='Data Sheet'!G18/'Data Sheet'!G$17 -> 0.6149343 | I6: ='Data Sheet'!H18/'Data Sheet'!H$17 -> 0.64389657 | J6: ='Data Sheet'!I18/'Data Sheet'!I$17 -> 0.66842005 | ... L6: ='Data Sheet'!K18/'Data Sheet'!K$17 -> 0.611674
B7: ='Data Sheet'!A19 -> Change in Inventory | C7: ='Data Sheet'!B19/'Data Sheet'!B$17 -> 0.010075204 | D7: ='Data Sheet'!C19/'Data Sheet'!C$17 -> 0.027438359 | E7: ='Data Sheet'!D19/'Data Sheet'!D$17 -> 0.007019642 | F7: ='Data Sheet'!E19/'Data Sheet'!E$17 -> -0.0068003275 | G7: ='Data Sheet'!F19/'Data Sheet'!F$17 -> -0.008546395 | H7: ='Data Sheet'!G19/'Data Sheet'!G$17 -> -0.018752035 | I7: ='Data Sheet'!H19/'Data Sheet'!H$17 -> -0.0057118668 | J7: ='Data Sheet'!I19/'Data Sheet'!I$17 -> 0.01382103 | ... L7: ='Data Sheet'!K19/'Data Sheet'!K$17 -> -0.0064499255
B8: ='Data Sheet'!A20 -> Power and Fuel | C8: ='Data Sheet'!B20/'Data Sheet'!B$17 -> 0.0041884213 | D8: ='Data Sheet'!C20/'Data Sheet'!C$17 -> 0.0043005273 | E8: ='Data Sheet'!D20/'Data Sheet'!D$17 -> 0.004486633 | F8: ='Data Sheet'!E20/'Data Sheet'!E$17 -> 0.0052524952 | G8: ='Data Sheet'!F20/'Data Sheet'!F$17 -> 0.0048452899 | H8: ='Data Sheet'!G20/'Data Sheet'!G$17 -> 0.0044551377 | I8: ='Data Sheet'!H20/'Data Sheet'!H$17 -> 0.0078228109 | J8: ='Data Sheet'!I20/'Data Sheet'!I$17 -> 0.007264653 | ... L8: ='Data Sheet'!K20/'Data Sheet'!K$17 -> 0.0055561241
B9: ='Data Sheet'!A21 -> Other Mfr. Exp | C9: ='Data Sheet'!B21/'Data Sheet'!B$17 -> 0.044320546 | D9: ='Data Sheet'!C21/'Data Sheet'!C$17 -> 0.037329068 | E9: ='Data Sheet'!D21/'Data Sheet'!D$17 -> 0.037632111 | F9: ='Data Sheet'!E21/'Data Sheet'!E$17 -> 0.038731543 | G9: ='Data Sheet'!F21/'Data Sheet'!F$17 -> 0.044208832 | H9: ='Data Sheet'!G21/'Data Sheet'!G$17 -> 0.033119871 | I9: ='Data Sheet'!H21/'Data Sheet'!H$17 -> 0.033856195 | J9: ='Data Sheet'!I21/'Data Sheet'!I$17 -> 0.03400894 | ... L9: ='Data Sheet'!K21/'Data Sheet'!K$17 -> 0.042786477
